Workbook
Name IQ_CH: 110000
Name IQ_CQ: 5000
Name IQ_CY: 10000
Name IQ_DAILY: 500000
Name IQ_FH: 100000
Name IQ_FQ: 500
Name IQ_FY: 1000
Name IQ_LTM: 2000
Name IQ_MONTH: 15000
Name IQ_NTM: 6000
Name IQ_WEEK: 50000
Name IQ_YTD: 3000

Sheet Summary
B2: Sales Data
B4: USD | C4: Full Year | I4: Full Year | O4: Total Sales | AB4: 2026B | AE4: Existing | AR4: New
C5: 25A | D5: 25B | E5: 25F vs 25B | F5: 24A | G5: 25F vs 24A | I5: 26B | J5: 25A | K5: 26B vs 25F | O5: 46023 | P5: 46054 | Q5: 46082 | R5: 46113 | S5: 46143 | T5: 46174 | U5: 46204 | V5: 46235 | W5: 46266 | X5: 46296 | Y5: 46327 | Z5: 46357 | AB5: Existing doors | AC5: New doors | AE5: 46023 | AF5: 46054 | AG5: 46082 | AH5: 46113 | AI5: 46143 | AJ5: 46174 | AK5: 46204 | AL5: 46235 | AM5: 46266 | AN5: 46296 | AO5: 46327 | AP5: 46357 | AR5: 46023 | AS5: 46054 | AT5: 46082 | AU5: 46113 | AV5: 46143 | AW5: 46174 | AX5: 46204 | AY5: 46235 | AZ5: 46266 | BA5: 46296 | BB5: 46327 | BC5: 46357
B6: Northeast | C6: =Northeast!Z7+Northeast!Z16+Northeast!Z22+C43 -> 81851.45 | D6: =Northeast!Y7+Northeast!Y16+Northeast!Y22+D43 -> 199000 | E6: =IFERROR(C6/D6-1, "N/A") -> -0.58868618 | F6: =Northeast!X7+Northeast!X16+Northeast!X22+F43 -> 90880.71 | G6: =IFERROR(C6/F6-1, "N/A") -> -0.099352877 | I6: =Northeast!AA7+Northeast!AA16+Northeast!AA22 -> 199000 | J6: =C6 -> 81851.45 | K6: =IFERROR(I6/J6-1, "N/A") -> 1.4312337 | O6: =Northeast!AG7+Northeast!AG16+Northeast!AG22 -> 7920 | P6: =Northeast!AH7+Northeast!AH16+Northeast!AH22 -> 12920 | Q6: =Northeast!AI7+Northeast!AI16+Northeast!AI22 -> 13910 | R6: =Northeast!AJ7+Northeast!AJ16+Northeast!AJ22 -> 13910 | S6: =Northeast!AK7+Northeast!AK16+Northeast!AK22 -> 12910 | T6: =Northeast!AL7+Northeast!AL16+Northeast!AL22 -> 16920 | U6: =Northeast!AM7+Northeast!AM16+Northeast!AM22 -> 18920 | V6: =Northeast!AN7+Northeast!AN16+Northeast!AN22 -> 9940 | ... Z6: =Northeast!AR7+Northeast!AR16+Northeast!AR22 -> 16930 | AB6: =Northeast!AA7+Northeast!AA16 -> 99000 | AC6: =I6-AB6 -> 100000 | AE6: =Northeast!AG7+Northeast!AG16 -> 7920 | AF6: =Northeast!AH7+Northeast!AH16 -> 7920 | AG6: =Northeast!AI7+Northeast!AI16 -> 8910 | AH6: =Northeast!AJ7+Northeast!AJ16 -> 8910 | AI6: =Northeast!AK7+Northeast!AK16 -> 8910 | AJ6: =Northeast!AL7+Northeast!AL16 -> 7920 | AK6: =Northeast!AM7+Northeast!AM16 -> 7920 | AL6: =Northeast!AN7+Northeast!AN16 -> 5940 | ... AP6: =Northeast!AR7+Northeast!AR16 -> 6930 | AR6: =O6-AE6 -> 0 | AS6: =P6-AF6 -> 5000 | AT6: =Q6-AG6 -> 5000 | AU6: =R6-AH6 -> 5000 | AV6: =S6-AI6 -> 4000 | AW6: =T6-AJ6 -> 9000 | AX6: =U6-AK6 -> 11000 | AY6: =V6-AL6 -> 4000 | ... BC6: =Z6-AP6 -> 10000
B7: Central | C7: =Central!Z8+Central!Z19+Central!Z25+C44 -> 138736.72 | D7: =Central!Y8+Central!Y19+Central!Y25+D44 -> 242000 | E7: =IFERROR(C7/D7-1, "N/A") -> -0.42670777 | F7: =Central!X8+Central!X19+Central!X25+F44 -> 121731.17 | G7: =IFERROR(C7/F7-1, "N/A") -> 0.13969758 | I7: =Central!AA8+Central!AA19+Central!AA25 -> 286000 | J7: =C7 -> 138736.72 | K7: =IFERROR(I7/J7-1, "N/A") -> 1.0614586 | O7: =Central!AG8+Central!AG19+Central!AG25 -> 14880 | P7: =Central!AH8+Central!AH19+Central!AH25 -> 19880 | Q7: =Central!AI8+Central!AI19+Central!AI25 -> 21740 | R7: =Central!AJ8+Central!AJ19+Central!AJ25 -> 21740 | S7: =Central!AK8+Central!AK19+Central!AK25 -> 20740 | T7: =Central!AL8+Central!AL19+Central!AL25 -> 23880 | U7: =Central!AM8+Central!AM19+Central!AM25 -> 25880 | V7: =Central!AN8+Central!AN19+Central!AN25 -> 15160 | ... Z7: =Central!AR8+Central!AR19+Central!AR25 -> 23020 | AB7: =Central!AA8+Central!AA19 -> 186000 | AC7: =I7-AB7 -> 100000 | AE7: =Central!AG8+Central!AG19 -> 14880 | AF7: =Central!AH8+Central!AH19 -> 14880 | AG7: =Central!AI8+Central!AI19 -> 16740 | AH7: =Central!AJ8+Central!AJ19 -> 16740 | AI7: =Central!AK8+Central!AK19 -> 16740 | AJ7: =Central!AL8+Central!AL19 -> 14880 | AK7: =Central!AM8+Central!AM19 -> 14880 | AL7: =Central!AN8+Central!AN19 -> 11160 | ... AP7: =Central!AR8+Central!AR19 -> 13020 | AR7: =O7-AE7 -> 0 | AS7: =P7-AF7 -> 5000 | AT7: =Q7-AG7 -> 5000 | AU7: =R7-AH7 -> 5000 | AV7: =S7-AI7 -> 4000 | AW7: =T7-AJ7 -> 9000 | AX7: =U7-AK7 -> 11000 | AY7: =V7-AL7 -> 4000 | ... BC7: =Z7-AP7 -> 10000
B8: West | C8: =West!Z16+West!Z27+West!Z33+C45 -> 306743.02 | D8: =West!Y16+West!Y27+West!Y33+D45 -> 574500 | E8: =IFERROR(C8/D8-1, "N/A") -> -0.46606959 | F8: =West!X16+West!X27+West!X33+F45 -> 343837.12 | G8: =IFERROR(C8/F8-1, "N/A") -> -0.10788277 | I8: =West!AA16+West!AA27+West!AA33 -> 377000 | J8: =C8 -> 306743.02 | K8: =IFERROR(I8/J8-1, "N/A") -> 0.22904182 | O8: =West!AG16+West!AG27+West!AG33 -> 22160 | P8: =West!AH16+West!AH27+West!AH33 -> 27160 | Q8: =West!AI16+West!AI27+West!AI33 -> 29930 | R8: =West!AJ16+West!AJ27+West!AJ33 -> 29930 | S8: =West!AK16+West!AK27+West!AK33 -> 28930 | T8: =West!AL16+West!AL27+West!AL33 -> 31160 | U8: =West!AM16+West!AM27+West!AM33 -> 33160 | V8: =West!AN16+West!AN27+West!AN33 -> 20620 | ... Z8: =West!AR16+West!AR27+West!AR33 -> 29390 | AB8: =West!AA16+West!AA27 -> 277000 | AC8: =I8-AB8 -> 100000 | AE8: =West!AG16+West!AG27 -> 22160 | AF8: =West!AH16+West!AH27 -> 22160 | AG8: =West!AI16+West!AI27 -> 24930 | AH8: =West!AJ16+West!AJ27 -> 24930 | AI8: =West!AK16+West!AK27 -> 24930 | AJ8: =West!AL16+West!AL27 -> 22160 | AK8: =West!AM16+West!AM27 -> 22160 | AL8: =West!AN16+West!AN27 -> 16620 | ... AP8: =West!AR16+West!AR27 -> 19390 | AR8: =O8-AE8 -> 0 | AS8: =P8-AF8 -> 5000 | AT8: =Q8-AG8 -> 5000 | AU8: =R8-AH8 -> 5000 | AV8: =S8-AI8 -> 4000 | AW8: =T8-AJ8 -> 9000 | AX8: =U8-AK8 -> 11000 | AY8: =V8-AL8 -> 4000 | ... BC8: =Z8-AP8 -> 10000
B9: Southeast | C9: =Southeast!Z14+Southeast!Z23+Southeast!Z29+C46 -> 131948.22 | D9: =Southeast!Y14+Southeast!Y23+Southeast!Y29+D46 -> 343000 | E9: =IFERROR(C9/D9-1, "N/A") -> -0.61531131 | F9: =Southeast!X14+Southeast!X23+Southeast!X29+F46 -> 150948.02 | G9: =IFERROR(C9/F9-1, "N/A") -> -0.12586982 | I9: =Southeast!AA14+Southeast!AA23+Southeast!AA29 -> 272000 | J9: =C9 -> 131948.22 | K9: =IFERROR(I9/J9-1, "N/A") -> 1.0614147 | O9: =Southeast!AG14+Southeast!AG23+Southeast!AG29 -> 13760 | P9: =Southeast!AH14+Southeast!AH23+Southeast!AH29 -> 18760 | Q9: =Southeast!AI14+Southeast!AI23+Southeast!AI29 -> 20480 | R9: =Southeast!AJ14+Southeast!AJ23+Southeast!AJ29 -> 20480 | S9: =Southeast!AK14+Southeast!AK23+Southeast!AK29 -> 19480 | T9: =Southeast!AL14+Southeast!AL23+Southeast!AL29 -> 22760 | U9: =Southeast!AM14+Southeast!AM23+Southeast!AM29 -> 24760 | V9: =Southeast!AN14+Southeast!AN23+Southeast!AN29 -> 14320 | ... Z9: =Southeast!AR14+Southeast!AR23+Southeast!AR29 -> 22040 | AB9: =Southeast!AA14+Southeast!AA23 -> 172000 | AC9: =I9-AB9 -> 100000 | AE9: =Southeast!AG14+Southeast!AG23 -> 13760 | AF9: =Southeast!AH14+Southeast!AH23 -> 13760 | AG9: =Southeast!AI14+Southeast!AI23 -> 15480 | AH9: =Southeast!AJ14+Southeast!AJ23 -> 15480 | AI9: =Southeast!AK14+Southeast!AK23 -> 15480 | AJ9: =Southeast!AL14+Southeast!AL23 -> 13760 | AK9: =Southeast!AM14+Southeast!AM23 -> 13760 | AL9: =Southeast!AN14+Southeast!AN23 -> 10320 | ... AP9: =Southeast!AR14+Southeast!AR23 -> 12040 | AR9: =O9-AE9 -> 0 | AS9: =P9-AF9 -> 5000 | AT9: =Q9-AG9 -> 5000 | AU9: =R9-AH9 -> 5000 | AV9: =S9-AI9 -> 4000 | AW9: =T9-AJ9 -> 9000 | AX9: =U9-AK9 -> 11000 | AY9: =V9-AL9 -> 4000 | ... BC9: =Z9-AP9 -> 10000
B10: Other | C10: =Other!Z5+Other!Z10+Other!Z16+C47 -> 77613.54 | D10: =Other!Y5+Other!Y10+Other!Y16+D47 -> 155000 | E10: =IFERROR(C10/D10-1, "N/A") -> -0.49926748 | F10: =Other!X5+Other!X10+Other!X16+F47 -> 59847.38 | G10: =IFERROR(C10/F10-1, "N/A") -> 0.29685777 | I10: =Other!AA5+Other!AA10+Other!AA16 -> 90000 | J10: =C10 -> 77613.54 | K10: =IFERROR(I10/J10-1, "N/A") -> 0.15959148 | O10: =Other!AG5+Other!AG10+Other!AG16 -> 7200 | P10: =Other!AH5+Other!AH10+Other!AH16 -> 7200 | Q10: =Other!AI5+Other!AI10+Other!AI16 -> 8100 | R10: =Other!AJ5+Other!AJ10+Other!AJ16 -> 8100 | S10: =Other!AK5+Other!AK10+Other!AK16 -> 8100 | T10: =Other!AL5+Other!AL10+Other!AL16 -> 7200 | U10: =Other!AM5+Other!AM10+Other!AM16 -> 7200 | V10: =Other!AN5+Other!AN10+Other!AN16 -> 5400 | ... Z10: =Other!AR5+Other!AR10+Other!AR16 -> 6300 | AB10: =Other!AA5+Other!AA10 -> 90000 | AC10: =I10-AB10 -> 0 | AE10: =Other!AG5+Other!AG10 -> 7200 | AF10: =Other!AH5+Other!AH10 -> 7200 | AG10: =Other!AI5+Other!AI10 -> 8100 | AH10: =Other!AJ5+Other!AJ10 -> 8100 | AI10: =Other!AK5+Other!AK10 -> 8100 | AJ10: =Other!AL5+Other!AL10 -> 7200 | AK10: =Other!AM5+Other!AM10 -> 7200 | AL10: =Other!AN5+Other!AN10 -> 5400 | ... AP10: =Other!AR5+Other!AR10 -> 6300 | AR10: =O10-AE10 -> 0 | AS10: =P10-AF10 -> 0 | AT10: =Q10-AG10 -> 0 | AU10: =R10-AH10 -> 0 | AV10: =S10-AI10 -> 0 | AW10: =T10-AJ10 -> 0 | AX10: =U10-AK10 -> 0 | AY10: =V10-AL10 -> 0 | ... BC10: =Z10-AP10 -> 0
B12: US Spa | C12: =SUM(C6:C10) -> 736892.95 | D12: =SUM(D6:D10) -> 1513500 | E12: =IFERROR(C12/D12-1, "N/A") -> -0.51311995 | F12: =SUM(F6:F10) -> 767244.4 | G12: =IFERROR(C12/F12-1, "N/A") -> -0.039559038 | I12: =SUM(I6:I10) -> 1224000 | J12: =SUM(J6:J10) -> 736892.95 | K12: =IFERROR(I12/J12-1, "N/A") -> 0.66102824 | O12: =SUM(O6:O10) -> 65920 | P12: =SUM(P6:P10) -> 85920 | Q12: =SUM(Q6:Q10) -> 94160 | R12: =SUM(R6:R10) -> 94160 | S12: =SUM(S6:S10) -> 90160 | T12: =SUM(T6:T10) -> 101920 | U12: =SUM(U6:U10) -> 109920 | V12: =SUM(V6:V10) -> 65440 | ... Z12: =SUM(Z6:Z10) -> 97680 | AB12: =SUM(AB6:AB10) -> 824000 | AC12: =SUM(AC6:AC10) -> 400000 | AE12: =SUM(AE6:AE10) -> 65920 | AF12: =SUM(AF6:AF10) -> 65920 | AG12: =SUM(AG6:AG10) -> 74160 | AH12: =SUM(AH6:AH10) -> 74160 | AI12: =SUM(AI6:AI10) -> 74160 | AJ12: =SUM(AJ6:AJ10) -> 65920 | AK12: =SUM(AK6:AK10) -> 65920 | AL12: =SUM(AL6:AL10) -> 49440 | ... AP12: =SUM(AP6:AP10) -> 57680 | AR12: =SUM(AR6:AR10) -> 0 | AS12: =SUM(AS6:AS10) -> 20000 | AT12: =SUM(AT6:AT10) -> 20000 | AU12: =SUM(AU6:AU10) -> 20000 | AV12: =SUM(AV6:AV10) -> 16000 | AW12: =SUM(AW6:AW10) -> 36000 | AX12: =SUM(AX6:AX10) -> 44000 | AY12: =SUM(AY6:AY10) -> 16000 | ... BC12: =SUM(BC6:BC10) -> 40000
B16: Commission Summary
C18: Sales 2026 | D18: o/w New 2026 | E18: o/w New 2025 | F18: o/w Existing | G18: Commission on New 2026 | H18: Commission on New 2025 | I18: Commission on Existing | J18: Total 2026 Commission
B19: Northeast | C19: =I6 -> 199000 | D19: =Northeast!AA22 -> 100000 | E19: =Northeast!AA16 -> 37000 | F19: =C19-D19-E19 -> 62000 | G19: =D19*10% -> 10000 | H19: =E19*5% -> 1850 | I19: =F19*5% -> 3100 | J19: =SUM(G19:I19) -> 14950
B20: Central | C20: =I7 -> 286000 | D20: =Central!AA25 -> 100000 | E20: =Central!AA19 -> 66000 | F20: =C20-D20-E20 -> 120000 | G20: =D20*10% -> 10000 | H20: =E20*5% -> 3300 | I20: =F20*5% -> 6000 | J20: =SUM(G20:I20) -> 19300
B21: West | C21: =I8 -> 377000 | D21: =West!AA33 -> 100000 | E21: =West!AA27 -> 77000 | F21: =C21-D21-E21 -> 200000 | G21: =D21*10% -> 10000 | H21: =E21*5% -> 3850 | I21: =F21*5% -> 10000 | J21: =SUM(G21:I21) -> 23850
B22: Southeast | C22: =I9 -> 272000 | D22: =Southeast!AA29 -> 100000 | E22: =Southeast!AA23 -> 23000 | F22: =C22-D22-E22 -> 149000 | G22: =D22*10% -> 10000 | H22: =E22*5% -> 1150 | I22: =F22*5% -> 7450 | J22: =SUM(G22:I22) -> 18600
B23: Other | C23: =I10 -> 90000 | D23: =Other!AA16 -> 0 | E23: =Other!AA10 -> 20000 | F23: =C23-D23-E23 -> 70000 | G23: =D23*10% -> 0 | H23: =E23*5% -> 1000 | I23: =F23*5% -> 3500 | J23: =SUM(G23:I23) -> 4500
B25: US Spa | C25: =SUM(C19:C23) -> 1224000 | D25: =SUM(D19:D23) -> 400000 | E25: =SUM(E19:E23) -> 223000 | F25: =SUM(F19:F23) -> 601000 | G25: =SUM(G19:G23) -> 40000 | H25: =SUM(H19:H23) -> 11150 | I25: =SUM(I19:I23) -> 30050 | J25: =SUM(J19:J23) -> 81200
B39: Lost
B41: USD | C41: Full Year | M41: Full Year
C42: 25F | D42: 25B | E42: 25F vs 25B | F42: 24A | G42: 25F vs 24A | H42: 25B | I42: 25A vs 25B | J42: 24A | K42: 25A vs 24A | M42: 26B | N42: 25F | O42: 26B vs 25F
B43: Northeast | C43: =SUMIF(Lost!$D:$D, $B43,Lost!Z:Z) -> 0 | D43: =SUMIF(Lost!$D:$D, $B43,Lost!Y:Y) -> 0 | E43: =IFERROR(C43/D43-1, "N/A") -> N/A | F43: =SUMIF(Lost!$D:$D, $B43,Lost!X:X) -> 0 | G43: =IFERROR(C43/F43-1, "N/A") -> N/A | H43: =SUMIF(Lost!$D:$D, $B43,Lost!Q:Q) -> 0 | I43: =IFERROR(#REF!/H43-1, "N/A") -> N/A | J43: =SUMIF(Lost!$D:$D, $B43,Lost!O:O) -> 0 | K43: =IFERROR(#REF!/J43-1, "N/A") -> N/A | M43: =SUMIF(Lost!$D:$D, $B43,Lost!AA:AA) -> 0 | N43: =C43 -> 0 | O43: =IFERROR(M43/N43-1, "N/A") -> N/A
B44: Central | C44: =SUMIF(Lost!$D:$D, $B44,Lost!Z:Z) -> 0 | D44: =SUMIF(Lost!$D:$D, $B44,Lost!Y:Y) -> 10000 | E44: =IFERROR(C44/D44-1, "N/A") -> -1 | F44: =SUMIF(Lost!$D:$D, $B44,Lost!X:X) -> 5494 | G44: =IFERROR(C44/F44-1, "N/A") -> -1 | H44: =SUMIF(Lost!$D:$D, $B44,Lost!Q:Q) -> 10000 | I44: =IFERROR(#REF!/H44-1, "N/A") -> N/A | J44: =SUMIF(Lost!$D:$D, $B44,Lost!O:O) -> 5494 | K44: =IFERROR(#REF!/J44-1, "N/A") -> N/A | M44: =SUMIF(Lost!$D:$D, $B44,Lost!AA:AA) -> 0 | N44: =C44 -> 0 | O44: =IFERROR(M44/N44-1, "N/A") -> N/A
B45: West | C45: =SUMIF(Lost!$D:$D, $B45,Lost!Z:Z) -> 0 | D45: =SUMIF(Lost!$D:$D, $B45,Lost!Y:Y) -> 0 | E45: =IFERROR(C45/D45-1, "N/A") -> N/A | F45: =SUMIF(Lost!$D:$D, $B45,Lost!X:X) -> 0 | G45: =IFERROR(C45/F45-1, "N/A") -> N/A | H45: =SUMIF(Lost!$D:$D, $B45,Lost!Q:Q) -> 0 | I45: =IFERROR(#REF!/H45-1, "N/A") -> N/A | J45: =SUMIF(Lost!$D:$D, $B45,Lost!O:O) -> 0 | K45: =IFERROR(#REF!/J45-1, "N/A") -> N/A | M45: =SUMIF(Lost!$D:$D, $B45,Lost!AA:AA) -> 0 | N45: =C45 -> 0 | O45: =IFERROR(M45/N45-1, "N/A") -> N/A
B46: Southeast | C46: =SUMIF(Lost!$D:$D, $B46,Lost!Z:Z) -> 0 | D46: =SUMIF(Lost!$D:$D, $B46,Lost!Y:Y) -> 0 | E46: =IFERROR(C46/D46-1, "N/A") -> N/A | F46: =SUMIF(Lost!$D:$D, $B46,Lost!X:X) -> 0 | G46: =IFERROR(C46/F46-1, "N/A") -> N/A | H46: =SUMIF(Lost!$D:$D, $B46,Lost!Q:Q) -> 0 | I46: =IFERROR(#REF!/H46-1, "N/A") -> N/A | J46: =SUMIF(Lost!$D:$D, $B46,Lost!O:O) -> 0 | K46: =IFERROR(#REF!/J46-1, "N/A") -> N/A | M46: =SUMIF(Lost!$D:$D, $B46,Lost!AA:AA) -> 0 | N46: =C46 -> 0 | O46: =IFERROR(M46/N46-1, "N/A") -> N/A
B47: Other | C47: =SUMIF(Lost!$D:$D, $B47,Lost!Z:Z) -> 0 | D47: =SUMIF(Lost!$D:$D, $B47,Lost!Y:Y) -> 0 | E47: =IFERROR(C47/D47-1, "N/A") -> N/A | F47: =SUMIF(Lost!$D:$D, $B47,Lost!X:X) -> 0 | G47: =IFERROR(C47/F47-1, "N/A") -> N/A | H47: =SUMIF(Lost!$D:$D, $B47,Lost!Q:Q) -> 0 | I47: =IFERROR(#REF!/H47-1, "N/A") -> N/A | J47: =SUMIF(Lost!$D:$D, $B47,Lost!O:O) -> 0 | K47: =IFERROR(#REF!/J47-1, "N/A") -> N/A | M47: =SUMIF(Lost!$D:$D, $B47,Lost!AA:AA) -> 0 | N47: =C47 -> 0 | O47: =IFERROR(M47/N47-1, "N/A") -> N/A
B49: US Spa | C49: =SUM(C43:C47) -> 0 | D49: =SUM(D43:D47) -> 10000 | E49: =IFERROR(C49/D49-1, "N/A") -> -1 | F49: =SUM(F43:F47) -> 5494 | G49: =IFERROR(C49/F49-1, "N/A") -> -1 | H49: =SUM(H43:H47) -> 10000 | I49: =IFERROR(#REF!/H49-1, "N/A") -> N/A | J49: =SUM(J43:J47) -> 5494 | K49: =IFERROR(#REF!/J49-1, "N/A") -> N/A | M49: =SUM(M43:M47) -> 0 | N49: =SUM(N43:N47) -> 0 | O49: =IFERROR(M49/N49-1, "N/A") -> N/A

Sheet Definition
B2: Cluster | C2: Definition
B3: A+++ | C3: QMS Key Account with a target / potential > $100k per year
B4: A++ | C4: QMS Key Account with a target / potential $50k - $100k per year
B5: A+ | C5: QMS Key Account with a target / potential $30k - $50k per year
B6: A | C6: Non-key account, with 2025 sales > $20k or 2026 target >$20k
B7: B | C7: Non-key account, with 2025 sales > $10k or 2026 target >$10k
B8: C | C8: Non-key account, with 2025 sales < $10k or 2026 target <$10k
B9: Lost | C9: Lost door, no budget
B10: NKD26 | C10: New door won in 2026

Sheet Northeast
O1: Year to date | P1: Year to date | Q1: Year to date | S1: Year to date | T1: Year to date | V1: Full year | W1: Full year | X1: Full year | Y1: Full year | Z1: Full year | AA1: Full year | AC1: Full year | AD1: Full year | AE1: Full year | AG1: 0.08 | AH1: 0.08 | AI1: 0.09 | AJ1: 0.09 | AK1: 0.09 | AL1: 0.08 | AM1: 0.08 | AN1: 0.06 | AO1: 0.09 | AP1: 0.1 | AQ1: 0.09 | AR1: 0.07
B2: Customer Code | C2: Customer Name | D2: Region | E2: Sales person | F2: New door year | G2: Active? | H2: 2025 Cluster | I2: 2026 Cluster | J2: 2025A | K2: 2026B | L2: Size indicator | M2: Customer Growth Class | O2: 2024 YTD | P2: 2025 YTD | Q2: 2025B YTD | S2: 25 vs 24 % | T2: 25 vs 25B % | V2: 2022 | W2: 2023 | X2: 2024 | Y2: 2025B | Z2: 2025A | AA2: 2026B | AC2: 25 vs 24 % | AD2: 25 vs 25B % | AE2: 26B vs 25A % | AG2: 46023 | AH2: 46054 | AI2: 46082 | AJ2: 46113 | AK2: 46143 | AL2: 46174 | AM2: 46204 | AN2: 46235 | AO2: 46266 | AP2: 46296 | AQ2: 46327 | AR2: 46357
B3: 25001 | C3: Four Seasons Hotel Philadelphia; PA | D3: =VLOOKUP($B3, 'Performance data'!$B:$K, 3, 0) -> Northeast | E3: Marcus | F3: =VLOOKUP($B3, 'Performance data'!$B:$K, 7, 0) -> 2021 | H3: =VLOOKUP($B3, 'Performance data'!$B:$K, 5, 0) -> A | I3: A+ | J3: =P3 -> 26036.49 | K3: 30000 | M3: Grow | O3: =SUMIF('Performance data'!$B:$B, $B3,'Performance data'!K:K) -> 33680.82 | P3: =SUMIF('Performance data'!$B:$B, $B3,'Performance data'!L:L) -> 26036.49 | Q3: =SUMIF('Performance data'!$B:$B, $B3,'Performance data'!M:M) -> 40000 | S3: =$P3/O3-1 -> -0.22696389 | T3: =P3/Q3-1 -> -0.34908775 | V3: =SUMIF('Performance data'!$B:$B, $B3,'Performance data'!Z:Z) -> 32357.19 | W3: =SUMIF('Performance data'!$B:$B, $B3,'Performance data'!AA:AA) -> 24745.57 | X3: =SUMIF('Performance data'!$B:$B, $B3,'Performance data'!AB:AB) -> 33680.82 | Y3: =SUMIF('Performance data'!$B:$B, $B3,'Performance data'!AD:AD) -> 40000 | Z3: =J3 -> 26036.49 | AA3: =K3 -> 30000 | AC3: =Z3/X3-1 -> -0.22696389 | AD3: =Z3/Y3-1 -> -0.34908775 | AE3: =AA3/Z3-1 -> 0.15222904 | AG3: =$AA3*AG$1 -> 2400 | AH3: =$AA3*AH$1 -> 2400 | AI3: =$AA3*AI$1 -> 2700 | AJ3: =$AA3*AJ$1 -> 2700 | AK3: =$AA3*AK$1 -> 2700 | AL3: =$AA3*AL$1 -> 2400 | AM3: =$AA3*AM$1 -> 2400 | AN3: =$AA3*AN$1 -> 1800 | ... AR3: =$AA3*AR$1 -> 2100
B4: 25037 | C4: Equinox Holdings Inc; Boston | D4: =VLOOKUP($B4, 'Performance data'!$B:$K, 3, 0) -> Northeast | E4: Marcus | F4: =VLOOKUP($B4, 'Performance data'!$B:$K, 7, 0) -> 2023 | H4: =VLOOKUP($B4, 'Performance data'!$B:$K, 5, 0) -> B | I4: C | J4: =P4 -> 5249.32 | K4: 6000 | M4: Maintain | O4: =SUMIF('Performance data'!$B:$B, $B4,'Performance data'!K:K) -> 14341.14 | P4: =SUMIF('Performance data'!$B:$B, $B4,'Performance data'!L:L) -> 5249.32 | Q4: =SUMIF('Performance data'!$B:$B, $B4,'Performance data'!M:M) -> 16000 | S4: =$P4/O4-1 -> -0.63396773 | T4: =P4/Q4-1 -> -0.6719175 | V4: =SUMIF('Performance data'!$B:$B, $B4,'Performance data'!Z:Z) -> 0 | W4: =SUMIF('Performance data'!$B:$B, $B4,'Performance data'!AA:AA) -> 20827.14 | X4: =SUMIF('Performance data'!$B:$B, $B4,'Performance data'!AB:AB) -> 14341.14 | Y4: =SUMIF('Performance data'!$B:$B, $B4,'Performance data'!AD:AD) -> 16000 | Z4: =J4 -> 5249.32 | AA4: =K4 -> 6000 | AC4: =Z4/X4-1 -> -0.63396773 | AD4: =Z4/Y4-1 -> -0.6719175 | AE4: =AA4/Z4-1 -> 0.14300519 | AG4: =$AA4*AG$1 -> 480 | AH4: =$AA4*AH$1 -> 480 | AI4: =$AA4*AI$1 -> 540 | AJ4: =$AA4*AJ$1 -> 540 | AK4: =$AA4*AK$1 -> 540 | AL4: =$AA4*AL$1 -> 480 | AM4: =$AA4*AM$1 -> 480 | AN4: =$AA4*AN$1 -> 360 | ... AR4: =$AA4*AR$1 -> 420
B5: 25045 | C5: dba Haven Spa | D5: =VLOOKUP($B5, 'Performance data'!$B:$K, 3, 0) -> Northeast | E5: Marcus | F5: =VLOOKUP($B5, 'Performance data'!$B:$K, 7, 0) -> 2024 | H5: =VLOOKUP($B5, 'Performance data'!$B:$K, 5, 0) -> NKD24 | I5: C | J5: =P5 -> 5838.02 | K5: 6000 | M5: Maintain | O5: =SUMIF('Performance data'!$B:$B, $B5,'Performance data'!K:K) -> 27105.03 | P5: =SUMIF('Performance data'!$B:$B, $B5,'Performance data'!L:L) -> 5838.02 | Q5: =SUMIF('Performance data'!$B:$B, $B5,'Performance data'!M:M) -> 25000 | S5: =$P5/O5-1 -> -0.78461489 | T5: =P5/Q5-1 -> -0.7664792 | V5: =SUMIF('Performance data'!$B:$B, $B5,'Performance data'!Z:Z) -> 0 | W5: =SUMIF('Performance data'!$B:$B, $B5,'Performance data'!AA:AA) -> 0 | X5: =SUMIF('Performance data'!$B:$B, $B5,'Performance data'!AB:AB) -> 27105.03 | Y5: =SUMIF('Performance data'!$B:$B, $B5,'Performance data'!AD:AD) -> 25000 | Z5: =J5 -> 5838.02 | AA5: =K5 -> 6000 | AC5: =Z5/X5-1 -> -0.78461489 | AD5: =Z5/Y5-1 -> -0.7664792 | AE5: =AA5/Z5-1 -> 0.027745708 | AG5: =$AA5*AG$1 -> 480 | AH5: =$AA5*AH$1 -> 480 | AI5: =$AA5*AI$1 -> 540 | AJ5: =$AA5*AJ$1 -> 540 | AK5: =$AA5*AK$1 -> 540 | AL5: =$AA5*AL$1 -> 480 | AM5: =$AA5*AM$1 -> 480 | AN5: =$AA5*AN$1 -> 360 | ... AR5: =$AA5*AR$1 -> 420
B6: 25049 | C6: Four Seasons Baltimore; MD | D6: =VLOOKUP($B6, 'Performance data'!$B:$K, 3, 0) -> Northeast | E6: Marcus | F6: =VLOOKUP($B6, 'Performance data'!$B:$K, 7, 0) -> 2024 | H6: =VLOOKUP($B6, 'Performance data'!$B:$K, 5, 0) -> NKD24 | I6: A+ | J6: =P6 -> 14251.07 | K6: 20000 | M6: Grow | O6: =SUMIF('Performance data'!$B:$B, $B6,'Performance data'!K:K) -> 15753.72 | P6: =SUMIF('Performance data'!$B:$B, $B6,'Performance data'!L:L) -> 14251.07 | Q6: =SUMIF('Performance data'!$B:$B, $B6,'Performance data'!M:M) -> 18000 | S6: =$P6/O6-1 -> -0.09538382 | T6: =P6/Q6-1 -> -0.20827389 | V6: =SUMIF('Performance data'!$B:$B, $B6,'Performance data'!Z:Z) -> 0 | W6: =SUMIF('Performance data'!$B:$B, $B6,'Performance data'!AA:AA) -> 0 | X6: =SUMIF('Performance data'!$B:$B, $B6,'Performance data'!AB:AB) -> 15753.72 | Y6: =SUMIF('Performance data'!$B:$B, $B6,'Performance data'!AD:AD) -> 18000 | Z6: =J6 -> 14251.07 | AA6: =K6 -> 20000 | AC6: =Z6/X6-1 -> -0.09538382 | AD6: =Z6/Y6-1 -> -0.20827389 | AE6: =AA6/Z6-1 -> 0.40340339 | AG6: =$AA6*AG$1 -> 1600 | AH6: =$AA6*AH$1 -> 1600 | AI6: =$AA6*AI$1 -> 1800 | AJ6: =$AA6*AJ$1 -> 1800 | AK6: =$AA6*AK$1 -> 1800 | AL6: =$AA6*AL$1 -> 1600 | AM6: =$AA6*AM$1 -> 1600 | AN6: =$AA6*AN$1 -> 1200 | ... AR6: =$AA6*AR$1 -> 1400
B7: Total Active Existing Doors | G7: =COUNTIF(G3:G6, "Yes") -> 0 | J7: =SUM(J3:J6) -> 51374.9 | K7: =SUM(K3:K6) -> 62000 | O7: =SUM(O3:O6) -> 90880.71 | P7: =SUM(P3:P6) -> 51374.9 | Q7: =SUM(Q3:Q6) -> 99000 | S7: =$P7/O7-1 -> -0.43469962 | T7: =P7/Q7-1 -> -0.48106162 | V7: =SUM(V3:V6) -> 32357.19 | W7: =SUM(W3:W6) -> 45572.71 | X7: =SUM(X3:X6) -> 90880.71 | Y7: =SUM(Y3:Y6) -> 99000 | Z7: =SUM(Z3:Z6) -> 51374.9 | AA7: =SUM(AA3:AA6) -> 62000 | AC7: =Z7/X7-1 -> -0.43469962 | AD7: =Z7/Y7-1 -> -0.48106162 | AE7: =AA7/Z7-1 -> 0.206815 | AG7: =SUM(AG3:AG6) -> 4960 | AH7: =SUM(AH3:AH6) -> 4960 | AI7: =SUM(AI3:AI6) -> 5580 | AJ7: =SUM(AJ3:AJ6) -> 5580 | AK7: =SUM(AK3:AK6) -> 5580 | AL7: =SUM(AL3:AL6) -> 4960 | AM7: =SUM(AM3:AM6) -> 4960 | AN7: =SUM(AN3:AN6) -> 3720 | ... AR7: =SUM(AR3:AR6) -> 4340
B11: 25061 | C11: Equinox Holdings Inc; Washington DC | D11: =VLOOKUP($B11, 'Performance data'!$B:$K, 3, 0) -> Northeast | E11: Marcus | F11: =VLOOKUP($B11, 'Performance data'!$B:$K, 7, 0) -> 2025 | H11: =VLOOKUP($B11, 'Performance data'!$B:$K, 5, 0) -> NKD25 | I11: C | J11: =P11 -> 6871.79 | K11: 7000 | M11: Maintain | O11: =SUMIF('Performance data'!$B:$B, $B11,'Performance data'!K:K) -> 0 | P11: =SUMIF('Performance data'!$B:$B, $B11,'Performance data'!L:L) -> 6871.79 | Q11: =SUMIF('Performance data'!$B:$B, $B11,'Performance data'!M:M) -> 0 | S11: =$P11/O11-1 -> #DIV/0! | T11: =P11/Q11-1 -> #DIV/0! | V11: =SUMIF('Performance data'!$B:$B, $B11,'Performance data'!Z:Z) -> 0 | W11: =SUMIF('Performance data'!$B:$B, $B11,'Performance data'!AA:AA) -> 0 | X11: =SUMIF('Performance data'!$B:$B, $B11,'Performance data'!AB:AB) -> 0 | Y11: =SUMIF('Performance data'!$B:$B, $B11,'Performance data'!AD:AD) -> 0 | Z11: =J11 -> 6871.79 | AA11: =K11 -> 7000 | AC11: =Z11/X11-1 -> #DIV/0! | AD11: =Z11/Y11-1 -> #DIV/0! | AE11: =AA11/Z11-1 -> 0.018657439 | AG11: =$AA11*AG$1 -> 560 | AH11: =$AA11*AH$1 -> 560 | AI11: =$AA11*AI$1 -> 630 | AJ11: =$AA11*AJ$1 -> 630 | AK11: =$AA11*AK$1 -> 630 | AL11: =$AA11*AL$1 -> 560 | AM11: =$AA11*AM$1 -> 560 | AN11: =$AA11*AN$1 -> 420 | ... AR11: =$AA11*AR$1 -> 490
B12: 25062 | C12: Equinox Holdings Inc; SPA Retail Washington DC | D12: =VLOOKUP($B12, 'Performance data'!$B:$K, 3, 0) -> Northeast | E12: Marcus | F12: =VLOOKUP($B12, 'Performance data'!$B:$K, 7, 0) -> 2025 | H12: =VLOOKUP($B12, 'Performance data'!$B:$K, 5, 0) -> NKD25 | I12: C | J12: =P12 -> 3844.76 | K12: 5000 | M12: Maintain | O12: =SUMIF('Performance data'!$B:$B, $B12,'Performance data'!K:K) -> 0 | P12: =SUMIF('Performance data'!$B:$B, $B12,'Performance data'!L:L) -> 3844.76 | Q12: =SUMIF('Performance data'!$B:$B, $B12,'Performance data'!M:M) -> 0 | S12: =$P12/O12-1 -> #DIV/0! | T12: =P12/Q12-1 -> #DIV/0! | V12: =SUMIF('Performance data'!$B:$B, $B12,'Performance data'!Z:Z) -> 0 | W12: =SUMIF('Performance data'!$B:$B, $B12,'Performance data'!AA:AA) -> 0 | X12: =SUMIF('Performance data'!$B:$B, $B12,'Performance data'!AB:AB) -> 0 | Y12: =SUMIF('Performance data'!$B:$B, $B12,'Performance data'!AD:AD) -> 0 | Z12: =J12 -> 3844.76 | AA12: =K12 -> 5000 | AC12: =Z12/X12-1 -> #DIV/0! | AD12: =Z12/Y12-1 -> #DIV/0! | AE12: =AA12/Z12-1 -> 0.30047129 | AG12: =$AA12*AG$1 -> 400 | AH12: =$AA12*AH$1 -> 400 | AI12: =$AA12*AI$1 -> 450 | AJ12: =$AA12*AJ$1 -> 450 | AK12: =$AA12*AK$1 -> 450 | AL12: =$AA12*AL$1 -> 400 | AM12: =$AA12*AM$1 -> 400 | AN12: =$AA12*AN$1 -> 300 | ... AR12: =$AA12*AR$1 -> 350
B13: 25070 | C13: Renaissance Hotel Partners LLC | D13: =VLOOKUP($B13, 'Performance data'!$B:$K, 3, 0) -> Northeast | E13: Marcus | F13: =VLOOKUP($B13, 'Performance data'!$B:$K, 7, 0) -> 2025 | H13: =VLOOKUP($B13, 'Performance data'!$B:$K, 5, 0) -> NKD25 | I13: A++ | J13: =P13 -> 19760 | K13: 25000 | M13: Grow | O13: =SUMIF('Performance data'!$B:$B, $B13,'Performance data'!K:K) -> 0 | P13: =SUMIF('Performance data'!$B:$B, $B13,'Performance data'!L:L) -> 19760 | Q13: =SUMIF('Performance data'!$B:$B, $B13,'Performance data'!M:M) -> 0 | S13: =$P13/O13-1 -> #DIV/0! | T13: =P13/Q13-1 -> #DIV/0! | V13: =SUMIF('Performance data'!$B:$B, $B13,'Performance data'!Z:Z) -> 0 | W13: =SUMIF('Performance data'!$B:$B, $B13,'Performance data'!AA:AA) -> 0 | X13: =SUMIF('Performance data'!$B:$B, $B13,'Performance data'!AB:AB) -> 0 | Y13: =SUMIF('Performance data'!$B:$B, $B13,'Performance data'!AD:AD) -> 0 | Z13: =J13 -> 19760 | AA13: =K13 -> 25000 | AC13: =Z13/X13-1 -> #DIV/0! | AD13: =Z13/Y13-1 -> #DIV/0! | AE13: =AA13/Z13-1 -> 0.26518219 | AG13: =$AA13*AG$1 -> 2000 | AH13: =$AA13*AH$1 -> 2000 | AI13: =$AA13*AI$1 -> 2250 | AJ13: =$AA13*AJ$1 -> 2250 | AK13: =$AA13*AK$1 -> 2250 | AL13: =$AA13*AL$1 -> 2000 | AM13: =$AA13*AM$1 -> 2000 | AN13: =$AA13*AN$1 -> 1500 | ... AR13: =$AA13*AR$1 -> 1750
B14: NKD25 | C14: New doors 2025 | D14: Northeast | E14: Marcus | F14: 2025 | H14: NKD25 | O14: 0 | P14: 0 | Q14: =SUMIFS('2025 budget doc'!$AC:$AC, '2025 budget doc'!$B:$B, "NKD25", '2025 budget doc'!$E:$E, $D14) -> 18000 | S14: =$P14/O14-1 -> #DIV/0! | T14: =P14/Q14-1 -> -1 | V14: 0 | W14: 0 | X14: 0 | Y14: =SUMIFS('2025 budget doc'!$L:$L, '2025 budget doc'!$B:$B, "NKD25", '2025 budget doc'!$E:$E, $D14) -> 100000 | Z14: =J14 -> 0 | AA14: =K14 -> 0 | AC14: =Z14/X14-1 -> #DIV/0! | AD14: =Z14/Y14-1 -> -1 | AE14: =AA14/Z14-1 -> #DIV/0! | AG14: =$AA14*AG$1 -> 0 | AH14: =$AA14*AH$1 -> 0 | AI14: =$AA14*AI$1 -> 0 | AJ14: =$AA14*AJ$1 -> 0 | AK14: =$AA14*AK$1 -> 0 | AL14: =$AA14*AL$1 -> 0 | AM14: =$AA14*AM$1 -> 0 | AN14: =$AA14*AN$1 -> 0 | ... AR14: =$AA14*AR$1 -> 0
B16: Total New Doors 2025 | G16: =COUNTIF(G11:G13, "Yes")+G14 -> 0 | J16: =SUM(J11:J14) -> 30476.55 | K16: =SUM(K11:K14) -> 37000 | O16: =SUM(O11:O14) -> 0 | P16: =SUM(P11:P14) -> 30476.55 | Q16: =SUM(Q11:Q14) -> 18000 | S16: =$P16/O16-1 -> #DIV/0! | T16: =P16/Q16-1 -> 0.69314167 | V16: =SUM(V11:V14) -> 0 | W16: =SUM(W11:W14) -> 0 | X16: =SUM(X11:X14) -> 0 | Y16: =SUM(Y11:Y14) -> 100000 | Z16: =SUM(Z11:Z14) -> 30476.55 | AA16: =SUM(AA11:AA14) -> 37000 | AC16: =Z16/X16-1 -> #DIV/0! | AD16: =Z16/Y16-1 -> -0.6952345 | AE16: =AA16/Z16-1 -> 0.21404818 | AG16: =SUM(AG11:AG14) -> 2960 | AH16: =SUM(AH11:AH14) -> 2960 | AI16: =SUM(AI11:AI14) -> 3330 | AJ16: =SUM(AJ11:AJ14) -> 3330 | AK16: =SUM(AK11:AK14) -> 3330 | AL16: =SUM(AL11:AL14) -> 2960 | AM16: =SUM(AM11:AM14) -> 2960 | AN16: =SUM(AN11:AN14) -> 2220 | ... AR16: =SUM(AR11:AR14) -> 2590
AY19: =AV20 -> 1 | AZ19: =AW20 -> 1 | BA19: =AX20+AV20 -> 2 | BB19: =AY20+AW20 -> 1 | BC19: =AZ20+AX20+AV20 -> 3 | BD19: =BA20+AY20+AW20 -> 2 | BE19: =BB20+AZ20+AX20+AV20 -> 3 | BF19: =BC20+BA20+AY20+AW20 -> 3
B20: NKD26 | C20: New doors 2026 | D20: Northeast | E20: Marcus | F20: 2026 | G20: 8 | H20: NKD26 | I20: NKD26 | K20: 100000 | O20: 0 | P20: 0 | Q20: 0 | S20: =$P20/O20-1 -> #DIV/0! | T20: =P20/Q20-1 -> #DIV/0! | V20: 0 | W20: 0 | X20: 0 | Y20: 0 | Z20: =J20 -> 0 | AA20: =K20 -> 100000 | AC20: =Z20/X20-1 -> #DIV/0! | AD20: =Z20/Y20-1 -> #DIV/0! | AE20: =AA20/Z20-1 -> #DIV/0! | AG20: =AU20*5000+AU19*4000 -> 0 | AH20: =AV20*5000+AV19*4000 -> 5000 | AI20: =AW20*5000+AW19*4000 -> 5000 | AJ20: =AX20*5000+AX19*4000 -> 5000 | AK20: =AY20*5000+AY19*4000 -> 4000 | AL20: =AZ20*5000+AZ19*4000 -> 9000 | AM20: =BA20*5000+BA19*4000-2000 -> 11000 | AN20: =BB20*5000+BB19*4000 -> 4000 | AO20: =BC20*5000+BC19*4000 -> 17000 | AP20: =BD20*5000+BD19*4000 -> 13000 | AQ20: =BE20*5000+BE19*4000 -> 17000 | AR20: =BF20*5000+BF19*4000-2000 -> 10000 | AV20: 1 | AW20: 1 | AX20: 1 | AZ20: 1 | BA20: 1 | BC20: 1 | BD20: 1 | BE20: 1
B22: Total New Doors 2026 | G22: =COUNTIF(G19:G19, "Yes")+G20 -> 8 | J22: =SUM(J19:J20) -> 0 | K22: =SUM(K19:K20) -> 100000 | O22: =SUM(O19:O20) -> 0 | P22: =SUM(P19:P20) -> 0 | Q22: =SUM(Q19:Q20) -> 0 | S22: =$P22/O22-1 -> #DIV/0! | T22: =P22/Q22-1 -> #DIV/0! | V22: =SUM(V19:V20) -> 0 | W22: =SUM(W19:W20) -> 0 | X22: =SUM(X19:X20) -> 0 | Y22: =SUM(Y19:Y20) -> 0 | Z22: =SUM(Z19:Z20) -> 0 | AA22: =SUM(AA19:AA20) -> 100000 | AC22: =Z22/X22-1 -> #DIV/0! | AD22: =Z22/Y22-1 -> #DIV/0! | AE22: =AA22/Z22-1 -> #DIV/0! | AG22: =SUM(AG19:AG20) -> 0 | AH22: =SUM(AH19:AH20) -> 5000 | AI22: =SUM(AI19:AI20) -> 5000 | AJ22: =SUM(AJ19:AJ20) -> 5000 | AK22: =SUM(AK19:AK20) -> 4000 | AL22: =SUM(AL19:AL20) -> 9000 | AM22: =SUM(AM19:AM20) -> 11000 | AN22: =SUM(AN19:AN20) -> 4000 | ... AR22: =SUM(AR19:AR20) -> 10000

Sheet Central
O1: Year to date | P1: Year to date | Q1: Year to date | S1: Year to date | T1: Year to date | V1: Full year | W1: Full year | X1: Full year | Y1: Full year | Z1: Full year | AA1: Full year | AC1: Full year | AD1: Full year | AE1: Full year | AG1: 0.08 | AH1: 0.08 | AI1: 0.09 | AJ1: 0.09 | AK1: 0.09 | AL1: 0.08 | AM1: 0.08 | AN1: 0.06 | AO1: 0.09 | AP1: 0.1 | AQ1: 0.09 | AR1: 0.07
B2: Customer Code | C2: Customer Name | D2: Region | E2: Sales person | F2: New door year | G2: Active? | H2: 2025 Cluster | I2: 2026 Cluster | J2: 2025A | K2: 2026B | L2: Size indicator | M2: Customer Growth Class | O2: 2024 YTD | P2: 2025 YTD | Q2: 2025B YTD | S2: 25 vs 24 % | T2: 25 vs 25B % | V2: 2022 | W2: 2023 | X2: 2024 | Y2: 2025B | Z2: 2025A | AA2: 2026B | AC2: 25 vs 24 % | AD2: 25 vs 25B % | AE2: 26B vs 25A % | AG2: 46023 | AH2: 46054 | AI2: 46082 | AJ2: 46113 | AK2: 46143 | AL2: 46174 | AM2: 46204 | AN2: 46235 | AO2: 46266 | AP2: 46296 | AQ2: 46327 | AR2: 46357
B3: 25039 | C3: Four Seasons Hotel Austin; DTRS Austin LLC | D3: =VLOOKUP($B3, 'Performance data'!$B:$K, 3, 0) -> Central | E3: =VLOOKUP($B3, 'Performance data'!$B:$K, 4, 0) -> Emily | F3: =VLOOKUP($B3, 'Performance data'!$B:$K, 7, 0) -> 2024 | H3: =VLOOKUP($B3, 'Performance data'!$B:$K, 5, 0) -> NKD24 | I3: Lost | J3: =P3 -> 2153.52 | M3: Lose | O3: =SUMIF('Performance data'!$B:$B, $B3,'Performance data'!K:K) -> 18410.82 | P3: =SUMIF('Performance data'!$B:$B, $B3,'Performance data'!L:L) -> 2153.52 | Q3: =SUMIF('Performance data'!$B:$B, $B3,'Performance data'!M:M) -> 16000 | S3: =$P3/O3-1 -> -0.88302965 | T3: =P3/Q3-1 -> -0.865405 | V3: =SUMIF('Performance data'!$B:$B, $B3,'Performance data'!Z:Z) -> 0 | W3: =SUMIF('Performance data'!$B:$B, $B3,'Performance data'!AA:AA) -> 0 | X3: =SUMIF('Performance data'!$B:$B, $B3,'Performance data'!AB:AB) -> 18410.82 | Y3: =SUMIF('Performance data'!$B:$B, $B3,'Performance data'!AD:AD) -> 16000 | Z3: =J3 -> 2153.52 | AA3: =K3 -> 0 | AC3: =Z3/X3-1 -> -0.88302965 | AD3: =Z3/Y3-1 -> -0.865405 | AE3: =AA3/Z3-1 -> -1 | AG3: =$AA3*AG$1 -> 0 | AH3: =$AA3*AH$1 -> 0 | AI3: =$AA3*AI$1 -> 0 | AJ3: =$AA3*AJ$1 -> 0 | AK3: =$AA3*AK$1 -> 0 | AL3: =$AA3*AL$1 -> 0 | AM3: =$AA3*AM$1 -> 0 | AN3: =$AA3*AN$1 -> 0 | ... AR3: =$AA3*AR$1 -> 0
B4: 25044 | C4: The Elms Hotel and Spa; Missouri | D4: =VLOOKUP($B4, 'Performance data'!$B:$K, 3, 0) -> Central | E4: =VLOOKUP($B4, 'Performance data'!$B:$K, 4, 0) -> Emily | F4: =VLOOKUP($B4, 'Performance data'!$B:$K, 7, 0) -> 2024 | H4: =VLOOKUP($B4, 'Performance data'!$B:$K, 5, 0) -> NKD24 | I4: A | J4: =P4 -> 26752.85 | K4: 28000 | M4: Grow | O4: =SUMIF('Performance data'!$B:$B, $B4,'Performance data'!K:K) -> 23382.73 | P4: =SUMIF('Performance data'!$B:$B, $B4,'Performance data'!L:L) -> 26752.85 | Q4: =SUMIF('Performance data'!$B:$B, $B4,'Performance data'!M:M) -> 25000 | S4: =$P4/O4-1 -> 0.14412859 | T4: =P4/Q4-1 -> 0.070114 | V4: =SUMIF('Performance data'!$B:$B, $B4,'Performance data'!Z:Z) -> 0 | W4: =SUMIF('Performance data'!$B:$B, $B4,'Performance data'!AA:AA) -> 0 | X4: =SUMIF('Performance data'!$B:$B, $B4,'Performance data'!AB:AB) -> 23382.73 | Y4: =SUMIF('Performance data'!$B:$B, $B4,'Performance data'!AD:AD) -> 25000 | Z4: =J4 -> 26752.85 | AA4: =K4 -> 28000 | AC4: =Z4/X4-1 -> 0.14412859 | AD4: =Z4/Y4-1 -> 0.070114 | AE4: =AA4/Z4-1 -> 0.046617463 | AG4: =$AA4*AG$1 -> 2240 | AH4: =$AA4*AH$1 -> 2240 | AI4: =$AA4*AI$1 -> 2520 | AJ4: =$AA4*AJ$1 -> 2520 | AK4: =$AA4*AK$1 -> 2520 | AL4: =$AA4*AL$1 -> 2240 | AM4: =$AA4*AM$1 -> 2240 | AN4: =$AA4*AN$1 -> 1680 | ... AR4: =$AA4*AR$1 -> 1960
B5: 25050 | C5: Mokara Hotel & Spa, Omni Hotels Management Corp. | D5: =VLOOKUP($B5, 'Performance data'!$B:$K, 3, 0) -> Central | E5: =VLOOKUP($B5, 'Performance data'!$B:$K, 4, 0) -> Emily | F5: =VLOOKUP($B5, 'Performance data'!$B:$K, 7, 0) -> 2024 | H5: =VLOOKUP($B5, 'Performance data'!$B:$K, 5, 0) -> NKD24 | I5: A+ | J5: =P5 -> 7207.32 | K5: 12000 | M5: Grow | O5: =SUMIF('Performance data'!$B:$B, $B5,'Performance data'!K:K) -> 16142.96 | P5: =SUMIF('Performance data'!$B:$B, $B5,'Performance data'!L:L) -> 7207.32 | Q5: =SUMIF('Performance data'!$B:$B, $B5,'Performance data'!M:M) -> 16000 | S5: =$P5/O5-1 -> -0.55353169 | T5: =P5/Q5-1 -> -0.5495425 | V5: =SUMIF('Performance data'!$B:$B, $B5,'Performance data'!Z:Z) -> 0 | W5: =SUMIF('Performance data'!$B:$B, $B5,'Performance data'!AA:AA) -> 0 | X5: =SUMIF('Performance data'!$B:$B, $B5,'Performance data'!AB:AB) -> 16142.96 | Y5: =SUMIF('Performance data'!$B:$B, $B5,'Performance data'!AD:AD) -> 16000 | Z5: =J5 -> 7207.32 | AA5: =K5 -> 12000 | AC5: =Z5/X5-1 -> -0.55353169 | AD5: =Z5/Y5-1 -> -0.5495425 | AE5: =AA5/Z5-1 -> 0.66497394 | AG5: =$AA5*AG$1 -> 960 | AH5: =$AA5*AH$1 -> 960 | AI5: =$AA5*AI$1 -> 1080 | AJ5: =$AA5*AJ$1 -> 1080 | AK5: =$AA5*AK$1 -> 1080 | AL5: =$AA5*AL$1 -> 960 | AM5: =$AA5*AM$1 -> 960 | AN5: =$AA5*AN$1 -> 720 | ... AR5: =$AA5*AR$1 -> 840
B6: 25054 | C6: Four Seasons Hotel Nashville; TN | D6: =VLOOKUP($B6, 'Performance data'!$B:$K, 3, 0) -> Southeast | E6: Emily | F6: =VLOOKUP($B6, 'Performance data'!$B:$K, 7, 0) -> 2024 | H6: =VLOOKUP($B6, 'Performance data'!$B:$K, 5, 0) -> NKD24 | I6: A+ | J6: =P6 -> 26549.66 | K6: 30000 | M6: Grow | O6: =SUMIF('Performance data'!$B:$B, $B6,'Performance data'!K:K) -> 24095.02 | P6: =SUMIF('Performance data'!$B:$B, $B6,'Performance data'!L:L) -> 26549.66 | Q6: =SUMIF('Performance data'!$B:$B, $B6,'Performance data'!M:M) -> 25000 | S6: =$P6/O6-1 -> 0.10187333 | T6: =P6/Q6-1 -> 0.0619864 | V6: =SUMIF('Performance data'!$B:$B, $B6,'Performance data'!Z:Z) -> 0 | W6: =SUMIF('Performance data'!$B:$B, $B6,'Performance data'!AA:AA) -> 0 | X6: =SUMIF('Performance data'!$B:$B, $B6,'Performance data'!AB:AB) -> 24095.02 | Y6: =SUMIF('Performance data'!$B:$B, $B6,'Performance data'!AD:AD) -> 25000 | Z6: =J6 -> 26549.66 | AA6: =K6 -> 30000 | AC6: =Z6/X6-1 -> 0.10187333 | AD6: =Z6/Y6-1 -> 0.0619864 | AE6: =AA6/Z6-1 -> 0.12995797 | AG6: =$AA6*AG$1 -> 2400 | AH6: =$AA6*AH$1 -> 2400 | AI6: =$AA6*AI$1 -> 2700 | AJ6: =$AA6*AJ$1 -> 2700 | AK6: =$AA6*AK$1 -> 2700 | AL6: =$AA6*AL$1 -> 2400 | AM6: =$AA6*AM$1 -> 2400 | AN6: =$AA6*AN$1 -> 1800 | ... AR6: =$AA6*AR$1 -> 2100
B7: 25056 | C7: AMI LLC Bergamos Retreat | D7: =VLOOKUP($B7, 'Performance data'!$B:$K, 3, 0) -> Central | E7: Emily | F7: =VLOOKUP($B7, 'Performance data'!$B:$K, 7, 0) -> 2024 | H7: =VLOOKUP($B7, 'Performance data'!$B:$K, 5, 0) -> NKD24 | I7: A+++ | J7: =P7 -> 35149.62 | K7: 50000 | M7: Grow | O7: =SUMIF('Performance data'!$B:$B, $B7,'Performance data'!K:K) -> 34205.64 | P7: =SUMIF('Performance data'!$B:$B, $B7,'Performance data'!L:L) -> 35149.62 | Q7: =SUMIF('Performance data'!$B:$B, $B7,'Performance data'!M:M) -> 50000 | S7: =$P7/O7-1 -> 0.027597203 | T7: =P7/Q7-1 -> -0.2970076 | V7: =SUMIF('Performance data'!$B:$B, $B7,'Performance data'!Z:Z) -> 0 | W7: =SUMIF('Performance data'!$B:$B, $B7,'Performance data'!AA:AA) -> 0 | X7: =SUMIF('Performance data'!$B:$B, $B7,'Performance data'!AB:AB) -> 34205.64 | Y7: =SUMIF('Performance data'!$B:$B, $B7,'Performance data'!AD:AD) -> 50000 | Z7: =J7 -> 35149.62 | AA7: =K7 -> 50000 | AC7: =Z7/X7-1 -> 0.027597203 | AD7: =Z7/Y7-1 -> -0.2970076 | AE7: =AA7/Z7-1 -> 0.42249048 | AG7: =$AA7*AG$1 -> 4000 | AH7: =$AA7*AH$1 -> 4000 | AI7: =$AA7*AI$1 -> 4500 | AJ7: =$AA7*AJ$1 -> 4500 | AK7: =$AA7*AK$1 -> 4500 | AL7: =$AA7*AL$1 -> 4000 | AM7: =$AA7*AM$1 -> 4000 | AN7: =$AA7*AN$1 -> 3000 | ... AR7: =$AA7*AR$1 -> 3500
B8: Total Active Existing Doors | G8: =COUNTIF(G3:G7, "Yes") -> 0 | J8: =SUM(J3:J7) -> 97812.97 | K8: =SUM(K3:K7) -> 120000 | O8: =SUM(O3:O7) -> 116237.17 | P8: =SUM(P3:P7) -> 97812.97 | Q8: =SUM(Q3:Q7) -> 132000 | S8: =$P8/O8-1 -> -0.15850524 | T8: =P8/Q8-1 -> -0.25899265 | V8: =SUM(V3:V7) -> 0 | W8: =SUM(W3:W7) -> 0 | X8: =SUM(X3:X7) -> 116237.17 | Y8: =SUM(Y3:Y7) -> 132000 | Z8: =SUM(Z3:Z7) -> 97812.97 | AA8: =SUM(AA3:AA7) -> 120000 | AC8: =Z8/X8-1 -> -0.15850524 | AD8: =Z8/Y8-1 -> -0.25899265 | AE8: =AA8/Z8-1 -> 0.22683117 | AG8: =SUM(AG3:AG7) -> 9600 | AH8: =SUM(AH3:AH7) -> 9600 | AI8: =SUM(AI3:AI7) -> 10800 | AJ8: =SUM(AJ3:AJ7) -> 10800 | AK8: =SUM(AK3:AK7) -> 10800 | AL8: =SUM(AL3:AL7) -> 9600 | AM8: =SUM(AM3:AM7) -> 9600 | AN8: =SUM(AN3:AN7) -> 7200 | ... AR8: =SUM(AR3:AR7) -> 8400
B12: 25068 | C12: 321 Skin Glow LLC | D12: =VLOOKUP($B12, 'Performance data'!$B:$K, 3, 0) -> Central | E12: =VLOOKUP($B12, 'Performance data'!$B:$K, 4, 0) -> Emily | F12: =VLOOKUP($B12, 'Performance data'!$B:$K, 7, 0) -> 2025 | H12: =VLOOKUP($B12, 'Performance data'!$B:$K, 5, 0) -> NKD25 | I12: B | J12: =P12 -> 9538 | K12: 12000 | M12: Grow | O12: =SUMIF('Performance data'!$B:$B, $B12,'Performance data'!K:K) -> 0 | P12: =SUMIF('Performance data'!$B:$B, $B12,'Performance data'!L:L) -> 9538 | Q12: =SUMIF('Performance data'!$B:$B, $B12,'Performance data'!M:M) -> 0 | S12: =$P12/O12-1 -> #DIV/0! | T12: =P12/Q12-1 -> #DIV/0! | V12: =SUMIF('Performance data'!$B:$B, $B12,'Performance data'!Z:Z) -> 0 | W12: =SUMIF('Performance data'!$B:$B, $B12,'Performance data'!AA:AA) -> 0 | X12: =SUMIF('Performance data'!$B:$B, $B12,'Performance data'!AB:AB) -> 0 | Y12: =SUMIF('Performance data'!$B:$B, $B12,'Performance data'!AD:AD) -> 0 | Z12: =J12 -> 9538 | AA12: =K12 -> 12000 | AC12: =Z12/X12-1 -> #DIV/0! | AD12: =Z12/Y12-1 -> #DIV/0! | AE12: =AA12/Z12-1 -> 0.25812539 | AG12: =$AA12*AG$1 -> 960 | AH12: =$AA12*AH$1 -> 960 | AI12: =$AA12*AI$1 -> 1080 | AJ12: =$AA12*AJ$1 -> 1080 | AK12: =$AA12*AK$1 -> 1080 | AL12: =$AA12*AL$1 -> 960 | AM12: =$AA12*AM$1 -> 960 | AN12: =$AA12*AN$1 -> 720 | ... AR12: =$AA12*AR$1 -> 840
B13: 25071 | C13: Nerdium LLC; Texas | D13: =VLOOKUP($B13, 'Performance data'!$B:$K, 3, 0) -> Central | E13: =VLOOKUP($B13, 'Performance data'!$B:$K, 4, 0) -> Emily | F13: =VLOOKUP($B13, 'Performance data'!$B:$K, 7, 0) -> 2025 | H13: =VLOOKUP($B13, 'Performance data'!$B:$K, 5, 0) -> NKD25 | I13: B | J13: =P13 -> 5488.99 | K13: 10000 | M13: Grow | O13: =SUMIF('Performance data'!$B:$B, $B13,'Performance data'!K:K) -> 0 | P13: =SUMIF('Performance data'!$B:$B, $B13,'Performance data'!L:L) -> 5488.99 | Q13: =SUMIF('Performance data'!$B:$B, $B13,'Performance data'!M:M) -> 0 | S13: =$P13/O13-1 -> #DIV/0! | T13: =P13/Q13-1 -> #DIV/0! | V13: =SUMIF('Performance data'!$B:$B, $B13,'Performance data'!Z:Z) -> 0 | W13: =SUMIF('Performance data'!$B:$B, $B13,'Performance data'!AA:AA) -> 0 | X13: =SUMIF('Performance data'!$B:$B, $B13,'Performance data'!AB:AB) -> 0 | Y13: =SUMIF('Performance data'!$B:$B, $B13,'Performance data'!AD:AD) -> 0 | Z13: =J13 -> 5488.99 | AA13: =K13 -> 10000 | AC13: =Z13/X13-1 -> #DIV/0! | AD13: =Z13/Y13-1 -> #DIV/0! | AE13: =AA13/Z13-1 -> 0.82182879 | AG13: =$AA13*AG$1 -> 800 | AH13: =$AA13*AH$1 -> 800 | AI13: =$AA13*AI$1 -> 900 | AJ13: =$AA13*AJ$1 -> 900 | AK13: =$AA13*AK$1 -> 900 | AL13: =$AA13*AL$1 -> 800 | AM13: =$AA13*AM$1 -> 800 | AN13: =$AA13*AN$1 -> 600 | ... AR13: =$AA13*AR$1 -> 700
B14: 25073 | C14: Mario Tricoci Hair Salons & Day Spas | D14: =VLOOKUP($B14, 'Performance data'!$B:$K, 3, 0) -> Central | E14: =VLOOKUP($B14, 'Performance data'!$B:$K, 4, 0) -> Emily | F14: =VLOOKUP($B14, 'Performance data'!$B:$K, 7, 0) -> 2025 | H14: =VLOOKUP($B14, 'Performance data'!$B:$K, 5, 0) -> NKD25 | I14: A | J14: =P14 -> 8904 | K14: 20000 | M14: Grow | O14: =SUMIF('Performance data'!$B:$B, $B14,'Performance data'!K:K) -> 0 | P14: =SUMIF('Performance data'!$B:$B, $B14,'Performance data'!L:L) -> 8904 | Q14: =SUMIF('Performance data'!$B:$B, $B14,'Performance data'!M:M) -> 0 | S14: =$P14/O14-1 -> #DIV/0! | T14: =P14/Q14-1 -> #DIV/0! | V14: =SUMIF('Performance data'!$B:$B, $B14,'Performance data'!Z:Z) -> 0 | W14: =SUMIF('Performance data'!$B:$B, $B14,'Performance data'!AA:AA) -> 0 | X14: =SUMIF('Performance data'!$B:$B, $B14,'Performance data'!AB:AB) -> 0 | Y14: =SUMIF('Performance data'!$B:$B, $B14,'Performance data'!AD:AD) -> 0 | Z14: =J14 -> 8904 | AA14: =K14 -> 20000 | AC14: =Z14/X14-1 -> #DIV/0! | AD14: =Z14/Y14-1 -> #DIV/0! | AE14: =AA14/Z14-1 -> 1.2461815 | AG14: =$AA14*AG$1 -> 1600 | AH14: =$AA14*AH$1 -> 1600 | AI14: =$AA14*AI$1 -> 1800 | AJ14: =$AA14*AJ$1 -> 1800 | AK14: =$AA14*AK$1 -> 1800 | AL14: =$AA14*AL$1 -> 1600 | AM14: =$AA14*AM$1 -> 1600 | AN14: =$AA14*AN$1 -> 1200 | ... AR14: =$AA14*AR$1 -> 1400
B15: 25074 | C15: Houstonian Campus, LLC | D15: =VLOOKUP($B15, 'Performance data'!$B:$K, 3, 0) -> Central | E15: =VLOOKUP($B15, 'Performance data'!$B:$K, 4, 0) -> Emily | F15: =VLOOKUP($B15, 'Performance data'!$B:$K, 7, 0) -> 2025 | H15: =VLOOKUP($B15, 'Performance data'!$B:$K, 5, 0) -> NKD25 | I15: A++ | J15: =P15 -> 6178.28 | K15: 12000 | M15: Grow | O15: =SUMIF('Performance data'!$B:$B, $B15,'Performance data'!K:K) -> 0 | P15: =SUMIF('Performance data'!$B:$B, $B15,'Performance data'!L:L) -> 6178.28 | Q15: =SUMIF('Performance data'!$B:$B, $B15,'Performance data'!M:M) -> 0 | S15: =$P15/O15-1 -> #DIV/0! | T15: =P15/Q15-1 -> #DIV/0! | V15: =SUMIF('Performance data'!$B:$B, $B15,'Performance data'!Z:Z) -> 0 | W15: =SUMIF('Performance data'!$B:$B, $B15,'Performance data'!AA:AA) -> 0 | X15: =SUMIF('Performance data'!$B:$B, $B15,'Performance data'!AB:AB) -> 0 | Y15: =SUMIF('Performance data'!$B:$B, $B15,'Performance data'!AD:AD) -> 0 | Z15: =J15 -> 6178.28 | AA15: =K15 -> 12000 | AC15: =Z15/X15-1 -> #DIV/0! | AD15: =Z15/Y15-1 -> #DIV/0! | AE15: =AA15/Z15-1 -> 0.94228814 | AG15: =$AA15*AG$1 -> 960 | AH15: =$AA15*AH$1 -> 960 | AI15: =$AA15*AI$1 -> 1080 | AJ15: =$AA15*AJ$1 -> 1080 | AK15: =$AA15*AK$1 -> 1080 | AL15: =$AA15*AL$1 -> 960 | AM15: =$AA15*AM$1 -> 960 | AN15: =$AA15*AN$1 -> 720 | ... AR15: =$AA15*AR$1 -> 840
B16: 25060 | C16: Nashville Hospitality/DBA Westin | D16: =VLOOKUP($B16, 'Performance data'!$B:$K, 3, 0) -> Southeast | E16: Emily | F16: =VLOOKUP($B16, 'Performance data'!$B:$K, 7, 0) -> 2025 | H16: NKD25 | I16: B | J16: =P16 -> 10814.48 | K16: 12000 | M16: Grow | O16: =SUMIF('Performance data'!$B:$B, $B16,'Performance data'!K:K) -> 0 | P16: =SUMIF('Performance data'!$B:$B, $B16,'Performance data'!L:L) -> 10814.48 | Q16: =SUMIF('Performance data'!$B:$B, $B16,'Performance data'!M:M) -> 0 | S16: =$P16/O16-1 -> #DIV/0! | T16: =P16/Q16-1 -> #DIV/0! | V16: =SUMIF('Performance data'!$B:$B, $B16,'Performance data'!Z:Z) -> 0 | W16: =SUMIF('Performance data'!$B:$B, $B16,'Performance data'!AA:AA) -> 0 | X16: =SUMIF('Performance data'!$B:$B, $B16,'Performance data'!AB:AB) -> 0 | Y16: =SUMIF('Performance data'!$B:$B, $B16,'Performance data'!AD:AD) -> 0 | Z16: =J16 -> 10814.48 | AA16: =K16 -> 12000 | AC16: =Z16/X16-1 -> #DIV/0! | AD16: =Z16/Y16-1 -> #DIV/0! | AE16: =AA16/Z16-1 -> 0.10962339 | AG16: =$AA16*AG$1 -> 960 | AH16: =$AA16*AH$1 -> 960 | AI16: =$AA16*AI$1 -> 1080 | AJ16: =$AA16*AJ$1 -> 1080 | AK16: =$AA16*AK$1 -> 1080 | AL16: =$AA16*AL$1 -> 960 | AM16: =$AA16*AM$1 -> 960 | AN16: =$AA16*AN$1 -> 720 | ... AR16: =$AA16*AR$1 -> 840
B17: NKD25 | C17: New doors 2025 | D17: Central | E17: Emily | F17: 2025 | H17: NKD25 | O17: 0 | P17: 0 | Q17: =SUMIFS('2025 budget doc'!$AC:$AC, '2025 budget doc'!$B:$B, "NKD25", '2025 budget doc'!$E:$E, $D17) -> 18000 | S17: =$P17/O17-1 -> #DIV/0! | T17: =P17/Q17-1 -> -1 | V17: 0 | W17: 0 | X17: 0 | Y17: =SUMIFS('2025 budget doc'!$L:$L, '2025 budget doc'!$B:$B, "NKD25", '2025 budget doc'!$E:$E, $D17) -> 100000 | Z17: =J17 -> 0 | AA17: =K17 -> 0 | AC17: =Z17/X17-1 -> #DIV/0! | AD17: =Z17/Y17-1 -> -1 | AE17: =AA17/Z17-1 -> #DIV/0! | AG17: =$AA17*AG$1 -> 0 | AH17: =$AA17*AH$1 -> 0 | AI17: =$AA17*AI$1 -> 0 | AJ17: =$AA17*AJ$1 -> 0 | AK17: =$AA17*AK$1 -> 0 | AL17: =$AA17*AL$1 -> 0 | AM17: =$AA17*AM$1 -> 0 | AN17: =$AA17*AN$1 -> 0 | ... AR17: =$AA17*AR$1 -> 0
AG18: =$AA18*AG$1 -> 0 | AH18: =$AA18*AH$1 -> 0 | AI18: =$AA18*AI$1 -> 0 | AJ18: =$AA18*AJ$1 -> 0 | AK18: =$AA18*AK$1 -> 0 | AL18: =$AA18*AL$1 -> 0 | AM18: =$AA18*AM$1 -> 0 | AN18: =$AA18*AN$1 -> 0 | ... AR18: =$AA18*AR$1 -> 0
B19: Total New Doors 2025 | G19: =COUNTIF(G12:G13, "Yes")+G17 -> 0 | J19: =SUM(J12:J17) -> 40923.75 | K19: =SUM(K12:K17) -> 66000 | O19: =SUM(O12:O17) -> 0 | P19: =SUM(P12:P17) -> 40923.75 | Q19: =SUM(Q12:Q17) -> 18000 | S19: =$P19/O19-1 -> #DIV/0! | T19: =P19/Q19-1 -> 1.2735417 | V19: =SUM(V12:V17) -> 0 | W19: =SUM(W12:W17) -> 0 | X19: =SUM(X12:X17) -> 0 | Y19: =SUM(Y12:Y17) -> 100000 | Z19: =SUM(Z12:Z17) -> 40923.75 | AA19: =SUM(AA12:AA17) -> 66000 | AC19: =Z19/X19-1 -> #DIV/0! | AD19: =Z19/Y19-1 -> -0.5907625 | AE19: =AA19/Z19-1 -> 0.61275543 | AG19: =SUM(AG12:AG17) -> 5280 | AH19: =SUM(AH12:AH17) -> 5280 | AI19: =SUM(AI12:AI17) -> 5940 | AJ19: =SUM(AJ12:AJ17) -> 5940 | AK19: =SUM(AK12:AK17) -> 5940 | AL19: =SUM(AL12:AL17) -> 5280 | AM19: =SUM(AM12:AM17) -> 5280 | AN19: =SUM(AN12:AN17) -> 3960 | ... AR19: =SUM(AR12:AR17) -> 4620
AY22: =AV23 -> 1 | AZ22: =AW23 -> 1 | BA22: =AX23+AV23 -> 2 | BB22: =AY23+AW23 -> 1 | BC22: =AZ23+AX23+AV23 -> 3 | BD22: =BA23+AY23+AW23 -> 2 | BE22: =BB23+AZ23+AX23+AV23 -> 3 | BF22: =BC23+BA23+AY23+AW23 -> 3
B23: NKD26 | C23: New doors 2026 | D23: Central | E23: Emily | F23: 2026 | G23: 8 | H23: NKD26 | I23: NKD26 | K23: 100000 | O23: 0 | P23: 0 | Q23: 0 | S23: =$P23/O23-1 -> #DIV/0! | T23: =P23/Q23-1 -> #DIV/0! | V23: 0 | W23: 0 | X23: 0 | Y23: 0 | Z23: =J23 -> 0 | AA23: =K23 -> 100000 | AC23: =Z23/X23-1 -> #DIV/0! | AD23: =Z23/Y23-1 -> #DIV/0! | AE23: =AA23/Z23-1 -> #DIV/0! | AG23: =AU23*5000+AU22*4000 -> 0 | AH23: =AV23*5000+AV22*4000 -> 5000 | AI23: =AW23*5000+AW22*4000 -> 5000 | AJ23: =AX23*5000+AX22*4000 -> 5000 | AK23: =AY23*5000+AY22*4000 -> 4000 | AL23: =AZ23*5000+AZ22*4000 -> 9000 | AM23: =BA23*5000+BA22*4000-2000 -> 11000 | AN23: =BB23*5000+BB22*4000 -> 4000 | AO23: =BC23*5000+BC22*4000 -> 17000 | AP23: =BD23*5000+BD22*4000 -> 13000 | AQ23: =BE23*5000+BE22*4000 -> 17000 | AR23: =BF23*5000+BF22*4000-2000 -> 10000 | AV23: 1 | AW23: 1 | AX23: 1 | AZ23: 1 | BA23: 1 | BC23: 1 | BD23: 1 | BE23: 1
B25: Total New Doors 2026 | G25: =COUNTIF(G22:G22, "Yes")+G23 -> 8 | J25: =SUM(J22:J23) -> 0 | K25: =SUM(K22:K23) -> 100000 | O25: =SUM(O22:O23) -> 0 | P25: =SUM(P22:P23) -> 0 | Q25: =SUM(Q22:Q23) -> 0 | S25: =$P25/O25-1 -> #DIV/0! | T25: =P25/Q25-1 -> #DIV/0! | V25: =SUM(V22:V23) -> 0 | W25: =SUM(W22:W23) -> 0 | X25: =SUM(X22:X23) -> 0 | Y25: =SUM(Y22:Y23) -> 0 | Z25: =SUM(Z22:Z23) -> 0 | AA25: =SUM(AA22:AA23) -> 100000 | AC25: =Z25/X25-1 -> #DIV/0! | AD25: =Z25/Y25-1 -> #DIV/0! | AE25: =AA25/Z25-1 -> #DIV/0! | AG25: =SUM(AG22:AG23) -> 0 | AH25: =SUM(AH22:AH23) -> 5000 | AI25: =SUM(AI22:AI23) -> 5000 | AJ25: =SUM(AJ22:AJ23) -> 5000 | AK25: =SUM(AK22:AK23) -> 4000 | AL25: =SUM(AL22:AL23) -> 9000 | AM25: =SUM(AM22:AM23) -> 11000 | AN25: =SUM(AN22:AN23) -> 4000 | ... AR25: =SUM(AR22:AR23) -> 10000

Sheet West
O1: Year to date | P1: Year to date | Q1: Year to date | S1: Year to date | T1: Year to date | V1: Full year | W1: Full year | X1: Full year | Y1: Full year | Z1: Full year | AA1: Full year | AC1: Full year | AD1: Full year | AE1: Full year | AG1: 0.08 | AH1: 0.08 | AI1: 0.09 | AJ1: 0.09 | AK1: 0.09 | AL1: 0.08 | AM1: 0.08 | AN1: 0.06 | AO1: 0.09 | AP1: 0.1 | AQ1: 0.09 | AR1: 0.07
B2: Customer Code | C2: Customer Name | D2: Region | E2: Sales person | F2: New door year | G2: Active? | H2: 2025 Cluster | I2: 2026 Cluster | J2: 2025A | K2: 2026B | L2: Size indicator | M2: Customer Growth Class | O2: 2024 YTD | P2: 2025 YTD | Q2: 2025B YTD | S2: 25 vs 24 % | T2: 25 vs 25B % | V2: 2022 | W2: 2023 | X2: 2024 | Y2: 2025B | Z2: 2025A | AA2: 2026B | AC2: 25 vs 24 % | AD2: 25 vs 25B % | AE2: 26B vs 25A % | AG2: 46023 | AH2: 46054 | AI2: 46082 | AJ2: 46113 | AK2: 46143 | AL2: 46174 | AM2: 46204 | AN2: 46235 | AO2: 46266 | AP2: 46296 | AQ2: 46327 | AR2: 46357
B3: 25012 | C3: Rosewood Sense Spa, CA | D3: =VLOOKUP($B3, 'Performance data'!$B:$K, 3, 0) -> West | E3: Erin | F3: =VLOOKUP($B3, 'Performance data'!$B:$K, 7, 0) -> 2022 | H3: =VLOOKUP($B3, 'Performance data'!$B:$K, 5, 0) -> A+ | I3: Lost | J3: =P3 -> 52636.33 | M3: Lose | O3: =SUMIF('Performance data'!$B:$B, $B3,'Performance data'!K:K) -> 104398.38 | P3: =SUMIF('Performance data'!$B:$B, $B3,'Performance data'!L:L) -> 52636.33 | Q3: =SUMIF('Performance data'!$B:$B, $B3,'Performance data'!M:M) -> 120000 | S3: =$P3/O3-1 -> -0.49581277 | T3: =P3/Q3-1 -> -0.56136392 | V3: =SUMIF('Performance data'!$B:$B, $B3,'Performance data'!Z:Z) -> 127800.66 | W3: =SUMIF('Performance data'!$B:$B, $B3,'Performance data'!AA:AA) -> 127251.66 | X3: =SUMIF('Performance data'!$B:$B, $B3,'Performance data'!AB:AB) -> 104398.38 | Y3: =SUMIF('Performance data'!$B:$B, $B3,'Performance data'!AD:AD) -> 120000 | Z3: =J3 -> 52636.33 | AA3: =K3 -> 0 | AC3: =Z3/X3-1 -> -0.49581277 | AD3: =Z3/Y3-1 -> -0.56136392 | AE3: =AA3/Z3-1 -> -1 | AG3: =$AA3*AG$1 -> 0 | AH3: =$AA3*AH$1 -> 0 | AI3: =$AA3*AI$1 -> 0 | AJ3: =$AA3*AJ$1 -> 0 | AK3: =$AA3*AK$1 -> 0 | AL3: =$AA3*AL$1 -> 0 | AM3: =$AA3*AM$1 -> 0 | AN3: =$AA3*AN$1 -> 0 | ... AR3: =$AA3*AR$1 -> 0
B4: 25027 | C4: San Manuel Entert.; Yaamava Resort; Highland | D4: =VLOOKUP($B4, 'Performance data'!$B:$K, 3, 0) -> West | E4: Erin | F4: =VLOOKUP($B4, 'Performance data'!$B:$K, 7, 0) -> 2022 | H4: =VLOOKUP($B4, 'Performance data'!$B:$K, 5, 0) -> A+ | I4: A+++ | J4: =P4 -> 113790.07 | K4: 120000 | M4: Grow | O4: =SUMIF('Performance data'!$B:$B, $B4,'Performance data'!K:K) -> 103728.39 | P4: =SUMIF('Performance data'!$B:$B, $B4,'Performance data'!L:L) -> 113790.07 | Q4: =SUMIF('Performance data'!$B:$B, $B4,'Performance data'!M:M) -> 115000 | S4: =$P4/O4-1 -> 0.097000252 | T4: =P4/Q4-1 -> -0.01052113 | V4: =SUMIF('Performance data'!$B:$B, $B4,'Performance data'!Z:Z) -> 19362.58 | W4: =SUMIF('Performance data'!$B:$B, $B4,'Performance data'!AA:AA) -> 57225.3 | X4: =SUMIF('Performance data'!$B:$B, $B4,'Performance data'!AB:AB) -> 103728.39 | Y4: =SUMIF('Performance data'!$B:$B, $B4,'Performance data'!AD:AD) -> 115000 | Z4: =J4 -> 113790.07 | AA4: =K4 -> 120000 | AC4: =Z4/X4-1 -> 0.097000252 | AD4: =Z4/Y4-1 -> -0.01052113 | AE4: =AA4/Z4-1 -> 0.054573567 | AG4: =$AA4*AG$1 -> 9600 | AH4: =$AA4*AH$1 -> 9600 | AI4: =$AA4*AI$1 -> 10800 | AJ4: =$AA4*AJ$1 -> 10800 | AK4: =$AA4*AK$1 -> 10800 | AL4: =$AA4*AL$1 -> 9600 | AM4: =$AA4*AM$1 -> 9600 | AN4: =$AA4*AN$1 -> 7200 | ... AR4: =$AA4*AR$1 -> 8400
B5: 25032 | C5: Four Seasons Hotel Las Vegas | D5: =VLOOKUP($B5, 'Performance data'!$B:$K, 3, 0) -> West | E5: Erin | F5: =VLOOKUP($B5, 'Performance data'!$B:$K, 7, 0) -> 2023 | H5: =VLOOKUP($B5, 'Performance data'!$B:$K, 5, 0) -> A+ | I5: A+ | J5: =P5 -> 44420.93 | K5: 50000 | M5: Grow | O5: =SUMIF('Performance data'!$B:$B, $B5,'Performance data'!K:K) -> 50110.28 | P5: =SUMIF('Performance data'!$B:$B, $B5,'Performance data'!L:L) -> 44420.93 | Q5: =SUMIF('Performance data'!$B:$B, $B5,'Performance data'!M:M) -> 55000 | S5: =$P5/O5-1 -> -0.11353658 | T5: =P5/Q5-1 -> -0.19234673 | V5: =SUMIF('Performance data'!$B:$B, $B5,'Performance data'!Z:Z) -> 0 | W5: =SUMIF('Performance data'!$B:$B, $B5,'Performance data'!AA:AA) -> 38782.75 | X5: =SUMIF('Performance data'!$B:$B, $B5,'Performance data'!AB:AB) -> 50110.28 | Y5: =SUMIF('Performance data'!$B:$B, $B5,'Performance data'!AD:AD) -> 55000 | Z5: =J5 -> 44420.93 | AA5: =K5 -> 50000 | AC5: =Z5/X5-1 -> -0.11353658 | AD5: =Z5/Y5-1 -> -0.19234673 | AE5: =AA5/Z5-1 -> 0.12559552 | AG5: =$AA5*AG$1 -> 4000 | AH5: =$AA5*AH$1 -> 4000 | AI5: =$AA5*AI$1 -> 4500 | AJ5: =$AA5*AJ$1 -> 4500 | AK5: =$AA5*AK$1 -> 4500 | AL5: =$AA5*AL$1 -> 4000 | AM5: =$AA5*AM$1 -> 4000 | AN5: =$AA5*AN$1 -> 3000 | ... AR5: =$AA5*AR$1 -> 3500
B6: 25038 | C6: Lemon & Honey Day Spa; Orange, CA | D6: =VLOOKUP($B6, 'Performance data'!$B:$K, 3, 0) -> West | E6: Erin | F6: =VLOOKUP($B6, 'Performance data'!$B:$K, 7, 0) -> 2023 | H6: =VLOOKUP($B6, 'Performance data'!$B:$K, 5, 0) -> A | I6: B | J6: =P6 -> 13457.21 | K6: 13000 | M6: Maintain | O6: =SUMIF('Performance data'!$B:$B, $B6,'Performance data'!K:K) -> 28530.96 | P6: =SUMIF('Performance data'!$B:$B, $B6,'Performance data'!L:L) -> 13457.21 | Q6: =SUMIF('Performance data'!$B:$B, $B6,'Performance data'!M:M) -> 26000 | S6: =$P6/O6-1 -> -0.52832958 | T6: =P6/Q6-1 -> -0.482415 | V6: =SUMIF('Performance data'!$B:$B, $B6,'Performance data'!Z:Z) -> 0 | W6: =SUMIF('Performance data'!$B:$B, $B6,'Performance data'!AA:AA) -> 5204.37 | X6: =SUMIF('Performance data'!$B:$B, $B6,'Performance data'!AB:AB) -> 28530.96 | Y6: =SUMIF('Performance data'!$B:$B, $B6,'Performance data'!AD:AD) -> 26000 | Z6: =J6 -> 13457.21 | AA6: =K6 -> 13000 | AC6: =Z6/X6-1 -> -0.52832958 | AD6: =Z6/Y6-1 -> -0.482415 | AE6: =AA6/Z6-1 -> -0.033975096 | AG6: =$AA6*AG$1 -> 1040 | AH6: =$AA6*AH$1 -> 1040 | AI6: =$AA6*AI$1 -> 1170 | AJ6: =$AA6*AJ$1 -> 1170 | AK6: =$AA6*AK$1 -> 1170 | AL6: =$AA6*AL$1 -> 1040 | AM6: =$AA6*AM$1 -> 1040 | AN6: =$AA6*AN$1 -> 780 | ... AR6: =$AA6*AR$1 -> 910
B7: 25004 | C7: Teton Mountain Lodge | D7: =VLOOKUP($B7, 'Performance data'!$B:$K, 3, 0) -> West | E7: Erin | F7: =VLOOKUP($B7, 'Performance data'!$B:$K, 7, 0) -> 2021 | H7: =VLOOKUP($B7, 'Performance data'!$B:$K, 5, 0) -> B | I7: C | J7: =P7 -> 6008.52 | K7: 6000 | M7: Maintain | O7: =SUMIF('Performance data'!$B:$B, $B7,'Performance data'!K:K) -> 10917.56 | P7: =SUMIF('Performance data'!$B:$B, $B7,'Performance data'!L:L) -> 6008.52 | Q7: =SUMIF('Performance data'!$B:$B, $B7,'Performance data'!M:M) -> 12000 | S7: =$P7/O7-1 -> -0.44964626 | T7: =P7/Q7-1 -> -0.49929 | V7: =SUMIF('Performance data'!$B:$B, $B7,'Performance data'!Z:Z) -> 5634 | W7: =SUMIF('Performance data'!$B:$B, $B7,'Performance data'!AA:AA) -> 7158.06 | X7: =SUMIF('Performance data'!$B:$B, $B7,'Performance data'!AB:AB) -> 10917.56 | Y7: =SUMIF('Performance data'!$B:$B, $B7,'Performance data'!AD:AD) -> 12000 | Z7: =J7 -> 6008.52 | AA7: =K7 -> 6000 | AC7: =Z7/X7-1 -> -0.44964626 | AD7: =Z7/Y7-1 -> -0.49929 | AE7: =AA7/Z7-1 -> -0.0014179865 | AG7: =$AA7*AG$1 -> 480 | AH7: =$AA7*AH$1 -> 480 | AI7: =$AA7*AI$1 -> 540 | AJ7: =$AA7*AJ$1 -> 540 | AK7: =$AA7*AK$1 -> 540 | AL7: =$AA7*AL$1 -> 480 | AM7: =$AA7*AM$1 -> 480 | AN7: =$AA7*AN$1 -> 360 | ... AR7: =$AA7*AR$1 -> 420
B8: 25000 | C8: West Coast Lifestyles Inc.; CA | D8: =VLOOKUP($B8, 'Performance data'!$B:$K, 3, 0) -> West | E8: Erin | F8: =VLOOKUP($B8, 'Performance data'!$B:$K, 7, 0) -> 2021 | H8: =VLOOKUP($B8, 'Performance data'!$B:$K, 5, 0) -> C | I8: Lost | J8: =P8 -> 737 | M8: Lose | O8: =SUMIF('Performance data'!$B:$B, $B8,'Performance data'!K:K) -> 1539.92 | P8: =SUMIF('Performance data'!$B:$B, $B8,'Performance data'!L:L) -> 737 | Q8: =SUMIF('Performance data'!$B:$B, $B8,'Performance data'!M:M) -> 1500 | S8: =$P8/O8-1 -> -0.52140371 | T8: =P8/Q8-1 -> -0.50866667 | V8: =SUMIF('Performance data'!$B:$B, $B8,'Performance data'!Z:Z) -> 5749.65 | W8: =SUMIF('Performance data'!$B:$B, $B8,'Performance data'!AA:AA) -> 7017.28 | X8: =SUMIF('Performance data'!$B:$B, $B8,'Performance data'!AB:AB) -> 1539.92 | Y8: =SUMIF('Performance data'!$B:$B, $B8,'Performance data'!AD:AD) -> 1500 | Z8: =J8 -> 737 | AA8: =K8 -> 0 | AC8: =Z8/X8-1 -> -0.52140371 | AD8: =Z8/Y8-1 -> -0.50866667 | AE8: =AA8/Z8-1 -> -1 | AG8: =$AA8*AG$1 -> 0 | AH8: =$AA8*AH$1 -> 0 | AI8: =$AA8*AI$1 -> 0 | AJ8: =$AA8*AJ$1 -> 0 | AK8: =$AA8*AK$1 -> 0 | AL8: =$AA8*AL$1 -> 0 | AM8: =$AA8*AM$1 -> 0 | AN8: =$AA8*AN$1 -> 0 | ... AR8: =$AA8*AR$1 -> 0
B9: 25015 | C9: Gateway Canyon Resort & Spa; CO | D9: =VLOOKUP($B9, 'Performance data'!$B:$K, 3, 0) -> West | E9: Erin | F9: =VLOOKUP($B9, 'Performance data'!$B:$K, 7, 0) -> 2022 | H9: =VLOOKUP($B9, 'Performance data'!$B:$K, 5, 0) -> C | I9: C | J9: =P9 -> 1573.68 | O9: =SUMIF('Performance data'!$B:$B, $B9,'Performance data'!K:K) -> 2717.32 | P9: =SUMIF('Performance data'!$B:$B, $B9,'Performance data'!L:L) -> 1573.68 | Q9: =SUMIF('Performance data'!$B:$B, $B9,'Performance data'!M:M) -> 3000 | S9: =$P9/O9-1 -> -0.42087056 | T9: =P9/Q9-1 -> -0.47544 | V9: =SUMIF('Performance data'!$B:$B, $B9,'Performance data'!Z:Z) -> 9631.1 | W9: =SUMIF('Performance data'!$B:$B, $B9,'Performance data'!AA:AA) -> 6958.48 | X9: =SUMIF('Performance data'!$B:$B, $B9,'Performance data'!AB:AB) -> 2717.32 | Y9: =SUMIF('Performance data'!$B:$B, $B9,'Performance data'!AD:AD) -> 3000 | Z9: =J9 -> 1573.68 | AA9: =K9 -> 0 | AC9: =Z9/X9-1 -> -0.42087056 | AD9: =Z9/Y9-1 -> -0.47544 | AE9: =AA9/Z9-1 -> -1 | AG9: =$AA9*AG$1 -> 0 | AH9: =$AA9*AH$1 -> 0 | AI9: =$AA9*AI$1 -> 0 | AJ9: =$AA9*AJ$1 -> 0 | AK9: =$AA9*AK$1 -> 0 | AL9: =$AA9*AL$1 -> 0 | AM9: =$AA9*AM$1 -> 0 | AN9: =$AA9*AN$1 -> 0 | ... AR9: =$AA9*AR$1 -> 0
B10: 25036 | C10: MacArthur Place; LÁuberge de Sonoma LLC; CA | D10: =VLOOKUP($B10, 'Performance data'!$B:$K, 3, 0) -> West | E10: Erin | F10: =VLOOKUP($B10, 'Performance data'!$B:$K, 7, 0) -> 2023 | H10: =VLOOKUP($B10, 'Performance data'!$B:$K, 5, 0) -> C | I10: C | J10: =P10 -> 654.34 | O10: =SUMIF('Performance data'!$B:$B, $B10,'Performance data'!K:K) -> 2357.58 | P10: =SUMIF('Performance data'!$B:$B, $B10,'Performance data'!L:L) -> 654.34 | Q10: =SUMIF('Performance data'!$B:$B, $B10,'Performance data'!M:M) -> 5000 | S10: =$P10/O10-1 -> -0.72245268 | T10: =P10/Q10-1 -> -0.869132 | V10: =SUMIF('Performance data'!$B:$B, $B10,'Performance data'!Z:Z) -> 0 | W10: =SUMIF('Performance data'!$B:$B, $B10,'Performance data'!AA:AA) -> 5919.87 | X10: =SUMIF('Performance data'!$B:$B, $B10,'Performance data'!AB:AB) -> 2357.58 | Y10: =SUMIF('Performance data'!$B:$B, $B10,'Performance data'!AD:AD) -> 5000 | Z10: =J10 -> 654.34 | AA10: =K10 -> 0 | AC10: =Z10/X10-1 -> -0.72245268 | AD10: =Z10/Y10-1 -> -0.869132 | AE10: =AA10/Z10-1 -> -1 | AG10: =$AA10*AG$1 -> 0 | AH10: =$AA10*AH$1 -> 0 | AI10: =$AA10*AI$1 -> 0 | AJ10: =$AA10*AJ$1 -> 0 | AK10: =$AA10*AK$1 -> 0 | AL10: =$AA10*AL$1 -> 0 | AM10: =$AA10*AM$1 -> 0 | AN10: =$AA10*AN$1 -> 0 | ... AR10: =$AA10*AR$1 -> 0
