Workbook

Sheet Summary
B2: GBP | C2: Full Year | I2: Full Year | M2: Total sales
C3: 25A | D3: 25B | E3: 25F vs 25B | F3: 24A | G3: 25F vs 24A | I3: 26B | J3: 25A | K3: 26B vs 25F | M3: 46023 | N3: 46054 | O3: 46082 | P3: 46113 | Q3: 46143 | R3: 46174 | S3: 46204 | T3: 46235 | U3: 46266 | V3: 46296 | W3: 46327 | X3: 46357
B4: Spa | C4: ='UK Spa Budget'!Z13+'UK Spa Budget'!Z27+'UK Spa Budget'!Z33 -> 153854.61 | D4: ='UK Spa Budget'!Y13+'UK Spa Budget'!Y27+'UK Spa Budget'!Y33 -> 229000 | E4: =IFERROR(C4/D4-1, "N/A") -> -0.32814581 | F4: ='UK Spa Budget'!X13+'UK Spa Budget'!X27+'UK Spa Budget'!X33 -> 103321.21 | G4: =IFERROR(C4/F4-1, "N/A") -> 0.48909028 | I4: ='UK Spa Budget'!AA13+'UK Spa Budget'!AA27+'UK Spa Budget'!AA33 -> 299000 | J4: =C4 -> 153854.61 | K4: =IFERROR(I4/J4-1, "N/A") -> 0.94339318 | M4: ='UK Spa Budget'!AG13+'UK Spa Budget'!AG27+'UK Spa Budget'!AG33 -> 15920 | N4: ='UK Spa Budget'!AH13+'UK Spa Budget'!AH27+'UK Spa Budget'!AH33 -> 19920 | O4: ='UK Spa Budget'!AI13+'UK Spa Budget'!AI27+'UK Spa Budget'!AI33 -> 21910 | P4: ='UK Spa Budget'!AJ13+'UK Spa Budget'!AJ27+'UK Spa Budget'!AJ33 -> 21910 | Q4: ='UK Spa Budget'!AK13+'UK Spa Budget'!AK27+'UK Spa Budget'!AK33 -> 24910 | R4: ='UK Spa Budget'!AL13+'UK Spa Budget'!AL27+'UK Spa Budget'!AL33 -> 21925 | S4: ='UK Spa Budget'!AM13+'UK Spa Budget'!AM27+'UK Spa Budget'!AM33 -> 23930 | T4: ='UK Spa Budget'!AN13+'UK Spa Budget'!AN27+'UK Spa Budget'!AN33 -> 21940 | ... X4: ='UK Spa Budget'!AR13+'UK Spa Budget'!AR27+'UK Spa Budget'!AR33 -> 26925
B5: Retail | C5: ='UK Retail Budget'!Z6 -> 143746.56 | D5: ='UK Retail Budget'!Y6 -> 137000 | E5: =IFERROR(C5/D5-1, "N/A") -> 0.049244964 | F5: ='UK Retail Budget'!X6 -> 147667.26 | G5: =IFERROR(C5/F5-1, "N/A") -> -0.026550909 | I5: ='UK Retail Budget'!AA6 -> 160000 | J5: =C5 -> 143746.56 | K5: =IFERROR(I5/J5-1, "N/A") -> 0.11307011 | M5: ='UK Retail Budget'!AG6 -> 12800 | N5: ='UK Retail Budget'!AH6 -> 12800 | O5: ='UK Retail Budget'!AI6 -> 14400 | P5: ='UK Retail Budget'!AJ6 -> 14400 | Q5: ='UK Retail Budget'!AK6 -> 14400 | R5: ='UK Retail Budget'!AL6 -> 12000 | S5: ='UK Retail Budget'!AM6 -> 11200 | T5: ='UK Retail Budget'!AN6 -> 9600 | ... X5: ='UK Retail Budget'!AR6 -> 12000
B6: Global eTailer | C6: ='Global eTailer Budget'!Z5 -> 28083.11 | D6: ='Global eTailer Budget'!Y5 -> 15000 | E6: =IFERROR(C6/D6-1, "N/A") -> 0.87220733 | F6: ='Global eTailer Budget'!X5 -> 8649.66 | G6: =IFERROR(C6/F6-1, "N/A") -> 2.2467299 | I6: ='Global eTailer Budget'!AA5 -> 30000 | J6: =C6 -> 28083.11 | K6: =IFERROR(I6/J6-1, "N/A") -> 0.068257754 | M6: ='Global eTailer Budget'!AG5 -> 2500 | N6: ='Global eTailer Budget'!AH5 -> 2500 | O6: ='Global eTailer Budget'!AI5 -> 2500 | P6: ='Global eTailer Budget'!AJ5 -> 2500 | Q6: ='Global eTailer Budget'!AK5 -> 2500 | R6: ='Global eTailer Budget'!AL5 -> 2500 | S6: ='Global eTailer Budget'!AM5 -> 2500 | T6: ='Global eTailer Budget'!AN5 -> 2500 | ... X6: ='Global eTailer Budget'!AR5 -> 2500
B8: Total UK | C8: =SUM(C4:C6) -> 325684.28 | D8: =SUM(D4:D6) -> 381000 | E8: =IFERROR(C8/D8-1, "N/A") -> -0.14518562 | F8: =SUM(F4:F6) -> 259638.13 | G8: =IFERROR(C8/F8-1, "N/A") -> 0.2543777 | I8: =SUM(I4:I6) -> 489000 | J8: =SUM(J4:J6) -> 325684.28 | K8: =IFERROR(I8/J8-1, "N/A") -> 0.50145411 | M8: =SUM(M4:M6) -> 31220 | N8: =SUM(N4:N6) -> 35220 | O8: =SUM(O4:O6) -> 38810 | P8: =SUM(P4:P6) -> 38810 | Q8: =SUM(Q4:Q6) -> 41810 | R8: =SUM(R4:R6) -> 36425 | S8: =SUM(S4:S6) -> 37630 | T8: =SUM(T4:T6) -> 34040 | ... X8: =SUM(X4:X6) -> 41425
B13: EUR | C13: Full Year | I13: Full Year
C14: 25A | D14: 25B | E14: 25F vs 25B | F14: 24A | G14: 25F vs 24A | I14: 26B | J14: 25A | K14: 26B vs 25F | M14: 46023 | N14: 46054 | O14: 46082 | P14: 46113 | Q14: 46143 | R14: 46174 | S14: 46204 | T14: 46235 | U14: 46266 | V14: 46296 | W14: 46327 | X14: 46357
B15: Spa | C15: =C4*1.3 -> 200010.99 | D15: =D4*1.2 -> 274800 | E15: =IFERROR(C15/D15-1, "N/A") -> -0.27215796 | F15: =F4*1.16 -> 119852.6 | G15: =IFERROR(C15/F15-1, "N/A") -> 0.66880808 | I15: =I4*1.16 -> 346840 | J15: =C15 -> 200010.99 | K15: =IFERROR(I15/J15-1, "N/A") -> 0.73410468 | M15: =M4*1.16 -> 18467.2 | N15: =N4*1.16 -> 23107.2 | O15: =O4*1.16 -> 25415.6 | P15: =P4*1.16 -> 25415.6 | Q15: =Q4*1.16 -> 28895.6 | R15: =R4*1.16 -> 25433 | S15: =S4*1.16 -> 27758.8 | T15: =T4*1.16 -> 25450.4 | ... X15: =X4*1.16 -> 31233
B16: Retail | C16: =C5*1.23 -> 176808.27 | D16: =D5*1.2 -> 164400 | E16: =IFERROR(C16/D16-1, "N/A") -> 0.075476088 | F16: =F5*1.17 -> 172770.69 | G16: =IFERROR(C16/F16-1, "N/A") -> 0.023369557 | I16: =I5*1.16 -> 185600 | J16: =C16 -> 176808.27 | K16: =IFERROR(I16/J16-1, "N/A") -> 0.049724661 | M16: =M5*1.16 -> 14848 | N16: =N5*1.16 -> 14848 | O16: =O5*1.16 -> 16704 | P16: =P5*1.16 -> 16704 | Q16: =Q5*1.16 -> 16704 | R16: =R5*1.16 -> 13920 | S16: =S5*1.16 -> 12992 | T16: =T5*1.16 -> 11136 | ... X16: =X5*1.16 -> 13920
B17: Global eTailer | C17: =C6*1.24 -> 34823.056 | D17: =D6*1.2 -> 18000 | E17: =IFERROR(C17/D17-1, "N/A") -> 0.93461424 | F17: =F6*1.16 -> 10033.606 | G17: =IFERROR(C17/F17-1, "N/A") -> 2.4706423 | I17: =I6*1.16 -> 34800 | J17: =C17 -> 34823.056 | K17: =IFERROR(I17/J17-1, "N/A") -> -0.00066210156 | M17: =M6*1.16 -> 2900 | N17: =N6*1.16 -> 2900 | O17: =O6*1.16 -> 2900 | P17: =P6*1.16 -> 2900 | Q17: =Q6*1.16 -> 2900 | R17: =R6*1.16 -> 2900 | S17: =S6*1.16 -> 2900 | T17: =T6*1.16 -> 2900 | ... X17: =X6*1.16 -> 2900
B19: Total UK | C19: =SUM(C15:C17) -> 411642.32 | D19: =SUM(D15:D17) -> 457200 | E19: =IFERROR(C19/D19-1, "N/A") -> -0.099644973 | F19: =SUM(F15:F17) -> 302656.9 | G19: =IFERROR(C19/F19-1, "N/A") -> 0.36009559 | I19: =SUM(I15:I17) -> 567240 | J19: =SUM(J15:J17) -> 411642.32 | K19: =IFERROR(I19/J19-1, "N/A") -> 0.37799243 | M19: =SUM(M15:M17) -> 36215.2 | N19: =SUM(N15:N17) -> 40855.2 | O19: =SUM(O15:O17) -> 45019.6 | P19: =SUM(P15:P17) -> 45019.6 | Q19: =SUM(Q15:Q17) -> 48499.6 | R19: =SUM(R15:R17) -> 42253 | S19: =SUM(S15:S17) -> 43650.8 | T19: =SUM(T15:T17) -> 39486.4 | ... X19: =SUM(X15:X17) -> 48053

Sheet UK Spa Budget
O1: Year to date | P1: Year to date | Q1: Year to date | S1: Year to date | T1: Year to date | V1: Full year | W1: Full year | X1: Full year | Y1: Full year | Z1: Full year | AA1: Full year | AC1: Full year | AD1: Full year | AE1: Full year | AG1: 0.08 | AH1: 0.08 | AI1: 0.09 | AJ1: 0.09 | AK1: 0.09 | AL1: 0.075 | AM1: 0.07 | AN1: 0.06 | AO1: 0.095 | AP1: 0.105 | AQ1: 0.09 | AR1: 0.075
B2: Customer Code | C2: Customer Name | D2: Country | E2: Region | F2: Customer Map | G2: New door year | H2: Active? | I2: 2025 Cluster | J2: 2025A | K2: 2026B | L2: Size indicator | M2: Customer Growth Class | O2: 2024 YTD | P2: 2025 YTD | Q2: 2025B YTD | S2: 25 vs 24 % | T2: 25 vs 25B % | V2: 2022 | W2: 2023 | X2: 2024 | Y2: 2025B | Z2: 2025F | AA2: 2026B | AC2: 25 vs 24 % | AD2: 25 vs 25B % | AE2: 26B vs 25F % | AG2: 46023 | AH2: 46054 | AI2: 46082 | AJ2: 46113 | AK2: 46143 | AL2: 46174 | AM2: 46204 | AN2: 46235 | AO2: 46266 | AP2: 46296 | AQ2: 46327 | AR2: 46357
B3: 51184 | C3: The Connaught Hotel | D3: =VLOOKUP($B3, 'Performance Data'!$B:$K, 3, 0) -> UK | E3: =VLOOKUP($B3, 'Performance Data'!$B:$K, 5, 0) -> Spa | F3: =VLOOKUP($B3, 'Performance Data'!$B:$K, 6, 0) -> Spas / Hotels | G3: =VLOOKUP($B3, 'Performance Data'!$B:$K, 9, 0) -> 2023 | I3: =VLOOKUP($B3, 'Performance Data'!$B:$K, 7, 0) -> BB | J3: =P3 -> 19779.42 | K3: 20000 | O3: =SUMIF('Performance Data'!$B:$B, $B3,'Performance Data'!N:N) -> 26665.91 | P3: =SUMIF('Performance Data'!$B:$B, $B3,'Performance Data'!O:O) -> 19779.42 | Q3: =SUMIF('Performance Data'!$B:$B, $B3,'Performance Data'!P:P) -> 20000 | S3: =$P3/O3-1 -> -0.2582507 | T3: =P3/Q3-1 -> -0.011029 | V3: =SUMIF('Performance Data'!$B:$B, $B3,'Performance Data'!AC:AC) -> 0 | W3: =SUMIF('Performance Data'!$B:$B, $B3,'Performance Data'!AD:AD) -> 6655.7 | X3: =SUMIF('Performance Data'!$B:$B, $B3,'Performance Data'!AE:AE) -> 26665.91 | Y3: =SUMIF('Performance Data'!$B:$B, $B3,'Performance Data'!AG:AG) -> 20000 | Z3: =J3 -> 19779.42 | AA3: =K3 -> 20000 | AC3: =Z3/X3-1 -> -0.2582507 | AD3: =Z3/Y3-1 -> -0.011029 | AE3: =AA3/Z3-1 -> 0.011151995 | AG3: =$AA3*AG$1 -> 1600 | AH3: =$AA3*AH$1 -> 1600 | AI3: =$AA3*AI$1 -> 1800 | AJ3: =$AA3*AJ$1 -> 1800 | AK3: =$AA3*AK$1 -> 1800 | AL3: =$AA3*AL$1 -> 1500 | AM3: =$AA3*AM$1 -> 1400 | AN3: =$AA3*AN$1 -> 1200 | ... AR3: =$AA3*AR$1 -> 1500
B4: 51185 | C4: Four Seasons Hotel London | D4: =VLOOKUP($B4, 'Performance Data'!$B:$K, 3, 0) -> UK | E4: =VLOOKUP($B4, 'Performance Data'!$B:$K, 5, 0) -> Spa | F4: =VLOOKUP($B4, 'Performance Data'!$B:$K, 6, 0) -> Spas / Hotels | G4: =VLOOKUP($B4, 'Performance Data'!$B:$K, 9, 0) -> 2024 | I4: =VLOOKUP($B4, 'Performance Data'!$B:$K, 7, 0) -> NKD24 | J4: =P4 -> 3448.59 | K4: 5000 | O4: =SUMIF('Performance Data'!$B:$B, $B4,'Performance Data'!N:N) -> 4761.01 | P4: =SUMIF('Performance Data'!$B:$B, $B4,'Performance Data'!O:O) -> 3448.59 | Q4: =SUMIF('Performance Data'!$B:$B, $B4,'Performance Data'!P:P) -> 5000 | S4: =$P4/O4-1 -> -0.27566 | T4: =P4/Q4-1 -> -0.310282 | V4: =SUMIF('Performance Data'!$B:$B, $B4,'Performance Data'!AC:AC) -> 0 | W4: =SUMIF('Performance Data'!$B:$B, $B4,'Performance Data'!AD:AD) -> 0 | X4: =SUMIF('Performance Data'!$B:$B, $B4,'Performance Data'!AE:AE) -> 4761.01 | Y4: =SUMIF('Performance Data'!$B:$B, $B4,'Performance Data'!AG:AG) -> 5000 | Z4: =J4 -> 3448.59 | AA4: =K4 -> 5000 | AC4: =Z4/X4-1 -> -0.27566 | AD4: =Z4/Y4-1 -> -0.310282 | AE4: =AA4/Z4-1 -> 0.44986792 | AG4: =$AA4*AG$1 -> 400 | AH4: =$AA4*AH$1 -> 400 | AI4: =$AA4*AI$1 -> 450 | AJ4: =$AA4*AJ$1 -> 450 | AK4: =$AA4*AK$1 -> 450 | AL4: =$AA4*AL$1 -> 375 | AM4: =$AA4*AM$1 -> 350 | AN4: =$AA4*AN$1 -> 300 | ... AR4: =$AA4*AR$1 -> 375
B5: 51186 | C5: hope street hotel; Liverpool | D5: =VLOOKUP($B5, 'Performance Data'!$B:$K, 3, 0) -> UK | E5: =VLOOKUP($B5, 'Performance Data'!$B:$K, 5, 0) -> Spa | F5: =VLOOKUP($B5, 'Performance Data'!$B:$K, 6, 0) -> Spas / Hotels | G5: =VLOOKUP($B5, 'Performance Data'!$B:$K, 9, 0) -> 2023 | I5: =VLOOKUP($B5, 'Performance Data'!$B:$K, 7, 0) -> BB | J5: =P5 -> 1162.46 | K5: 2000 | O5: =SUMIF('Performance Data'!$B:$B, $B5,'Performance Data'!N:N) -> 8045.51 | P5: =SUMIF('Performance Data'!$B:$B, $B5,'Performance Data'!O:O) -> 1162.46 | Q5: =SUMIF('Performance Data'!$B:$B, $B5,'Performance Data'!P:P) -> 10000 | S5: =$P5/O5-1 -> -0.85551444 | T5: =P5/Q5-1 -> -0.883754 | V5: =SUMIF('Performance Data'!$B:$B, $B5,'Performance Data'!AC:AC) -> 0 | W5: =SUMIF('Performance Data'!$B:$B, $B5,'Performance Data'!AD:AD) -> 2266.78 | X5: =SUMIF('Performance Data'!$B:$B, $B5,'Performance Data'!AE:AE) -> 8045.51 | Y5: =SUMIF('Performance Data'!$B:$B, $B5,'Performance Data'!AG:AG) -> 10000 | Z5: =J5 -> 1162.46 | AA5: =K5 -> 2000 | AC5: =Z5/X5-1 -> -0.85551444 | AD5: =Z5/Y5-1 -> -0.883754 | AE5: =AA5/Z5-1 -> 0.72048931 | AG5: =$AA5*AG$1 -> 160 | AH5: =$AA5*AH$1 -> 160 | AI5: =$AA5*AI$1 -> 180 | AJ5: =$AA5*AJ$1 -> 180 | AK5: =$AA5*AK$1 -> 180 | AL5: =$AA5*AL$1 -> 150 | AM5: =$AA5*AM$1 -> 140 | AN5: =$AA5*AN$1 -> 120 | ... AR5: =$AA5*AR$1 -> 150
B6: 51187 | C6: Julia Knight; Sale | D6: =VLOOKUP($B6, 'Performance Data'!$B:$K, 3, 0) -> UK | E6: =VLOOKUP($B6, 'Performance Data'!$B:$K, 5, 0) -> Spa | F6: =VLOOKUP($B6, 'Performance Data'!$B:$K, 6, 0) -> Institutes / Clinics | G6: =VLOOKUP($B6, 'Performance Data'!$B:$K, 9, 0) -> 2023 | I6: =VLOOKUP($B6, 'Performance Data'!$B:$K, 7, 0) -> CC | J6: =P6 -> 3504.29 | K6: 4000 | O6: =SUMIF('Performance Data'!$B:$B, $B6,'Performance Data'!N:N) -> 2526.58 | P6: =SUMIF('Performance Data'!$B:$B, $B6,'Performance Data'!O:O) -> 3504.29 | Q6: =SUMIF('Performance Data'!$B:$B, $B6,'Performance Data'!P:P) -> 2000 | S6: =$P6/O6-1 -> 0.38696974 | T6: =P6/Q6-1 -> 0.752145 | V6: =SUMIF('Performance Data'!$B:$B, $B6,'Performance Data'!AC:AC) -> 0 | W6: =SUMIF('Performance Data'!$B:$B, $B6,'Performance Data'!AD:AD) -> 1173.99 | X6: =SUMIF('Performance Data'!$B:$B, $B6,'Performance Data'!AE:AE) -> 2526.58 | Y6: =SUMIF('Performance Data'!$B:$B, $B6,'Performance Data'!AG:AG) -> 2000 | Z6: =J6 -> 3504.29 | AA6: =K6 -> 4000 | AC6: =Z6/X6-1 -> 0.38696974 | AD6: =Z6/Y6-1 -> 0.752145 | AE6: =AA6/Z6-1 -> 0.14145804 | AG6: =$AA6*AG$1 -> 320 | AH6: =$AA6*AH$1 -> 320 | AI6: =$AA6*AI$1 -> 360 | AJ6: =$AA6*AJ$1 -> 360 | AK6: =$AA6*AK$1 -> 360 | AL6: =$AA6*AL$1 -> 300 | AM6: =$AA6*AM$1 -> 280 | AN6: =$AA6*AN$1 -> 240 | ... AR6: =$AA6*AR$1 -> 300
B7: 51189 | C7: RTL Limited; The Grove Hotel | D7: =VLOOKUP($B7, 'Performance Data'!$B:$K, 3, 0) -> UK | E7: =VLOOKUP($B7, 'Performance Data'!$B:$K, 5, 0) -> Spa | F7: =VLOOKUP($B7, 'Performance Data'!$B:$K, 6, 0) -> Spas / Hotels | G7: =VLOOKUP($B7, 'Performance Data'!$B:$K, 9, 0) -> 2024 | I7: =VLOOKUP($B7, 'Performance Data'!$B:$K, 7, 0) -> NKD24 | J7: =P7 -> 32939.5 | K7: 35000 | O7: =SUMIF('Performance Data'!$B:$B, $B7,'Performance Data'!N:N) -> 28806.05 | P7: =SUMIF('Performance Data'!$B:$B, $B7,'Performance Data'!O:O) -> 32939.5 | Q7: =SUMIF('Performance Data'!$B:$B, $B7,'Performance Data'!P:P) -> 30000 | S7: =$P7/O7-1 -> 0.14349243 | T7: =P7/Q7-1 -> 0.097983333 | V7: =SUMIF('Performance Data'!$B:$B, $B7,'Performance Data'!AC:AC) -> 0 | W7: =SUMIF('Performance Data'!$B:$B, $B7,'Performance Data'!AD:AD) -> 0 | X7: =SUMIF('Performance Data'!$B:$B, $B7,'Performance Data'!AE:AE) -> 28806.05 | Y7: =SUMIF('Performance Data'!$B:$B, $B7,'Performance Data'!AG:AG) -> 30000 | Z7: =J7 -> 32939.5 | AA7: =K7 -> 35000 | AC7: =Z7/X7-1 -> 0.14349243 | AD7: =Z7/Y7-1 -> 0.097983333 | AE7: =AA7/Z7-1 -> 0.062554076 | AG7: =$AA7*AG$1 -> 2800 | AH7: =$AA7*AH$1 -> 2800 | AI7: =$AA7*AI$1 -> 3150 | AJ7: =$AA7*AJ$1 -> 3150 | AK7: =$AA7*AK$1 -> 3150 | AL7: =$AA7*AL$1 -> 2625 | AM7: =$AA7*AM$1 -> 2450 | AN7: =$AA7*AN$1 -> 2100 | ... AR7: =$AA7*AR$1 -> 2625
B8: 53000 | C8: IzzyJ Aesthetics | D8: =VLOOKUP($B8, 'Performance Data'!$B:$K, 3, 0) -> UK | E8: =VLOOKUP($B8, 'Performance Data'!$B:$K, 5, 0) -> Spa | F8: =VLOOKUP($B8, 'Performance Data'!$B:$K, 6, 0) -> Other | G8: =VLOOKUP($B8, 'Performance Data'!$B:$K, 9, 0) -> Pre-2022 | I8: =VLOOKUP($B8, 'Performance Data'!$B:$K, 7, 0) -> CC | J8: =P8 -> 487.8 | K8: 0 | O8: =SUMIF('Performance Data'!$B:$B, $B8,'Performance Data'!N:N) -> 2165.32 | P8: =SUMIF('Performance Data'!$B:$B, $B8,'Performance Data'!O:O) -> 487.8 | Q8: =SUMIF('Performance Data'!$B:$B, $B8,'Performance Data'!P:P) -> 0 | S8: =$P8/O8-1 -> -0.77472152 | T8: =P8/Q8-1 -> #DIV/0! | V8: =SUMIF('Performance Data'!$B:$B, $B8,'Performance Data'!AC:AC) -> 0 | W8: =SUMIF('Performance Data'!$B:$B, $B8,'Performance Data'!AD:AD) -> 610.56 | X8: =SUMIF('Performance Data'!$B:$B, $B8,'Performance Data'!AE:AE) -> 2165.32 | Y8: =SUMIF('Performance Data'!$B:$B, $B8,'Performance Data'!AG:AG) -> 0 | Z8: =J8 -> 487.8 | AA8: =K8 -> 0 | AC8: =Z8/X8-1 -> -0.77472152 | AD8: =Z8/Y8-1 -> #DIV/0! | AE8: =AA8/Z8-1 -> -1 | AG8: =$AA8*AG$1 -> 0 | AH8: =$AA8*AH$1 -> 0 | AI8: =$AA8*AI$1 -> 0 | AJ8: =$AA8*AJ$1 -> 0 | AK8: =$AA8*AK$1 -> 0 | AL8: =$AA8*AL$1 -> 0 | AM8: =$AA8*AM$1 -> 0 | AN8: =$AA8*AN$1 -> 0 | ... AR8: =$AA8*AR$1 -> 0
B9: 53014 | C9: Oblique house of aesthetics; London | D9: =VLOOKUP($B9, 'Performance Data'!$B:$K, 3, 0) -> UK | E9: =VLOOKUP($B9, 'Performance Data'!$B:$K, 5, 0) -> Spa | F9: =VLOOKUP($B9, 'Performance Data'!$B:$K, 6, 0) -> Institutes / Clinics | G9: =VLOOKUP($B9, 'Performance Data'!$B:$K, 9, 0) -> 2024 | I9: =VLOOKUP($B9, 'Performance Data'!$B:$K, 7, 0) -> NKD24 | J9: =P9 -> 13215.42 | K9: 15000 | O9: =SUMIF('Performance Data'!$B:$B, $B9,'Performance Data'!N:N) -> 15824.73 | P9: =SUMIF('Performance Data'!$B:$B, $B9,'Performance Data'!O:O) -> 13215.42 | Q9: =SUMIF('Performance Data'!$B:$B, $B9,'Performance Data'!P:P) -> 12000 | S9: =$P9/O9-1 -> -0.16488812 | T9: =P9/Q9-1 -> 0.101285 | V9: =SUMIF('Performance Data'!$B:$B, $B9,'Performance Data'!AC:AC) -> 0 | W9: =SUMIF('Performance Data'!$B:$B, $B9,'Performance Data'!AD:AD) -> 0 | X9: =SUMIF('Performance Data'!$B:$B, $B9,'Performance Data'!AE:AE) -> 15824.73 | Y9: =SUMIF('Performance Data'!$B:$B, $B9,'Performance Data'!AG:AG) -> 12000 | Z9: =J9 -> 13215.42 | AA9: =K9 -> 15000 | AC9: =Z9/X9-1 -> -0.16488812 | AD9: =Z9/Y9-1 -> 0.101285 | AE9: =AA9/Z9-1 -> 0.13503771 | AG9: =$AA9*AG$1 -> 1200 | AH9: =$AA9*AH$1 -> 1200 | AI9: =$AA9*AI$1 -> 1350 | AJ9: =$AA9*AJ$1 -> 1350 | AK9: =$AA9*AK$1 -> 1350 | AL9: =$AA9*AL$1 -> 1125 | AM9: =$AA9*AM$1 -> 1050 | AN9: =$AA9*AN$1 -> 900 | ... AR9: =$AA9*AR$1 -> 1125
B10: 53015 | C10: Hilton Bankside; Ken Tui Management Ltd.; London | D10: =VLOOKUP($B10, 'Performance Data'!$B:$K, 3, 0) -> UK | E10: =VLOOKUP($B10, 'Performance Data'!$B:$K, 5, 0) -> Spa | F10: =VLOOKUP($B10, 'Performance Data'!$B:$K, 6, 0) -> Spas / Hotels | G10: =VLOOKUP($B10, 'Performance Data'!$B:$K, 9, 0) -> 2024 | I10: =VLOOKUP($B10, 'Performance Data'!$B:$K, 7, 0) -> NKD24 | J10: =P10 -> 6384.93 | K10: 7000 | O10: =SUMIF('Performance Data'!$B:$B, $B10,'Performance Data'!N:N) -> 3678.79 | P10: =SUMIF('Performance Data'!$B:$B, $B10,'Performance Data'!O:O) -> 6384.93 | Q10: =SUMIF('Performance Data'!$B:$B, $B10,'Performance Data'!P:P) -> 10000 | S10: =$P10/O10-1 -> 0.735606 | T10: =P10/Q10-1 -> -0.361507 | V10: =SUMIF('Performance Data'!$B:$B, $B10,'Performance Data'!AC:AC) -> 0 | W10: =SUMIF('Performance Data'!$B:$B, $B10,'Performance Data'!AD:AD) -> 0 | X10: =SUMIF('Performance Data'!$B:$B, $B10,'Performance Data'!AE:AE) -> 3678.79 | Y10: =SUMIF('Performance Data'!$B:$B, $B10,'Performance Data'!AG:AG) -> 10000 | Z10: =J10 -> 6384.93 | AA10: =K10 -> 7000 | AC10: =Z10/X10-1 -> 0.735606 | AD10: =Z10/Y10-1 -> -0.361507 | AE10: =AA10/Z10-1 -> 0.096331518 | AG10: =$AA10*AG$1 -> 560 | AH10: =$AA10*AH$1 -> 560 | AI10: =$AA10*AI$1 -> 630 | AJ10: =$AA10*AJ$1 -> 630 | AK10: =$AA10*AK$1 -> 630 | AL10: =$AA10*AL$1 -> 525 | AM10: =$AA10*AM$1 -> 490 | AN10: =$AA10*AN$1 -> 420 | ... AR10: =$AA10*AR$1 -> 525
B11: 53016 | C11: Royal London House; Ken Tui Managem. Ltd | D11: =VLOOKUP($B11, 'Performance Data'!$B:$K, 3, 0) -> UK | E11: =VLOOKUP($B11, 'Performance Data'!$B:$K, 5, 0) -> Spa | F11: =VLOOKUP($B11, 'Performance Data'!$B:$K, 6, 0) -> Spas / Hotels | G11: =VLOOKUP($B11, 'Performance Data'!$B:$K, 9, 0) -> 2024 | I11: =VLOOKUP($B11, 'Performance Data'!$B:$K, 7, 0) -> NKD24 | J11: =P11 -> 1636.92 | K11: 2000 | O11: =SUMIF('Performance Data'!$B:$B, $B11,'Performance Data'!N:N) -> 2148.84 | P11: =SUMIF('Performance Data'!$B:$B, $B11,'Performance Data'!O:O) -> 1636.92 | Q11: =SUMIF('Performance Data'!$B:$B, $B11,'Performance Data'!P:P) -> 10000 | S11: =$P11/O11-1 -> -0.23823086 | T11: =P11/Q11-1 -> -0.836308 | V11: =SUMIF('Performance Data'!$B:$B, $B11,'Performance Data'!AC:AC) -> 0 | W11: =SUMIF('Performance Data'!$B:$B, $B11,'Performance Data'!AD:AD) -> 0 | X11: =SUMIF('Performance Data'!$B:$B, $B11,'Performance Data'!AE:AE) -> 2148.84 | Y11: =SUMIF('Performance Data'!$B:$B, $B11,'Performance Data'!AG:AG) -> 10000 | Z11: =J11 -> 1636.92 | AA11: =K11 -> 2000 | AC11: =Z11/X11-1 -> -0.23823086 | AD11: =Z11/Y11-1 -> -0.836308 | AE11: =AA11/Z11-1 -> 0.22180681 | AG11: =$AA11*AG$1 -> 160 | AH11: =$AA11*AH$1 -> 160 | AI11: =$AA11*AI$1 -> 180 | AJ11: =$AA11*AJ$1 -> 180 | AK11: =$AA11*AK$1 -> 180 | AL11: =$AA11*AL$1 -> 150 | AM11: =$AA11*AM$1 -> 140 | AN11: =$AA11*AN$1 -> 120 | ... AR11: =$AA11*AR$1 -> 150
B12: 53017 | C12: Piccadilly Town House; Ken Tui Managem. Ltd | D12: =VLOOKUP($B12, 'Performance Data'!$B:$K, 3, 0) -> UK | E12: =VLOOKUP($B12, 'Performance Data'!$B:$K, 5, 0) -> Spa | F12: =VLOOKUP($B12, 'Performance Data'!$B:$K, 6, 0) -> Spas / Hotels | G12: =VLOOKUP($B12, 'Performance Data'!$B:$K, 9, 0) -> 2024 | I12: =VLOOKUP($B12, 'Performance Data'!$B:$K, 7, 0) -> NKD24 | J12: =P12 -> 0 | O12: =SUMIF('Performance Data'!$B:$B, $B12,'Performance Data'!N:N) -> 8698.47 | P12: =SUMIF('Performance Data'!$B:$B, $B12,'Performance Data'!O:O) -> 0 | Q12: =SUMIF('Performance Data'!$B:$B, $B12,'Performance Data'!P:P) -> 10000 | S12: =$P12/O12-1 -> -1 | T12: =P12/Q12-1 -> -1 | V12: =SUMIF('Performance Data'!$B:$B, $B12,'Performance Data'!AC:AC) -> 0 | W12: =SUMIF('Performance Data'!$B:$B, $B12,'Performance Data'!AD:AD) -> 0 | X12: =SUMIF('Performance Data'!$B:$B, $B12,'Performance Data'!AE:AE) -> 8698.47 | Y12: =SUMIF('Performance Data'!$B:$B, $B12,'Performance Data'!AG:AG) -> 10000 | Z12: =J12 -> 0 | AA12: =K12 -> 0 | AC12: =Z12/X12-1 -> -1 | AD12: =Z12/Y12-1 -> -1 | AE12: =AA12/Z12-1 -> #DIV/0! | AG12: =$AA12*AG$1 -> 0 | AH12: =$AA12*AH$1 -> 0 | AI12: =$AA12*AI$1 -> 0 | AJ12: =$AA12*AJ$1 -> 0 | AK12: =$AA12*AK$1 -> 0 | AL12: =$AA12*AL$1 -> 0 | AM12: =$AA12*AM$1 -> 0 | AN12: =$AA12*AN$1 -> 0 | ... AR12: =$AA12*AR$1 -> 0
B13: Total Active Existing Doors | H13: =COUNTIF(H3:H12, "Yes") -> 0 | J13: =SUM(J3:J12) -> 82559.33 | K13: =SUM(K3:K12) -> 90000 | O13: =SUM(O3:O12) -> 103321.21 | P13: =SUM(P3:P12) -> 82559.33 | Q13: =SUM(Q3:Q12) -> 109000 | S13: =$P13/O13-1 -> -0.20094499 | T13: =P13/Q13-1 -> -0.24257495 | V13: =SUMIF('Performance Data'!$B:$B, $B13,'Performance Data'!AC:AC) -> 0 | W13: =SUM(W3:W12) -> 10707.03 | X13: =SUM(X3:X12) -> 103321.21 | Y13: =SUM(Y3:Y12) -> 109000 | Z13: =SUM(Z3:Z12) -> 82559.33 | AA13: =SUM(AA3:AA12) -> 90000 | AC13: =Z13/X13-1 -> -0.20094499 | AD13: =Z13/Y13-1 -> -0.24257495 | AE13: =AA13/Z13-1 -> 0.090125126 | AG13: =SUM(AG3:AG12) -> 7200 | AH13: =SUM(AH3:AH12) -> 7200 | AI13: =SUM(AI3:AI12) -> 8100 | AJ13: =SUM(AJ3:AJ12) -> 8100 | AK13: =SUM(AK3:AK12) -> 8100 | AL13: =SUM(AL3:AL12) -> 6750 | AM13: =SUM(AM3:AM12) -> 6300 | AN13: =SUM(AN3:AN12) -> 5400 | ... AR13: =SUM(AR3:AR12) -> 6750
B17: 53019 | C17: M Alexander London | D17: =VLOOKUP($B17, 'Performance Data'!$B:$K, 3, 0) -> UK | E17: =VLOOKUP($B17, 'Performance Data'!$B:$K, 5, 0) -> Spa | F17: =VLOOKUP($B17, 'Performance Data'!$B:$K, 6, 0) -> Institutes / Clinics | G17: =VLOOKUP($B17, 'Performance Data'!$B:$K, 9, 0) -> 2025 | I17: =VLOOKUP($B17, 'Performance Data'!$B:$K, 7, 0) -> NKD25 | J17: =P17 -> 3875.91 | K17: 5000 | O17: =SUMIF('Performance Data'!$B:$B, $B17,'Performance Data'!N:N) -> 0 | P17: =SUMIF('Performance Data'!$B:$B, $B17,'Performance Data'!O:O) -> 3875.91 | Q17: =SUMIF('Performance Data'!$B:$B, $B17,'Performance Data'!P:P) -> 0 | S17: =$P17/O17-1 -> #DIV/0! | T17: =P17/Q17-1 -> #DIV/0! | V17: =SUMIF('Performance Data'!$B:$B, $B17,'Performance Data'!AC:AC) -> 0 | W17: =SUMIF('Performance Data'!$B:$B, $B17,'Performance Data'!AD:AD) -> 0 | X17: =SUMIF('Performance Data'!$B:$B, $B17,'Performance Data'!AE:AE) -> 0 | Y17: =SUMIF('Performance Data'!$B:$B, $B17,'Performance Data'!AG:AG) -> 0 | Z17: =J17 -> 3875.91 | AA17: =K17 -> 5000 | AC17: =Z17/X17-1 -> #DIV/0! | AD17: =Z17/Y17-1 -> #DIV/0! | AE17: =AA17/Z17-1 -> 0.29001963 | AG17: =$AA17*AG$1 -> 400 | AH17: =$AA17*AH$1 -> 400 | AI17: =$AA17*AI$1 -> 450 | AJ17: =$AA17*AJ$1 -> 450 | AK17: =$AA17*AK$1 -> 450 | AL17: =$AA17*AL$1 -> 375 | AM17: =$AA17*AM$1 -> 350 | AN17: =$AA17*AN$1 -> 300 | ... AR17: =$AA17*AR$1 -> 375
B18: 53018 | C18: The Goodwood Hotel, Chichester | D18: =VLOOKUP($B18, 'Performance Data'!$B:$K, 3, 0) -> UK | E18: =VLOOKUP($B18, 'Performance Data'!$B:$K, 5, 0) -> Spa | F18: =VLOOKUP($B18, 'Performance Data'!$B:$K, 6, 0) -> Spas / Hotels | G18: =VLOOKUP($B18, 'Performance Data'!$B:$K, 9, 0) -> 2025 | I18: =VLOOKUP($B18, 'Performance Data'!$B:$K, 7, 0) -> NKD25 | J18: =P18 -> 12182.78 | K18: 15000 | O18: =SUMIF('Performance Data'!$B:$B, $B18,'Performance Data'!N:N) -> 0 | P18: =SUMIF('Performance Data'!$B:$B, $B18,'Performance Data'!O:O) -> 12182.78 | Q18: =SUMIF('Performance Data'!$B:$B, $B18,'Performance Data'!P:P) -> 0 | S18: =$P18/O18-1 -> #DIV/0! | T18: =P18/Q18-1 -> #DIV/0! | V18: =SUMIF('Performance Data'!$B:$B, $B18,'Performance Data'!AC:AC) -> 0 | W18: =SUMIF('Performance Data'!$B:$B, $B18,'Performance Data'!AD:AD) -> 0 | X18: =SUMIF('Performance Data'!$B:$B, $B18,'Performance Data'!AE:AE) -> 0 | Y18: =SUMIF('Performance Data'!$B:$B, $B18,'Performance Data'!AG:AG) -> 0 | Z18: =J18 -> 12182.78 | AA18: =K18 -> 15000 | AC18: =Z18/X18-1 -> #DIV/0! | AD18: =Z18/Y18-1 -> #DIV/0! | AE18: =AA18/Z18-1 -> 0.23124607 | AG18: =$AA18*AG$1 -> 1200 | AH18: =$AA18*AH$1 -> 1200 | AI18: =$AA18*AI$1 -> 1350 | AJ18: =$AA18*AJ$1 -> 1350 | AK18: =$AA18*AK$1 -> 1350 | AL18: =$AA18*AL$1 -> 1125 | AM18: =$AA18*AM$1 -> 1050 | AN18: =$AA18*AN$1 -> 900 | ... AR18: =$AA18*AR$1 -> 1125
B19: 53020 | C19: Guendalina The Skin Sculpter LTD | D19: =VLOOKUP($B19, 'Performance Data'!$B:$K, 3, 0) -> UK | E19: =VLOOKUP($B19, 'Performance Data'!$B:$K, 5, 0) -> Spa | F19: =VLOOKUP($B19, 'Performance Data'!$B:$K, 6, 0) -> Institutes / Clinics | G19: =VLOOKUP($B19, 'Performance Data'!$B:$K, 9, 0) -> 2025 | I19: =VLOOKUP($B19, 'Performance Data'!$B:$K, 7, 0) -> NKD25 | J19: =P19 -> 35192.72 | K19: 40000 | O19: =SUMIF('Performance Data'!$B:$B, $B19,'Performance Data'!N:N) -> 0 | P19: =SUMIF('Performance Data'!$B:$B, $B19,'Performance Data'!O:O) -> 35192.72 | Q19: =SUMIF('Performance Data'!$B:$B, $B19,'Performance Data'!P:P) -> 0 | S19: =$P19/O19-1 -> #DIV/0! | T19: =P19/Q19-1 -> #DIV/0! | V19: =SUMIF('Performance Data'!$B:$B, $B19,'Performance Data'!AC:AC) -> 0 | W19: =SUMIF('Performance Data'!$B:$B, $B19,'Performance Data'!AD:AD) -> 0 | X19: =SUMIF('Performance Data'!$B:$B, $B19,'Performance Data'!AE:AE) -> 0 | Y19: =SUMIF('Performance Data'!$B:$B, $B19,'Performance Data'!AG:AG) -> 0 | Z19: =J19 -> 35192.72 | AA19: =K19 -> 40000 | AC19: =Z19/X19-1 -> #DIV/0! | AD19: =Z19/Y19-1 -> #DIV/0! | AE19: =AA19/Z19-1 -> 0.13659871 | AG19: =$AA19*AG$1 -> 3200 | AH19: =$AA19*AH$1 -> 3200 | AI19: =$AA19*AI$1 -> 3600 | AJ19: =$AA19*AJ$1 -> 3600 | AK19: =$AA19*AK$1 -> 3600 | AL19: =$AA19*AL$1 -> 3000 | AM19: =$AA19*AM$1 -> 2800 | AN19: =$AA19*AN$1 -> 2400 | ... AR19: =$AA19*AR$1 -> 3000
B20: 51192 | C20: Rachel Staggs Ltd. | D20: =VLOOKUP($B20, 'Performance Data'!$B:$K, 3, 0) -> UK | E20: =VLOOKUP($B20, 'Performance Data'!$B:$K, 5, 0) -> Spa | F20: =VLOOKUP($B20, 'Performance Data'!$B:$K, 6, 0) -> Institutes / Clinics | G20: =VLOOKUP($B20, 'Performance Data'!$B:$K, 9, 0) -> 2025 | I20: =VLOOKUP($B20, 'Performance Data'!$B:$K, 7, 0) -> NKD25 | J20: =P20 -> 9511.98 | K20: 12000 | O20: =SUMIF('Performance Data'!$B:$B, $B20,'Performance Data'!N:N) -> 0 | P20: =SUMIF('Performance Data'!$B:$B, $B20,'Performance Data'!O:O) -> 9511.98 | Q20: =SUMIF('Performance Data'!$B:$B, $B20,'Performance Data'!P:P) -> 0 | S20: =$P20/O20-1 -> #DIV/0! | T20: =P20/Q20-1 -> #DIV/0! | V20: =SUMIF('Performance Data'!$B:$B, $B20,'Performance Data'!AC:AC) -> 0 | W20: =SUMIF('Performance Data'!$B:$B, $B20,'Performance Data'!AD:AD) -> 0 | X20: =SUMIF('Performance Data'!$B:$B, $B20,'Performance Data'!AE:AE) -> 0 | Y20: =SUMIF('Performance Data'!$B:$B, $B20,'Performance Data'!AG:AG) -> 0 | Z20: =J20 -> 9511.98 | AA20: =K20 -> 12000 | AC20: =Z20/X20-1 -> #DIV/0! | AD20: =Z20/Y20-1 -> #DIV/0! | AE20: =AA20/Z20-1 -> 0.26156699 | AG20: =$AA20*AG$1 -> 960 | AH20: =$AA20*AH$1 -> 960 | AI20: =$AA20*AI$1 -> 1080 | AJ20: =$AA20*AJ$1 -> 1080 | AK20: =$AA20*AK$1 -> 1080 | AL20: =$AA20*AL$1 -> 900 | AM20: =$AA20*AM$1 -> 840 | AN20: =$AA20*AN$1 -> 720 | ... AR20: =$AA20*AR$1 -> 900
B21: 51191 | C21: Louise Godsil; Tranquil Escape | D21: =VLOOKUP($B21, 'Performance Data'!$B:$K, 3, 0) -> UK | E21: =VLOOKUP($B21, 'Performance Data'!$B:$K, 5, 0) -> Spa | F21: =VLOOKUP($B21, 'Performance Data'!$B:$K, 6, 0) -> Institutes / Clinics | G21: =VLOOKUP($B21, 'Performance Data'!$B:$K, 9, 0) -> 2025 | I21: =VLOOKUP($B21, 'Performance Data'!$B:$K, 7, 0) -> NKD25 | J21: =P21 -> 5101.47 | K21: 7000 | O21: =SUMIF('Performance Data'!$B:$B, $B21,'Performance Data'!N:N) -> 0 | P21: =SUMIF('Performance Data'!$B:$B, $B21,'Performance Data'!O:O) -> 5101.47 | Q21: =SUMIF('Performance Data'!$B:$B, $B21,'Performance Data'!P:P) -> 0 | S21: =$P21/O21-1 -> #DIV/0! | T21: =P21/Q21-1 -> #DIV/0! | V21: =SUMIF('Performance Data'!$B:$B, $B21,'Performance Data'!AC:AC) -> 0 | W21: =SUMIF('Performance Data'!$B:$B, $B21,'Performance Data'!AD:AD) -> 0 | X21: =SUMIF('Performance Data'!$B:$B, $B21,'Performance Data'!AE:AE) -> 0 | Y21: =SUMIF('Performance Data'!$B:$B, $B21,'Performance Data'!AG:AG) -> 0 | Z21: =J21 -> 5101.47 | AA21: =K21 -> 7000 | AC21: =Z21/X21-1 -> #DIV/0! | AD21: =Z21/Y21-1 -> #DIV/0! | AE21: =AA21/Z21-1 -> 0.37215352 | AG21: =$AA21*AG$1 -> 560 | AH21: =$AA21*AH$1 -> 560 | AI21: =$AA21*AI$1 -> 630 | AJ21: =$AA21*AJ$1 -> 630 | AK21: =$AA21*AK$1 -> 630 | AL21: =$AA21*AL$1 -> 525 | AM21: =$AA21*AM$1 -> 490 | AN21: =$AA21*AN$1 -> 420 | ... AR21: =$AA21*AR$1 -> 525
B22: 53021 | C22: Ayadi Ltd. | D22: =VLOOKUP($B22, 'Performance Data'!$B:$K, 3, 0) -> UK | E22: =VLOOKUP($B22, 'Performance Data'!$B:$K, 5, 0) -> Spa | F22: =VLOOKUP($B22, 'Performance Data'!$B:$K, 6, 0) -> Spas / Hotels | G22: =VLOOKUP($B22, 'Performance Data'!$B:$K, 9, 0) -> 2026 | I22: =VLOOKUP($B22, 'Performance Data'!$B:$K, 7, 0) -> NKD25 | J22: =P22 -> 2109.56 | K22: 10000 | O22: =SUMIF('Performance Data'!$B:$B, $B22,'Performance Data'!N:N) -> 0 | P22: =SUMIF('Performance Data'!$B:$B, $B22,'Performance Data'!O:O) -> 2109.56 | Q22: =SUMIF('Performance Data'!$B:$B, $B22,'Performance Data'!P:P) -> 0 | S22: =$P22/O22-1 -> #DIV/0! | T22: =P22/Q22-1 -> #DIV/0! | V22: =SUMIF('Performance Data'!$B:$B, $B22,'Performance Data'!AC:AC) -> 0 | W22: =SUMIF('Performance Data'!$B:$B, $B22,'Performance Data'!AD:AD) -> 0 | X22: =SUMIF('Performance Data'!$B:$B, $B22,'Performance Data'!AE:AE) -> 0 | Y22: =SUMIF('Performance Data'!$B:$B, $B22,'Performance Data'!AG:AG) -> 0 | Z22: =J22 -> 2109.56 | AA22: =K22 -> 10000 | AC22: =Z22/X22-1 -> #DIV/0! | AD22: =Z22/Y22-1 -> #DIV/0! | AE22: =AA22/Z22-1 -> 3.740325 | AG22: =$AA22*AG$1 -> 800 | AH22: =$AA22*AH$1 -> 800 | AI22: =$AA22*AI$1 -> 900 | AJ22: =$AA22*AJ$1 -> 900 | AK22: =$AA22*AK$1 -> 900 | AL22: =$AA22*AL$1 -> 750 | AM22: =$AA22*AM$1 -> 700 | AN22: =$AA22*AN$1 -> 600 | ... AR22: =$AA22*AR$1 -> 750
B23: 51194 | C23: Artfarm Limited; The Fife Arms Braemar | D23: =VLOOKUP($B23, 'Performance Data'!$B:$K, 3, 0) -> UK | E23: =VLOOKUP($B23, 'Performance Data'!$B:$K, 5, 0) -> Spa | F23: =VLOOKUP($B23, 'Performance Data'!$B:$K, 6, 0) -> Spas / Hotels | G23: =VLOOKUP($B23, 'Performance Data'!$B:$K, 9, 0) -> 2027 | I23: =VLOOKUP($B23, 'Performance Data'!$B:$K, 7, 0) -> NKD25 | J23: =P23 -> 2107.76 | K23: 10000 | O23: =SUMIF('Performance Data'!$B:$B, $B23,'Performance Data'!N:N) -> 0 | P23: =SUMIF('Performance Data'!$B:$B, $B23,'Performance Data'!O:O) -> 2107.76 | Q23: =SUMIF('Performance Data'!$B:$B, $B23,'Performance Data'!P:P) -> 0 | S23: =$P23/O23-1 -> #DIV/0! | T23: =P23/Q23-1 -> #DIV/0! | V23: =SUMIF('Performance Data'!$B:$B, $B23,'Performance Data'!AC:AC) -> 0 | W23: =SUMIF('Performance Data'!$B:$B, $B23,'Performance Data'!AD:AD) -> 0 | X23: =SUMIF('Performance Data'!$B:$B, $B23,'Performance Data'!AE:AE) -> 0 | Y23: =SUMIF('Performance Data'!$B:$B, $B23,'Performance Data'!AG:AG) -> 0 | Z23: =J23 -> 2107.76 | AA23: =K23 -> 10000 | AC23: =Z23/X23-1 -> #DIV/0! | AD23: =Z23/Y23-1 -> #DIV/0! | AE23: =AA23/Z23-1 -> 3.7443732 | AG23: =$AA23*AG$1 -> 800 | AH23: =$AA23*AH$1 -> 800 | AI23: =$AA23*AI$1 -> 900 | AJ23: =$AA23*AJ$1 -> 900 | AK23: =$AA23*AK$1 -> 900 | AL23: =$AA23*AL$1 -> 750 | AM23: =$AA23*AM$1 -> 700 | AN23: =$AA23*AN$1 -> 600 | ... AR23: =$AA23*AR$1 -> 750
B24: 51196 | C24: CHAPEL BEAUTY | D24: =VLOOKUP($B24, 'Performance Data'!$B:$K, 3, 0) -> UK | E24: =VLOOKUP($B24, 'Performance Data'!$B:$K, 5, 0) -> Spa | F24: =VLOOKUP($B24, 'Performance Data'!$B:$K, 6, 0) -> Institutes / Clinics | G24: =VLOOKUP($B24, 'Performance Data'!$B:$K, 9, 0) -> 2028 | I24: =VLOOKUP($B24, 'Performance Data'!$B:$K, 7, 0) -> NKD25 | J24: =P24 -> 1213.1 | K24: 10000 | O24: =SUMIF('Performance Data'!$B:$B, $B24,'Performance Data'!N:N) -> 0 | P24: =SUMIF('Performance Data'!$B:$B, $B24,'Performance Data'!O:O) -> 1213.1 | Q24: =SUMIF('Performance Data'!$B:$B, $B24,'Performance Data'!P:P) -> 0 | S24: =$P24/O24-1 -> #DIV/0! | T24: =P24/Q24-1 -> #DIV/0! | V24: =SUMIF('Performance Data'!$B:$B, $B24,'Performance Data'!AC:AC) -> 0 | W24: =SUMIF('Performance Data'!$B:$B, $B24,'Performance Data'!AD:AD) -> 0 | X24: =SUMIF('Performance Data'!$B:$B, $B24,'Performance Data'!AE:AE) -> 0 | Y24: =SUMIF('Performance Data'!$B:$B, $B24,'Performance Data'!AG:AG) -> 0 | Z24: =J24 -> 1213.1 | AA24: =K24 -> 10000 | AC24: =Z24/X24-1 -> #DIV/0! | AD24: =Z24/Y24-1 -> #DIV/0! | AE24: =AA24/Z24-1 -> 7.2433435 | AG24: =$AA24*AG$1 -> 800 | AH24: =$AA24*AH$1 -> 800 | AI24: =$AA24*AI$1 -> 900 | AJ24: =$AA24*AJ$1 -> 900 | AK24: =$AA24*AK$1 -> 900 | AL24: =$AA24*AL$1 -> 750 | AM24: =$AA24*AM$1 -> 700 | AN24: =$AA24*AN$1 -> 600 | ... AR24: =$AA24*AR$1 -> 750
B25: NKD25 | C25: New doors 2025 | D25: UK | E25: Spa | G25: 2025 | I25: NKD25 | O25: 0 | P25: 0 | Q25: =SUMIF('Performance Data'!$B:$B, $B25,'Performance Data'!P:P) -> 120000 | S25: =$P25/O25-1 -> #DIV/0! | T25: =P25/Q25-1 -> -1 | V25: 0 | W25: 0 | X25: 0 | Y25: =SUMIF('Performance Data'!$B:$B, $B25,'Performance Data'!AG:AG) -> 120000 | Z25: =J25 -> 0 | AA25: =K25 -> 0 | AC25: =Z25/X25-1 -> #DIV/0! | AD25: =Z25/Y25-1 -> -1 | AE25: =AA25/Z25-1 -> #DIV/0! | AG25: =$AA25*AG$1 -> 0 | AH25: =$AA25*AH$1 -> 0 | AI25: =$AA25*AI$1 -> 0 | AJ25: =$AA25*AJ$1 -> 0 | AK25: =$AA25*AK$1 -> 0 | AL25: =$AA25*AL$1 -> 0 | AM25: =$AA25*AM$1 -> 0 | AN25: =$AA25*AN$1 -> 0 | ... AR25: =$AA25*AR$1 -> 0
B27: Total New Doors 2025 | H27: =COUNTIF(H17:H21, "Yes")+H25 -> 0 | J27: =SUM(J17:J25) -> 71295.28 | K27: =SUM(K17:K25) -> 109000 | O27: =SUM(O17:O25) -> 0 | P27: =SUM(P17:P25) -> 71295.28 | Q27: =SUM(Q17:Q25) -> 120000 | S27: =$P27/O27-1 -> #DIV/0! | T27: =P27/Q27-1 -> -0.40587267 | V27: =SUM(V17:V25) -> 0 | W27: =SUM(W17:W25) -> 0 | X27: =SUM(X17:X25) -> 0 | Y27: =SUM(Y17:Y25) -> 120000 | Z27: =SUM(Z17:Z25) -> 71295.28 | AA27: =SUM(AA17:AA25) -> 109000 | AC27: =Z27/X27-1 -> #DIV/0! | AD27: =Z27/Y27-1 -> -0.40587267 | AE27: =AA27/Z27-1 -> 0.52885296 | AG27: =SUM(AG17:AG25) -> 8720 | AH27: =SUM(AH17:AH25) -> 8720 | AI27: =SUM(AI17:AI25) -> 9810 | AJ27: =SUM(AJ17:AJ25) -> 9810 | AK27: =SUM(AK17:AK25) -> 9810 | AL27: =SUM(AL17:AL25) -> 8175 | AM27: =SUM(AM17:AM25) -> 7630 | AN27: =SUM(AN17:AN25) -> 6540 | ... AR27: =SUM(AR17:AR25) -> 8175
AY30: =AV31 -> 1 | AZ30: =AW31 -> 1 | BA30: =AX31+AV31 -> 2 | BB30: =AY31+AW31 -> 2 | BC30: =AZ31+AX31+AV31 -> 3 | BD30: =BA31+AY31+AW31 -> 3 | BE30: =BB31+AZ31+AX31+AV31 -> 4 | BF30: =BC31+BA31+AY31+AW31 -> 4
B31: NKD26 | C31: New doors 2026 | D31: UK | E31: Spa | G31: 2026 | H31: 10 | I31: NKD26 | K31: 100000 | O31: 0 | P31: 0 | Q31: 0 | S31: =$P31/O31-1 -> #DIV/0! | T31: =P31/Q31-1 -> #DIV/0! | V31: 0 | W31: 0 | X31: 0 | Y31: 0 | Z31: =J31 -> 0 | AA31: =K31 -> 100000 | AC31: =Z31/X31-1 -> #DIV/0! | AD31: =Z31/Y31-1 -> #DIV/0! | AE31: =AA31/Z31-1 -> #DIV/0! | AG31: =AU31*4000+AU30*3000 -> 0 | AH31: =AV31*4000+AV30*3000 -> 4000 | AI31: =AW31*4000+AW30*3000 -> 4000 | AJ31: =AX31*4000+AX30*3000 -> 4000 | AK31: =AY31*4000+AY30*3000 -> 7000 | AL31: =AZ31*4000+AZ30*3000 -> 7000 | AM31: =BA31*4000+BA30*3000 -> 10000 | AN31: =BB31*4000+BB30*3000 -> 10000 | ... AR31: =BF31*4000+BF30*3000 -> 12000 | AV31: 1 | AW31: 1 | AX31: 1 | AY31: 1 | AZ31: 1 | BA31: 1 | BB31: 1 | BC31: 1 | BD31: 1 | BE31: 1
B33: Total New Doors 2026 | H33: =COUNTIF(H30:H30, "Yes")+H31 -> 10 | J33: =SUM(J30:J31) -> 0 | K33: =SUM(K30:K31) -> 100000 | O33: =SUM(O30:O31) -> 0 | P33: =SUM(P30:P31) -> 0 | Q33: =SUM(Q30:Q31) -> 0 | S33: =$P33/O33-1 -> #DIV/0! | T33: =P33/Q33-1 -> #DIV/0! | V33: =SUM(V30:V31) -> 0 | W33: =SUM(W30:W31) -> 0 | X33: =SUM(X30:X31) -> 0 | Y33: =SUM(Y30:Y31) -> 0 | Z33: =SUM(Z30:Z31) -> 0 | AA33: =SUM(AA30:AA31) -> 100000 | AC33: =Z33/X33-1 -> #DIV/0! | AD33: =Z33/Y33-1 -> #DIV/0! | AE33: =AA33/Z33-1 -> #DIV/0! | AG33: =SUM(AG30:AG31) -> 0 | AH33: =SUM(AH30:AH31) -> 4000 | AI33: =SUM(AI30:AI31) -> 4000 | AJ33: =SUM(AJ30:AJ31) -> 4000 | AK33: =SUM(AK30:AK31) -> 7000 | AL33: =SUM(AL30:AL31) -> 7000 | AM33: =SUM(AM30:AM31) -> 10000 | AN33: =SUM(AN30:AN31) -> 10000 | ... AR33: =SUM(AR30:AR31) -> 12000

Sheet UK Retail Budget
O1: Year to date | P1: Year to date | Q1: Year to date | S1: Year to date | T1: Year to date | V1: Full year | W1: Full year | X1: Full year | Y1: Full year | Z1: Full year | AA1: Full year | AC1: Full year | AD1: Full year | AE1: Full year | AG1: 0.08 | AH1: 0.08 | AI1: 0.09 | AJ1: 0.09 | AK1: 0.09 | AL1: 0.075 | AM1: 0.07 | AN1: 0.06 | AO1: 0.095 | AP1: 0.105 | AQ1: 0.09 | AR1: 0.075
B2: Customer Code | C2: Customer Name | D2: Country | E2: Region | F2: Customer Map | G2: New door year | H2: Active? | I2: 2025 Cluster | J2: 2025A | K2: 2026B | L2: Size indicator | M2: Customer Growth Class | O2: 2024 YTD | P2: 2025 YTD | Q2: 2025B YTD | S2: 25 vs 24 % | T2: 25 vs 25B % | V2: 2022 | W2: 2023 | X2: 2024 | Y2: 2025B | Z2: 2025A | AA2: 2026B | AC2: 25 vs 24 % | AD2: 25 vs 25B % | AE2: 26B vs 25F % | AG2: 46023 | AH2: 46054 | AI2: 46082 | AJ2: 46113 | AK2: 46143 | AL2: 46174 | AM2: 46204 | AN2: 46235 | AO2: 46266 | AP2: 46296 | AQ2: 46327 | AR2: 46357
B3: 51101 | C3: Liberty | D3: =VLOOKUP($B3, 'Performance Data'!$B:$K, 3, 0) -> UK | E3: =VLOOKUP($B3, 'Performance Data'!$B:$K, 5, 0) -> Retail | F3: =VLOOKUP($B3, 'Performance Data'!$B:$K, 6, 0) -> Retail | G3: =VLOOKUP($B3, 'Performance Data'!$B:$K, 9, 0) -> Pre-2022 | I3: =VLOOKUP($B3, 'Performance Data'!$B:$K, 7, 0) -> AA | J3: =P3 -> 104135.52 | K3: 118000 | O3: =SUMIF('Performance Data'!$B:$B, $B3,'Performance Data'!N:N) -> 106390.93 | P3: =SUMIF('Performance Data'!$B:$B, $B3,'Performance Data'!O:O) -> 104135.52 | Q3: =SUMIF('Performance Data'!$B:$B, $B3,'Performance Data'!P:P) -> 100000 | S3: =$P3/O3-1 -> -0.02119927 | T3: =P3/Q3-1 -> 0.0413552 | V3: =SUMIF('Performance Data'!$B:$B, $B3,'Performance Data'!AC:AC) -> 0 | W3: =SUMIF('Performance Data'!$B:$B, $B3,'Performance Data'!AD:AD) -> 108670.28 | X3: =SUMIF('Performance Data'!$B:$B, $B3,'Performance Data'!AE:AE) -> 106390.93 | Y3: =SUMIF('Performance Data'!$B:$B, $B3,'Performance Data'!AG:AG) -> 100000 | Z3: =J3 -> 104135.52 | AA3: =K3 -> 118000 | AC3: =Z3/X3-1 -> -0.02119927 | AD3: =Z3/Y3-1 -> 0.0413552 | AE3: =AA3/Z3-1 -> 0.13313882 | AG3: =$AA3*AG$1 -> 9440 | AH3: =$AA3*AH$1 -> 9440 | AI3: =$AA3*AI$1 -> 10620 | AJ3: =$AA3*AJ$1 -> 10620 | AK3: =$AA3*AK$1 -> 10620 | AL3: =$AA3*AL$1 -> 8850 | AM3: =$AA3*AM$1 -> 8260 | AN3: =$AA3*AN$1 -> 7080 | ... AR3: =$AA3*AR$1 -> 8850
B4: 51172 | C4: Harrods (UK) Ltd. | D4: =VLOOKUP($B4, 'Performance Data'!$B:$K, 3, 0) -> UK | E4: =VLOOKUP($B4, 'Performance Data'!$B:$K, 5, 0) -> Retail | F4: =VLOOKUP($B4, 'Performance Data'!$B:$K, 6, 0) -> Retail | G4: =VLOOKUP($B4, 'Performance Data'!$B:$K, 9, 0) -> Pre-2022 | I4: =VLOOKUP($B4, 'Performance Data'!$B:$K, 7, 0) -> AA | J4: =P4 -> 38041.62 | K4: 40000 | O4: =SUMIF('Performance Data'!$B:$B, $B4,'Performance Data'!N:N) -> 39567.38 | P4: =SUMIF('Performance Data'!$B:$B, $B4,'Performance Data'!O:O) -> 38041.62 | Q4: =SUMIF('Performance Data'!$B:$B, $B4,'Performance Data'!P:P) -> 35000 | S4: =$P4/O4-1 -> -0.038561057 | T4: =P4/Q4-1 -> 0.086903429 | V4: =SUMIF('Performance Data'!$B:$B, $B4,'Performance Data'!AC:AC) -> 0 | W4: =SUMIF('Performance Data'!$B:$B, $B4,'Performance Data'!AD:AD) -> 24702.52 | X4: =SUMIF('Performance Data'!$B:$B, $B4,'Performance Data'!AE:AE) -> 39567.38 | Y4: =SUMIF('Performance Data'!$B:$B, $B4,'Performance Data'!AG:AG) -> 35000 | Z4: =J4 -> 38041.62 | AA4: =K4 -> 40000 | AC4: =Z4/X4-1 -> -0.038561057 | AD4: =Z4/Y4-1 -> 0.086903429 | AE4: =AA4/Z4-1 -> 0.051479932 | AG4: =$AA4*AG$1 -> 3200 | AH4: =$AA4*AH$1 -> 3200 | AI4: =$AA4*AI$1 -> 3600 | AJ4: =$AA4*AJ$1 -> 3600 | AK4: =$AA4*AK$1 -> 3600 | AL4: =$AA4*AL$1 -> 3000 | AM4: =$AA4*AM$1 -> 2800 | AN4: =$AA4*AN$1 -> 2400 | ... AR4: =$AA4*AR$1 -> 3000
B5: 51183 | C5: John Bell & Croyden, London | D5: =VLOOKUP($B5, 'Performance Data'!$B:$K, 3, 0) -> UK | E5: =VLOOKUP($B5, 'Performance Data'!$B:$K, 5, 0) -> Retail | F5: =VLOOKUP($B5, 'Performance Data'!$B:$K, 6, 0) -> Retail | G5: =VLOOKUP($B5, 'Performance Data'!$B:$K, 9, 0) -> 2022 | I5: =VLOOKUP($B5, 'Performance Data'!$B:$K, 7, 0) -> CC | J5: =P5 -> 1569.42 | K5: 2000 | O5: =SUMIF('Performance Data'!$B:$B, $B5,'Performance Data'!N:N) -> 1708.95 | P5: =SUMIF('Performance Data'!$B:$B, $B5,'Performance Data'!O:O) -> 1569.42 | Q5: =SUMIF('Performance Data'!$B:$B, $B5,'Performance Data'!P:P) -> 2000 | S5: =$P5/O5-1 -> -0.081646625 | T5: =P5/Q5-1 -> -0.21529 | V5: =SUMIF('Performance Data'!$B:$B, $B5,'Performance Data'!AC:AC) -> 0 | W5: =SUMIF('Performance Data'!$B:$B, $B5,'Performance Data'!AD:AD) -> 3526.98 | X5: =SUMIF('Performance Data'!$B:$B, $B5,'Performance Data'!AE:AE) -> 1708.95 | Y5: =SUMIF('Performance Data'!$B:$B, $B5,'Performance Data'!AG:AG) -> 2000 | Z5: =J5 -> 1569.42 | AA5: =K5 -> 2000 | AC5: =Z5/X5-1 -> -0.081646625 | AD5: =Z5/Y5-1 -> -0.21529 | AE5: =AA5/Z5-1 -> 0.27435613 | AG5: =$AA5*AG$1 -> 160 | AH5: =$AA5*AH$1 -> 160 | AI5: =$AA5*AI$1 -> 180 | AJ5: =$AA5*AJ$1 -> 180 | AK5: =$AA5*AK$1 -> 180 | AL5: =$AA5*AL$1 -> 150 | AM5: =$AA5*AM$1 -> 140 | AN5: =$AA5*AN$1 -> 120 | ... AR5: =$AA5*AR$1 -> 150
B6: Total Active Existing Doors | H6: =COUNTIF(H3:H5, "Yes") -> 0 | J6: =SUM(J3:J5) -> 143746.56 | K6: =SUM(K3:K5) -> 160000 | O6: =SUM(O3:O5) -> 147667.26 | P6: =SUM(P3:P5) -> 143746.56 | Q6: =SUM(Q3:Q5) -> 137000 | S6: =$P6/O6-1 -> -0.026550909 | T6: =P6/Q6-1 -> 0.049244964 | V6: =SUMIF('Performance Data'!$B:$B, $B6,'Performance Data'!AC:AC) -> 0 | W6: =SUM(W3:W5) -> 136899.78 | X6: =SUM(X3:X5) -> 147667.26 | Y6: =SUM(Y3:Y5) -> 137000 | Z6: =SUM(Z3:Z5) -> 143746.56 | AA6: =SUM(AA3:AA5) -> 160000 | AC6: =Z6/X6-1 -> -0.026550909 | AD6: =Z6/Y6-1 -> 0.049244964 | AE6: =AA6/Z6-1 -> 0.11307011 | AG6: =SUM(AG3:AG5) -> 12800 | AH6: =SUM(AH3:AH5) -> 12800 | AI6: =SUM(AI3:AI5) -> 14400 | AJ6: =SUM(AJ3:AJ5) -> 14400 | AK6: =SUM(AK3:AK5) -> 14400 | AL6: =SUM(AL3:AL5) -> 12000 | AM6: =SUM(AM3:AM5) -> 11200 | AN6: =SUM(AN3:AN5) -> 9600 | ... AR6: =SUM(AR3:AR5) -> 12000
B10: NKD25 | C10: New doors 2025 | D10: UK | E10: Retail | G10: 2025 | I10: NKD25 | O10: 0 | P10: 0 | Q10: 0 | S10: =$P10/O10-1 -> #DIV/0! | T10: =P10/Q10-1 -> #DIV/0! | V10: 0 | W10: 0 | X10: 0 | Y10: 0 | Z10: =J10 -> 0 | AA10: =K10 -> 0 | AC10: =Z10/X10-1 -> #DIV/0! | AD10: =Z10/Y10-1 -> #DIV/0! | AE10: =AA10/Z10-1 -> #DIV/0!
B12: Total New Doors 2025 | H12: =COUNTIF(H9, "Yes")+H10 -> 0 | J12: =SUM(J10:J10) -> 0 | K12: =SUM(K10:K10) -> 0 | O12: =SUM(O10:O10) -> 0 | P12: =SUM(P10:P10) -> 0 | Q12: =SUM(Q10:Q10) -> 0 | S12: =$P12/O12-1 -> #DIV/0! | T12: =P12/Q12-1 -> #DIV/0! | V12: =SUM(V10:V10) -> 0 | W12: =SUM(W10:W10) -> 0 | X12: =SUM(X10:X10) -> 0 | Y12: =SUM(Y10:Y10) -> 0 | Z12: =SUM(Z10:Z10) -> 0 | AA12: =SUM(AA10:AA10) -> 0 | AC12: =Z12/X12-1 -> #DIV/0! | AD12: =Z12/Y12-1 -> #DIV/0! | AE12: =AA12/Z12-1 -> #DIV/0!
B16: NKD26 | C16: New doors 2026 | D16: UK | E16: Retail | G16: 2026 | H16: 0 | I16: NKD26 | K16: 0 | O16: 0 | P16: 0 | Q16: 0 | S16: =$P16/O16-1 -> #DIV/0! | T16: =P16/Q16-1 -> #DIV/0! | V16: 0 | W16: 0 | X16: 0 | Y16: 0 | Z16: =J16 -> 0 | AA16: =K16 -> 0 | AC16: =Z16/X16-1 -> #DIV/0! | AD16: =Z16/Y16-1 -> #DIV/0! | AE16: =AA16/Z16-1 -> #DIV/0!
B18: Total New Doors 2026 | H18: =COUNTIF(H15:H15, "Yes")+H16 -> 0 | J18: =SUM(J15:J16) -> 0 | K18: =SUM(K15:K16) -> 0 | O18: =SUM(O15:O16) -> 0 | P18: =SUM(P15:P16) -> 0 | Q18: =SUM(Q15:Q16) -> 0 | S18: =$P18/O18-1 -> #DIV/0! | T18: =P18/Q18-1 -> #DIV/0! | V18: =SUM(V15:V16) -> 0 | W18: =SUM(W15:W16) -> 0 | X18: =SUM(X15:X16) -> 0 | Y18: =SUM(Y15:Y16) -> 0 | Z18: =SUM(Z15:Z16) -> 0 | AA18: =SUM(AA15:AA16) -> 0 | AC18: =Z18/X18-1 -> #DIV/0! | AD18: =Z18/Y18-1 -> #DIV/0! | AE18: =AA18/Z18-1 -> #DIV/0!

Sheet Global eTailer Budget
O1: Year to date | P1: Year to date | Q1: Year to date | S1: Year to date | T1: Year to date | V1: Full year | W1: Full year | X1: Full year | Y1: Full year | Z1: Full year | AA1: Full year | AC1: Full year | AD1: Full year | AE1: Full year
B2: Customer Code | C2: Customer Name | D2: Country | E2: Region | F2: Customer Map | G2: New door year | H2: Active? | I2: 2025 Cluster | J2: 2025A | K2: 2026B | L2: Size indicator | M2: Customer Growth Class | O2: 2024 YTD | P2: 2025 YTD | Q2: 2025B YTD | S2: 25 vs 24 % | T2: 25 vs 25B % | V2: 2022 | W2: 2023 | X2: 2024 | Y2: 2025B | Z2: 2025A | AA2: 2026B | AC2: 25 vs 24 % | AD2: 25 vs 25B % | AE2: 26B vs 25F % | AG2: 46023 | AH2: 46054 | AI2: 46082 | AJ2: 46113 | AK2: 46143 | AL2: 46174 | AM2: 46204 | AN2: 46235 | AO2: 46266 | AP2: 46296 | AQ2: 46327 | AR2: 46357
B3: 51175 | C3: The Hut.com Ltd; Poland | D3: =VLOOKUP($B3, 'Performance Data'!$B:$K, 3, 0) -> UK | E3: =VLOOKUP($B3, 'Performance Data'!$B:$K, 5, 0) -> eTailers | F3: =VLOOKUP($B3, 'Performance Data'!$B:$K, 6, 0) -> eTailers | G3: =VLOOKUP($B3, 'Performance Data'!$B:$K, 9, 0) -> Pre-2022 | I3: =VLOOKUP($B3, 'Performance Data'!$B:$K, 7, 0) -> BC | J3: =P3 -> 0 | O3: =SUMIF('Performance Data'!$B:$B, $B3,'Performance Data'!N:N) -> -6663.15 | P3: =SUMIF('Performance Data'!$B:$B, $B3,'Performance Data'!O:O) -> 0 | Q3: =SUMIF('Performance Data'!$B:$B, $B3,'Performance Data'!P:P) -> 5000 | S3: =$P3/O3-1 -> -1 | T3: =P3/Q3-1 -> -1 | V3: =SUMIF('Performance Data'!$B:$B, $B3,'Performance Data'!AC:AC) -> 0 | W3: =SUMIF('Performance Data'!$B:$B, $B3,'Performance Data'!AD:AD) -> 45672.35 | X3: =SUMIF('Performance Data'!$B:$B, $B3,'Performance Data'!AE:AE) -> -6663.15 | Y3: =SUMIF('Performance Data'!$B:$B, $B3,'Performance Data'!AG:AG) -> 5000 | Z3: =J3 -> 0 | AA3: =K3 -> 0 | AC3: =Z3/X3-1 -> -1 | AD3: =Z3/Y3-1 -> -1 | AE3: =AA3/Z3-1 -> #DIV/0! | AG3: =$AA3*1/12 -> 0 | AH3: =$AA3*1/12 -> 0 | AI3: =$AA3*1/12 -> 0 | AJ3: =$AA3*1/12 -> 0 | AK3: =$AA3*1/12 -> 0 | AL3: =$AA3*1/12 -> 0 | AM3: =$AA3*1/12 -> 0 | AN3: =$AA3*1/12 -> 0 | ... AR3: =$AA3*1/12 -> 0
B4: 51176 | C4: The Hut.com Ltd; GB | D4: =VLOOKUP($B4, 'Performance Data'!$B:$K, 3, 0) -> UK | E4: =VLOOKUP($B4, 'Performance Data'!$B:$K, 5, 0) -> eTailers | F4: =VLOOKUP($B4, 'Performance Data'!$B:$K, 6, 0) -> eTailers | G4: =VLOOKUP($B4, 'Performance Data'!$B:$K, 9, 0) -> Pre-2022 | I4: =VLOOKUP($B4, 'Performance Data'!$B:$K, 7, 0) -> BC | J4: =P4 -> 28083.11 | K4: 30000 | O4: =SUMIF('Performance Data'!$B:$B, $B4,'Performance Data'!N:N) -> 15312.81 | P4: =SUMIF('Performance Data'!$B:$B, $B4,'Performance Data'!O:O) -> 28083.11 | Q4: =SUMIF('Performance Data'!$B:$B, $B4,'Performance Data'!P:P) -> 10000 | S4: =$P4/O4-1 -> 0.83396189 | T4: =P4/Q4-1 -> 1.808311 | V4: =SUMIF('Performance Data'!$B:$B, $B4,'Performance Data'!AC:AC) -> 0 | W4: =SUMIF('Performance Data'!$B:$B, $B4,'Performance Data'!AD:AD) -> 31366.93 | X4: =SUMIF('Performance Data'!$B:$B, $B4,'Performance Data'!AE:AE) -> 15312.81 | Y4: =SUMIF('Performance Data'!$B:$B, $B4,'Performance Data'!AG:AG) -> 10000 | Z4: =J4 -> 28083.11 | AA4: =K4 -> 30000 | AC4: =Z4/X4-1 -> 0.83396189 | AD4: =Z4/Y4-1 -> 1.808311 | AE4: =AA4/Z4-1 -> 0.068257754 | AG4: =$AA4*1/12 -> 2500 | AH4: =$AA4*1/12 -> 2500 | AI4: =$AA4*1/12 -> 2500 | AJ4: =$AA4*1/12 -> 2500 | AK4: =$AA4*1/12 -> 2500 | AL4: =$AA4*1/12 -> 2500 | AM4: =$AA4*1/12 -> 2500 | AN4: =$AA4*1/12 -> 2500 | ... AR4: =$AA4*1/12 -> 2500
B5: Total Active Existing Doors | H5: =COUNTIF(H3:H4, "Yes") -> 0 | J5: =SUM(J3:J4) -> 28083.11 | K5: =SUM(K3:K4) -> 30000 | O5: =SUM(O3:O4) -> 8649.66 | P5: =SUM(P3:P4) -> 28083.11 | Q5: =SUM(Q3:Q4) -> 15000 | S5: =$P5/O5-1 -> 2.2467299 | T5: =P5/Q5-1 -> 0.87220733 | V5: =SUMIF('Performance Data'!$B:$B, $B5,'Performance Data'!AC:AC) -> 0 | W5: =SUM(W3:W4) -> 77039.28 | X5: =SUM(X3:X4) -> 8649.66 | Y5: =SUM(Y3:Y4) -> 15000 | Z5: =SUM(Z3:Z4) -> 28083.11 | AA5: =SUM(AA3:AA4) -> 30000 | AC5: =Z5/X5-1 -> 2.2467299 | AD5: =Z5/Y5-1 -> 0.87220733 | AE5: =AA5/Z5-1 -> 0.068257754 | AG5: =SUM(AG3:AG4) -> 2500 | AH5: =SUM(AH3:AH4) -> 2500 | AI5: =SUM(AI3:AI4) -> 2500 | AJ5: =SUM(AJ3:AJ4) -> 2500 | AK5: =SUM(AK3:AK4) -> 2500 | AL5: =SUM(AL3:AL4) -> 2500 | AM5: =SUM(AM3:AM4) -> 2500 | AN5: =SUM(AN3:AN4) -> 2500 | ... AR5: =SUM(AR3:AR4) -> 2500
B9: NKD25 | C9: New doors 2025 | D9: UK | E9: eTailers | G9: 2025 | H9: 0 | I9: NKD25 | J9: 0 | K9: 0 | O9: 0 | P9: 0 | Q9: 0 | S9: =$P9/O9-1 -> #DIV/0! | T9: =P9/Q9-1 -> #DIV/0! | V9: 0 | W9: 0 | X9: 0 | Y9: 0 | Z9: =J9 -> 0 | AA9: =K9 -> 0 | AC9: =Z9/X9-1 -> #DIV/0! | AD9: =Z9/Y9-1 -> #DIV/0! | AE9: =AA9/Z9-1 -> #DIV/0!
B11: Total New Doors 2025 | H11: =COUNTIF(H8, "Yes")+H9 -> 0 | J11: =SUM(J9:J9) -> 0 | K11: =SUM(K9:K9) -> 0 | O11: =SUM(O9:O9) -> 0 | P11: =SUM(P9:P9) -> 0 | Q11: =SUM(Q9:Q9) -> 0 | S11: =$P11/O11-1 -> #DIV/0! | T11: =P11/Q11-1 -> #DIV/0! | V11: =SUM(V9:V9) -> 0 | W11: =SUM(W9:W9) -> 0 | X11: =SUM(X9:X9) -> 0 | Y11: =SUM(Y9:Y9) -> 0 | Z11: =SUM(Z9:Z9) -> 0 | AA11: =SUM(AA9:AA9) -> 0 | AC11: =Z11/X11-1 -> #DIV/0! | AD11: =Z11/Y11-1 -> #DIV/0! | AE11: =AA11/Z11-1 -> #DIV/0!
B15: NKD26 | C15: New doors 2026 | D15: UK | E15: eTailers | G15: 2026 | H15: 0 | I15: NKD26 | K15: 0 | O15: 0 | P15: 0 | Q15: 0 | S15: =$P15/O15-1 -> #DIV/0! | T15: =P15/Q15-1 -> #DIV/0! | V15: 0 | W15: 0 | X15: 0 | Y15: 0 | Z15: =J15 -> 0 | AA15: =K15 -> 0 | AC15: =Z15/X15-1 -> #DIV/0! | AD15: =Z15/Y15-1 -> #DIV/0! | AE15: =AA15/Z15-1 -> #DIV/0!
B17: Total New Doors 2026 | H17: =COUNTIF(H14:H14, "Yes")+H15 -> 0 | J17: =SUM(J14:J15) -> 0 | K17: =SUM(K14:K15) -> 0 | O17: =SUM(O14:O15) -> 0 | P17: =SUM(P14:P15) -> 0 | Q17: =SUM(Q14:Q15) -> 0 | S17: =$P17/O17-1 -> #DIV/0! | T17: =P17/Q17-1 -> #DIV/0! | V17: =SUM(V14:V15) -> 0 | W17: =SUM(W14:W15) -> 0 | X17: =SUM(X14:X15) -> 0 | Y17: =SUM(Y14:Y15) -> 0 | Z17: =SUM(Z14:Z15) -> 0 | AA17: =SUM(AA14:AA15) -> 0 | AC17: =Z17/X17-1 -> #DIV/0! | AD17: =Z17/Y17-1 -> #DIV/0! | AE17: =AA17/Z17-1 -> #DIV/0!

Sheet Performance Data
L1: Year to date | M1: Year to date | N1: Year to date | O1: Year to date | P1: Year to date | R1: Year to date | S1: Year to date | T1: Year to date | U1: Year to date | V1: Year to date | X1: Year to date | Y1: Year to date | Z1: Year to date | AA1: Year to date | AC1: Full year | AD1: Full year | AE1: Full year | AF1: Full year | AG1: Full year | AI1: Full year | AJ1: Full year | AK1: Full year | AL1: Full year | AM1: Full year | AO1: Full year | AP1: Full year | AQ1: Full year | AR1: Full year
B2: Customer Code | C2: Customer Name | D2: Country | E2: Region | F2: Customer Map | G2: Mapping 2 | H2: Mapping 3 | I2: Active | J2: New door year | K2: New door month | L2: 2022 YTD | M2: 2023 YTD | N2: 2024 YTD | O2: 2025 YTD | P2: 2025B YTD | R2: 25 vs 24 % | S2: 25 vs 23 % | T2: 25 vs 22 % | U2: 25 vs 25B % | V2: 25 vs 22 CAGR % | X2: 25 vs 24 sales | Y2: 25 vs 23 sales | Z2: 25 vs 22 sales | AA2: 25 vs 25B sales | AC2: 2022 | AD2: 2023 | AE2: 2024 | AF2: 2025A | AG2: 2025B | AI2: 25 vs 24 % | AJ2: 25 vs 23 % | AK2: 25 vs 22 % | AL2: 25 vs 25B % | AM2: 25 vs 22 CAGR % | AO2: 25 vs 24 sales | AP2: 25 vs 23 sales | AQ2: 25 vs 22 sales | AR2: 25 vs 25B sales
B3: 51184 | C3: The Connaught Hotel | D3: UK | E3: UK | F3: =VLOOKUP($B3, '2025'!$B:$E, 3, 0) -> Spa | G3: =VLOOKUP($B3, '2025'!$B:$E, 4, 0) -> Spas / Hotels | H3: BB | I3: Yes | J3: 2023 | K3: 45261 | L3: =SUMIF('2022'!$B:$B, $B3,'2022'!$AF:$AF) -> 0 | M3: =SUMIF('2023'!$B:$B, $B3,'2023'!$AF:$AF) -> 6655.7 | N3: =SUMIF('2024'!$B:$B, $B3,'2024'!$AF:$AF) -> 26665.91 | O3: =SUMIF('2025'!$B:$B, $B3,'2025'!$AF:$AF) -> 19779.42 | P3: =SUMIF('2025B'!$B:$B, $B3,'2025B'!$AF:$AF) -> 20000 | R3: =IFERROR($O3/N3-1, "N/A") -> -0.2582507 | S3: =IFERROR($O3/M3-1, "N/A") -> 1.9718016 | T3: =IFERROR($O3/L3-1, "N/A") -> N/A | U3: =IFERROR($O3/P3-1, "N/A") -> -0.011029 | V3: =IFERROR(_xlfn.RRI(4,L3,O3), "N/A") -> N/A | X3: =$O3-N3 -> -6886.49 | Y3: =$O3-M3 -> 13123.72 | Z3: =$O3-L3 -> 19779.42 | AA3: =$O3-P3 -> -220.58 | AC3: =SUMIF('2022'!$B:$B, $B3,'2022'!$AF:$AF) -> 0 | AD3: =SUMIF('2023'!$B:$B, $B3,'2023'!$AF:$AF) -> 6655.7 | AE3: =SUMIF('2024'!$B:$B, $B3,'2024'!$AF:$AF) -> 26665.91 | AF3: =O3 -> 19779.42 | AG3: =SUMIF('2025B'!$B:$B, $B3,'2025B'!$AF:$AF) -> 20000 | AI3: =IFERROR($AF3/AE3-1, "N/A") -> -0.2582507 | AJ3: =IFERROR($AF3/AD3-1, "N/A") -> 1.9718016 | AK3: =IFERROR($AF3/AC3-1, "N/A") -> N/A | AL3: =IFERROR($AF3/AG3-1, "N/A") -> -0.011029 | AM3: =IFERROR(_xlfn.RRI(4,AC3,AF3), "N/A") -> N/A | AO3: =$AF3-AE3 -> -6886.49 | AP3: =$AF3-AD3 -> 13123.72 | AQ3: =$AF3-AC3 -> 19779.42 | AR3: =$AF3-AG3 -> -220.58
B4: 51185 | C4: Four Seasons Hotel London | D4: UK | E4: UK | F4: =VLOOKUP($B4, '2025'!$B:$E, 3, 0) -> Spa | G4: =VLOOKUP($B4, '2025'!$B:$E, 4, 0) -> Spas / Hotels | H4: NKD24 | I4: Yes | J4: 2024 | K4: 45352 | L4: =SUMIF('2022'!$B:$B, $B4,'2022'!$AF:$AF) -> 0 | M4: =SUMIF('2023'!$B:$B, $B4,'2023'!$AF:$AF) -> 0 | N4: =SUMIF('2024'!$B:$B, $B4,'2024'!$AF:$AF) -> 4761.01 | O4: =SUMIF('2025'!$B:$B, $B4,'2025'!$AF:$AF) -> 3448.59 | P4: =SUMIF('2025B'!$B:$B, $B4,'2025B'!$AF:$AF) -> 5000 | R4: =IFERROR($O4/N4-1, "N/A") -> -0.27566 | S4: =IFERROR($O4/M4-1, "N/A") -> N/A | T4: =IFERROR($O4/L4-1, "N/A") -> N/A | U4: =IFERROR($O4/P4-1, "N/A") -> -0.310282 | V4: =IFERROR(_xlfn.RRI(4,L4,O4), "N/A") -> N/A | X4: =$O4-N4 -> -1312.42 | Y4: =$O4-M4 -> 3448.59 | Z4: =$O4-L4 -> 3448.59 | AA4: =$O4-P4 -> -1551.41 | AC4: =SUMIF('2022'!$B:$B, $B4,'2022'!$AF:$AF) -> 0 | AD4: =SUMIF('2023'!$B:$B, $B4,'2023'!$AF:$AF) -> 0 | AE4: =SUMIF('2024'!$B:$B, $B4,'2024'!$AF:$AF) -> 4761.01 | AF4: =O4 -> 3448.59 | AG4: =SUMIF('2025B'!$B:$B, $B4,'2025B'!$AF:$AF) -> 5000 | AI4: =IFERROR($AF4/AE4-1, "N/A") -> -0.27566 | AJ4: =IFERROR($AF4/AD4-1, "N/A") -> N/A | AK4: =IFERROR($AF4/AC4-1, "N/A") -> N/A | AL4: =IFERROR($AF4/AG4-1, "N/A") -> -0.310282 | AM4: =IFERROR(_xlfn.RRI(4,AC4,AF4), "N/A") -> N/A | AO4: =$AF4-AE4 -> -1312.42 | AP4: =$AF4-AD4 -> 3448.59 | AQ4: =$AF4-AC4 -> 3448.59 | AR4: =$AF4-AG4 -> -1551.41
B5: 51186 | C5: hope street hotel; Liverpool | D5: UK | E5: UK | F5: =VLOOKUP($B5, '2025'!$B:$E, 3, 0) -> Spa | G5: =VLOOKUP($B5, '2025'!$B:$E, 4, 0) -> Spas / Hotels | H5: BB | I5: Yes | J5: 2023 | K5: 45231 | L5: =SUMIF('2022'!$B:$B, $B5,'2022'!$AF:$AF) -> 0 | M5: =SUMIF('2023'!$B:$B, $B5,'2023'!$AF:$AF) -> 2266.78 | N5: =SUMIF('2024'!$B:$B, $B5,'2024'!$AF:$AF) -> 8045.51 | O5: =SUMIF('2025'!$B:$B, $B5,'2025'!$AF:$AF) -> 1162.46 | P5: =SUMIF('2025B'!$B:$B, $B5,'2025B'!$AF:$AF) -> 10000 | R5: =IFERROR($O5/N5-1, "N/A") -> -0.85551444 | S5: =IFERROR($O5/M5-1, "N/A") -> -0.48717564 | T5: =IFERROR($O5/L5-1, "N/A") -> N/A | U5: =IFERROR($O5/P5-1, "N/A") -> -0.883754 | V5: =IFERROR(_xlfn.RRI(4,L5,O5), "N/A") -> N/A | X5: =$O5-N5 -> -6883.05 | Y5: =$O5-M5 -> -1104.32 | Z5: =$O5-L5 -> 1162.46 | AA5: =$O5-P5 -> -8837.54 | AC5: =SUMIF('2022'!$B:$B, $B5,'2022'!$AF:$AF) -> 0 | AD5: =SUMIF('2023'!$B:$B, $B5,'2023'!$AF:$AF) -> 2266.78 | AE5: =SUMIF('2024'!$B:$B, $B5,'2024'!$AF:$AF) -> 8045.51 | AF5: =O5 -> 1162.46 | AG5: =SUMIF('2025B'!$B:$B, $B5,'2025B'!$AF:$AF) -> 10000 | AI5: =IFERROR($AF5/AE5-1, "N/A") -> -0.85551444 | AJ5: =IFERROR($AF5/AD5-1, "N/A") -> -0.48717564 | AK5: =IFERROR($AF5/AC5-1, "N/A") -> N/A | AL5: =IFERROR($AF5/AG5-1, "N/A") -> -0.883754 | AM5: =IFERROR(_xlfn.RRI(4,AC5,AF5), "N/A") -> N/A | AO5: =$AF5-AE5 -> -6883.05 | AP5: =$AF5-AD5 -> -1104.32 | AQ5: =$AF5-AC5 -> 1162.46 | AR5: =$AF5-AG5 -> -8837.54
B6: 51187 | C6: Julia Knight; Sale | D6: UK | E6: UK | F6: =VLOOKUP($B6, '2025'!$B:$E, 3, 0) -> Spa | G6: =VLOOKUP($B6, '2025'!$B:$E, 4, 0) -> Institutes / Clinics | H6: CC | I6: Yes | J6: 2023 | K6: 45261 | L6: =SUMIF('2022'!$B:$B, $B6,'2022'!$AF:$AF) -> 0 | M6: =SUMIF('2023'!$B:$B, $B6,'2023'!$AF:$AF) -> 1173.99 | N6: =SUMIF('2024'!$B:$B, $B6,'2024'!$AF:$AF) -> 2526.58 | O6: =SUMIF('2025'!$B:$B, $B6,'2025'!$AF:$AF) -> 3504.29 | P6: =SUMIF('2025B'!$B:$B, $B6,'2025B'!$AF:$AF) -> 2000 | R6: =IFERROR($O6/N6-1, "N/A") -> 0.38696974 | S6: =IFERROR($O6/M6-1, "N/A") -> 1.9849402 | T6: =IFERROR($O6/L6-1, "N/A") -> N/A | U6: =IFERROR($O6/P6-1, "N/A") -> 0.752145 | V6: =IFERROR(_xlfn.RRI(4,L6,O6), "N/A") -> N/A | X6: =$O6-N6 -> 977.71 | Y6: =$O6-M6 -> 2330.3 | Z6: =$O6-L6 -> 3504.29 | AA6: =$O6-P6 -> 1504.29 | AC6: =SUMIF('2022'!$B:$B, $B6,'2022'!$AF:$AF) -> 0 | AD6: =SUMIF('2023'!$B:$B, $B6,'2023'!$AF:$AF) -> 1173.99 | AE6: =SUMIF('2024'!$B:$B, $B6,'2024'!$AF:$AF) -> 2526.58 | AF6: =O6 -> 3504.29 | AG6: =SUMIF('2025B'!$B:$B, $B6,'2025B'!$AF:$AF) -> 2000 | AI6: =IFERROR($AF6/AE6-1, "N/A") -> 0.38696974 | AJ6: =IFERROR($AF6/AD6-1, "N/A") -> 1.9849402 | AK6: =IFERROR($AF6/AC6-1, "N/A") -> N/A | AL6: =IFERROR($AF6/AG6-1, "N/A") -> 0.752145 | AM6: =IFERROR(_xlfn.RRI(4,AC6,AF6), "N/A") -> N/A | AO6: =$AF6-AE6 -> 977.71 | AP6: =$AF6-AD6 -> 2330.3 | AQ6: =$AF6-AC6 -> 3504.29 | AR6: =$AF6-AG6 -> 1504.29
B7: 51189 | C7: RTL Limited; The Grove Hotel | D7: UK | E7: UK | F7: =VLOOKUP($B7, '2025'!$B:$E, 3, 0) -> Spa | G7: =VLOOKUP($B7, '2025'!$B:$E, 4, 0) -> Spas / Hotels | H7: NKD24 | I7: Yes | J7: 2024 | K7: 45505 | L7: =SUMIF('2022'!$B:$B, $B7,'2022'!$AF:$AF) -> 0 | M7: =SUMIF('2023'!$B:$B, $B7,'2023'!$AF:$AF) -> 0 | N7: =SUMIF('2024'!$B:$B, $B7,'2024'!$AF:$AF) -> 28806.05 | O7: =SUMIF('2025'!$B:$B, $B7,'2025'!$AF:$AF) -> 32939.5 | P7: =SUMIF('2025B'!$B:$B, $B7,'2025B'!$AF:$AF) -> 30000 | R7: =IFERROR($O7/N7-1, "N/A") -> 0.14349243 | S7: =IFERROR($O7/M7-1, "N/A") -> N/A | T7: =IFERROR($O7/L7-1, "N/A") -> N/A | U7: =IFERROR($O7/P7-1, "N/A") -> 0.097983333 | V7: =IFERROR(_xlfn.RRI(4,L7,O7), "N/A") -> N/A | X7: =$O7-N7 -> 4133.45 | Y7: =$O7-M7 -> 32939.5 | Z7: =$O7-L7 -> 32939.5 | AA7: =$O7-P7 -> 2939.5 | AC7: =SUMIF('2022'!$B:$B, $B7,'2022'!$AF:$AF) -> 0 | AD7: =SUMIF('2023'!$B:$B, $B7,'2023'!$AF:$AF) -> 0 | AE7: =SUMIF('2024'!$B:$B, $B7,'2024'!$AF:$AF) -> 28806.05 | AF7: =O7 -> 32939.5 | AG7: =SUMIF('2025B'!$B:$B, $B7,'2025B'!$AF:$AF) -> 30000 | AI7: =IFERROR($AF7/AE7-1, "N/A") -> 0.14349243 | AJ7: =IFERROR($AF7/AD7-1, "N/A") -> N/A | AK7: =IFERROR($AF7/AC7-1, "N/A") -> N/A | AL7: =IFERROR($AF7/AG7-1, "N/A") -> 0.097983333 | AM7: =IFERROR(_xlfn.RRI(4,AC7,AF7), "N/A") -> N/A | AO7: =$AF7-AE7 -> 4133.45 | AP7: =$AF7-AD7 -> 32939.5 | AQ7: =$AF7-AC7 -> 32939.5 | AR7: =$AF7-AG7 -> 2939.5
B8: 53000 | C8: IzzyJ Aesthetics | D8: UK | E8: UK | F8: Spa | G8: =VLOOKUP($B8, '2025'!$B:$E, 4, 0) -> Other | H8: CC | I8: Yes | J8: Pre-2022 | K8: Pre-2022 | L8: =SUMIF('2022'!$B:$B, $B8,'2022'!$AF:$AF) -> 0 | M8: =SUMIF('2023'!$B:$B, $B8,'2023'!$AF:$AF) -> 610.56 | N8: =SUMIF('2024'!$B:$B, $B8,'2024'!$AF:$AF) -> 2165.32 | O8: =SUMIF('2025'!$B:$B, $B8,'2025'!$AF:$AF) -> 487.8 | P8: =SUMIF('2025B'!$B:$B, $B8,'2025B'!$AF:$AF) -> 0 | R8: =IFERROR($O8/N8-1, "N/A") -> -0.77472152 | S8: =IFERROR($O8/M8-1, "N/A") -> -0.20106132 | T8: =IFERROR($O8/L8-1, "N/A") -> N/A | U8: =IFERROR($O8/P8-1, "N/A") -> N/A | V8: =IFERROR(_xlfn.RRI(4,L8,O8), "N/A") -> N/A | X8: =$O8-N8 -> -1677.52 | Y8: =$O8-M8 -> -122.76 | Z8: =$O8-L8 -> 487.8 | AA8: =$O8-P8 -> 487.8 | AC8: =SUMIF('2022'!$B:$B, $B8,'2022'!$AF:$AF) -> 0 | AD8: =SUMIF('2023'!$B:$B, $B8,'2023'!$AF:$AF) -> 610.56 | AE8: =SUMIF('2024'!$B:$B, $B8,'2024'!$AF:$AF) -> 2165.32 | AF8: =O8 -> 487.8 | AG8: =SUMIF('2025B'!$B:$B, $B8,'2025B'!$AF:$AF) -> 0 | AI8: =IFERROR($AF8/AE8-1, "N/A") -> -0.77472152 | AJ8: =IFERROR($AF8/AD8-1, "N/A") -> -0.20106132 | AK8: =IFERROR($AF8/AC8-1, "N/A") -> N/A | AL8: =IFERROR($AF8/AG8-1, "N/A") -> N/A | AM8: =IFERROR(_xlfn.RRI(4,AC8,AF8), "N/A") -> N/A | AO8: =$AF8-AE8 -> -1677.52 | AP8: =$AF8-AD8 -> -122.76 | AQ8: =$AF8-AC8 -> 487.8 | AR8: =$AF8-AG8 -> 487.8
