Workbook

Sheet Summary
B2: EUR | C2: Full Year | I2: YTD | O2: Full Year | S2: Total sales | AL2: Existing | AZ2: New
C3: 25A | D3: 25B | E3: 25F vs 25B | F3: 24A | G3: 25F vs 24A | I3: 25A | J3: 25B | K3: 25A vs 25B | L3: 24A | M3: 25A vs 24A | O3: 26B | P3: 25A | Q3: 26B vs 25F | S3: 46023 | T3: 46054 | U3: 46082 | V3: 46113 | W3: 46143 | X3: 46174 | Y3: 46204 | Z3: 46235 | AA3: 46266 | AB3: 46296 | AC3: 46327 | AD3: 46357 | AF3: Target: | AG3: Target NC | AH3: Growth | AI3: Comment | AL3: 46023 | AM3: 46054 | AN3: 46082 | AO3: 46113 | AP3: 46143 | AQ3: 46174 | AR3: 46204 | AS3: 46235 | AT3: 46266 | AU3: 46296 | AV3: 46327 | AW3: 46357 | AZ3: 46023 | BA3: 46054 | BB3: 46082 | BC3: 46113 | BD3: 46143 | BE3: 46174 | BF3: 46204 | BG3: 46235 | BH3: 46266 | BI3: 46296 | BJ3: 46327 | BK3: 46357
B4: North | C4: =North!Z28+North!Z35+North!Z41 -> 602834.42 | D4: =North!Y28+North!Y35+North!Y41 -> 757700 | E4: =IFERROR(C4/D4-1, "N/A") -> -0.20438905 | F4: =North!X28+North!X35+North!X41 -> 674868.99 | G4: =IFERROR(C4/F4-1, "N/A") -> -0.1067386 | I4: =North!P28+North!P35+North!P41 -> 602834.42 | J4: =North!Q28+North!Q35+North!Q41 -> 532111.49 | K4: =IFERROR(I4/J4-1, "N/A") -> 0.13290998 | L4: =North!O28+North!O35+North!O41 -> 601941.21 | M4: =IFERROR(I4/L4-1, "N/A") -> 0.0014838825 | O4: =North!AA28+North!AA35+North!AA41 -> 713889.64 | P4: =C4 -> 602834.42 | Q4: =IFERROR(O4/P4-1, "N/A") -> 0.18422176 | S4: =North!AG28+North!AG35+North!AG41 -> 45772.275 | T4: =North!AH28+North!AH35+North!AH41 -> 56311.171 | U4: =North!AI28+North!AI35+North!AI41 -> 70388.964 | V4: =North!AJ28+North!AJ35+North!AJ41 -> 60580.619 | W4: =North!AK28+North!AK35+North!AK41 -> 64850.068 | X4: =North!AL28+North!AL35+North!AL41 -> 58311.171 | Y4: =North!AM28+North!AM35+North!AM41 -> 56311.171 | Z4: =North!AN28+North!AN35+North!AN41 -> 44502.827 | ... AD4: =North!AR28+North!AR35+North!AR41 -> 50772.275 | AF4: =North!K28+North!K32 -> 653889.64 | AG4: 60000 | AH4: =AF4/P4-1 -> 0.084691944 | AJ4: =SUM(S4:AD4)-SUM(AF4:AG4) -> 0 | AL4: =North!AG28+North!AG35 -> 45772.275 | AM4: =North!AH28+North!AH35 -> 52311.171 | AN4: =North!AI28+North!AI35 -> 65388.964 | AO4: =North!AJ28+North!AJ35 -> 55580.619 | AP4: =North!AK28+North!AK35 -> 58850.068 | AQ4: =North!AL28+North!AL35 -> 52311.171 | AR4: =North!AM28+North!AM35 -> 52311.171 | AS4: =North!AN28+North!AN35 -> 42502.827 | ... AW4: =North!AR28+North!AR35 -> 45772.275 | AZ4: =S4-AL4 -> 0 | BA4: =T4-AM4 -> 4000 | BB4: =U4-AN4 -> 5000 | BC4: =V4-AO4 -> 5000 | BD4: =W4-AP4 -> 6000 | BE4: =X4-AQ4 -> 6000 | BF4: =Y4-AR4 -> 4000 | BG4: =Z4-AS4 -> 2000 | ... BK4: =AD4-AW4 -> 5000
B5: North East | C5: ='North East'!Z21+'North East'!Z28+'North East'!Z34 -> 375419.11 | D5: ='North East'!Y21+'North East'!Y28+'North East'!Y34 -> 329000 | E5: =IFERROR(C5/D5-1, "N/A") -> 0.14109152 | F5: ='North East'!X21+'North East'!X28+'North East'!X34 -> 304271.93 | G5: =IFERROR(C5/F5-1, "N/A") -> 0.23382762 | O5: ='North East'!AA21+'North East'!AA28+'North East'!AA34 -> 470452.64 | P5: =C5 -> 375419.11 | Q5: =IFERROR(O5/P5-1, "N/A") -> 0.25313983 | S5: ='North East'!AG21+'North East'!AG28+'North East'!AG34 -> 28381.685 | T5: ='North East'!AH21+'North East'!AH28+'North East'!AH34 -> 36436.211 | U5: ='North East'!AI21+'North East'!AI28+'North East'!AI34 -> 44545.264 | V5: ='North East'!AJ21+'North East'!AJ28+'North East'!AJ34 -> 38463.474 | W5: ='North East'!AK21+'North East'!AK28+'North East'!AK34 -> 40490.737 | X5: ='North East'!AL21+'North East'!AL28+'North East'!AL34 -> 37436.211 | Y5: ='North East'!AM21+'North East'!AM28+'North East'!AM34 -> 38436.211 | Z5: ='North East'!AN21+'North East'!AN28+'North East'!AN34 -> 29354.422 | ... AD5: ='North East'!AR21+'North East'!AR28+'North East'!AR34 -> 35381.685 | AF5: ='North East'!K21 -> 405452.64 | AG5: 65000 | AH5: =AF5/P5-1 -> 0.08 | AJ5: =SUM(S5:AD5)-SUM(AF5:AG5) -> 0 | AL5: ='North East'!AG21+'North East'!AG28 -> 28381.685 | AM5: ='North East'!AH21+'North East'!AH28 -> 32436.211 | AN5: ='North East'!AI21+'North East'!AI28 -> 40545.264 | AO5: ='North East'!AJ21+'North East'!AJ28 -> 34463.474 | AP5: ='North East'!AK21+'North East'!AK28 -> 36490.737 | AQ5: ='North East'!AL21+'North East'!AL28 -> 32436.211 | AR5: ='North East'!AM21+'North East'!AM28 -> 32436.211 | AS5: ='North East'!AN21+'North East'!AN28 -> 26354.422 | ... AW5: ='North East'!AR21+'North East'!AR28 -> 28381.685 | AZ5: =S5-AL5 -> 0 | BA5: =T5-AM5 -> 4000 | BB5: =U5-AN5 -> 4000 | BC5: =V5-AO5 -> 4000 | BD5: =W5-AP5 -> 4000 | BE5: =X5-AQ5 -> 5000 | BF5: =Y5-AR5 -> 6000 | BG5: =Z5-AS5 -> 3000 | ... BK5: =AD5-AW5 -> 7000
B6: NRW | C6: =C62 -> 685835.6 | D6: =D62 -> 711500 | E6: =IFERROR(C6/D6-1, "N/A") -> -0.036070836 | F6: =F62 -> 600179.62 | G6: =IFERROR(C6/F6-1, "N/A") -> 0.14271724 | I6: ='NRW Ulrike'!P23+'NRW Ulrike'!P31+'NRW Ulrike'!P37 -> 22367.95 | J6: ='NRW Ulrike'!Q23+'NRW Ulrike'!Q31+'NRW Ulrike'!Q37 -> 11250 | K6: =IFERROR(I6/J6-1, "N/A") -> 0.98826222 | L6: ='NRW Ulrike'!O23+'NRW Ulrike'!O31+'NRW Ulrike'!O37 -> 0 | M6: =IFERROR(I6/L6-1, "N/A") -> N/A | O6: =O62 -> 837067.21 | P6: =C6 -> 685835.6 | Q6: =IFERROR(O6/P6-1, "N/A") -> 0.22050708 | S6: =S62 -> 52644.705 | T6: =T62 -> 67165.377 | U6: =U62 -> 82206.721 | V6: =V62 -> 70925.713 | W6: =W62 -> 74686.049 | X6: =X62 -> 67165.377 | Y6: =Y62 -> 67165.377 | Z6: =Z62 -> 52884.369 | ... AD6: =AD62 -> 60644.705 | AF6: =AF62 -> 752067.21 | AG6: =AG62 -> 85000 | AH6: =AF6/P6-1 -> 0.096570677 | AJ6: =SUM(S6:AD6)-SUM(AF6:AG6) -> 0 | AL6: =AL62 -> 52644.705 | AM6: =AM62 -> 60165.377 | AN6: =AN62 -> 75206.721 | AO6: =AO62 -> 63925.713 | AP6: =AP62 -> 67686.049 | AQ6: =AQ62 -> 60165.377 | AR6: =AR62 -> 60165.377 | AS6: =AS62 -> 48884.369 | ... AW6: =AW62 -> 52644.705 | AZ6: =AZ62 -> 0 | BA6: =BA62 -> 7000 | BB6: =BB62 -> 7000 | BC6: =BC62 -> 7000 | BD6: =BD62 -> 7000 | BE6: =BE62 -> 7000 | BF6: =BF62 -> 7000 | BG6: =BG62 -> 4000 | ... BK6: =BK62 -> 8000
B7: South West | C7: ='South West'!Z63+'South West'!Z72+'South West'!Z78 -> 1740960.7 | D7: ='South West'!Y63+'South West'!Y72+'South West'!Y78 -> 1878000 | E7: =IFERROR(C7/D7-1, "N/A") -> -0.072970873 | F7: ='South West'!X63+'South West'!X72+'South West'!X78 -> 1772537.5 | G7: =IFERROR(C7/F7-1, "N/A") -> -0.017814466 | I7: ='South West'!P63+'South West'!P72+'South West'!P78 -> 1740960.7 | J7: ='South West'!Q63+'South West'!Q72+'South West'!Q78 -> 1360290 | K7: =IFERROR(I7/J7-1, "N/A") -> 0.27984525 | L7: ='South West'!O63+'South West'!O72+'South West'!O78 -> 1772537.5 | M7: =IFERROR(I7/L7-1, "N/A") -> -0.017814466 | O7: ='South West'!AA63+'South West'!AA72+'South West'!AA78 -> 1903818.2 | P7: =C7 -> 1740960.7 | Q7: =IFERROR(O7/P7-1, "N/A") -> 0.093544598 | S7: ='South West'!AG63+'South West'!AG72+'South West'!AG78 -> 129767.27 | T7: ='South West'!AH63+'South West'!AH72+'South West'!AH78 -> 152305.45 | U7: ='South West'!AI63+'South West'!AI72+'South West'!AI78 -> 189381.82 | V7: ='South West'!AJ63+'South West'!AJ72+'South West'!AJ78 -> 161574.54 | W7: ='South West'!AK63+'South West'!AK72+'South West'!AK78 -> 170843.64 | X7: ='South West'!AL63+'South West'!AL72+'South West'!AL78 -> 152305.45 | Y7: ='South West'!AM63+'South West'!AM72+'South West'!AM78 -> 152305.45 | Z7: ='South West'!AN63+'South West'!AN72+'South West'!AN78 -> 122498.18 | ... AD7: ='South West'!AR63+'South West'!AR72+'South West'!AR78 -> 134767.27 | AF7: ='South West'!K63+'South West'!K72 -> 1853818.2 | AG7: 50000 | AH7: =AF7/P7-1 -> 0.064824823 | AJ7: =SUM(S7:AD7)-SUM(AF7:AG7) -> 0 | AL7: ='South West'!AG63+'South West'!AG72 -> 129767.27 | AM7: ='South West'!AH63+'South West'!AH72 -> 148305.45 | AN7: ='South West'!AI63+'South West'!AI72 -> 185381.82 | AO7: ='South West'!AJ63+'South West'!AJ72 -> 157574.54 | AP7: ='South West'!AK63+'South West'!AK72 -> 166843.64 | AQ7: ='South West'!AL63+'South West'!AL72 -> 148305.45 | AR7: ='South West'!AM63+'South West'!AM72 -> 148305.45 | AS7: ='South West'!AN63+'South West'!AN72 -> 120498.18 | ... AW7: ='South West'!AR63+'South West'!AR72 -> 129767.27 | AZ7: =S7-AL7 -> 0 | BA7: =T7-AM7 -> 4000 | BB7: =U7-AN7 -> 4000 | BC7: =V7-AO7 -> 4000 | BD7: =W7-AP7 -> 4000 | BE7: =X7-AQ7 -> 4000 | BF7: =Y7-AR7 -> 4000 | BG7: =Z7-AS7 -> 2000 | ... BK7: =AD7-AW7 -> 5000
B8: Bayern | C8: =Bayern!Z30+Bayern!Z38+Bayern!Z44 -> 564796.81 | D8: =Bayern!Y30+Bayern!Y38+Bayern!Y44 -> 637000 | E8: =IFERROR(C8/D8-1, "N/A") -> -0.11334881 | F8: =Bayern!X30+Bayern!X38+Bayern!X44 -> 544865.42 | G8: =IFERROR(C8/F8-1, "N/A") -> 0.036580391 | I8: =Bayern!P30+Bayern!P38+Bayern!P44 -> 564796.81 | J8: =Bayern!Q30+Bayern!Q38+Bayern!Q44 -> 454360 | K8: =IFERROR(I8/J8-1, "N/A") -> 0.24306015 | L8: =Bayern!O30+Bayern!O38+Bayern!O44 -> 544865.42 | M8: =IFERROR(I8/L8-1, "N/A") -> 0.036580391 | O8: =Bayern!AA30+Bayern!AA38+Bayern!AA44 -> 669939.2 | P8: =C8 -> 564796.81 | Q8: =IFERROR(O8/P8-1, "N/A") -> 0.18615967 | S8: =Bayern!AG30+Bayern!AG38+Bayern!AG44 -> 43045.744 | T8: =Bayern!AH30+Bayern!AH38+Bayern!AH44 -> 53195.136 | U8: =Bayern!AI30+Bayern!AI38+Bayern!AI44 -> 65493.92 | V8: =Bayern!AJ30+Bayern!AJ38+Bayern!AJ44 -> 57269.832 | W8: =Bayern!AK30+Bayern!AK38+Bayern!AK44 -> 60344.528 | X8: =Bayern!AL30+Bayern!AL38+Bayern!AL44 -> 55195.136 | Y8: =Bayern!AM30+Bayern!AM38+Bayern!AM44 -> 54195.136 | Z8: =Bayern!AN30+Bayern!AN38+Bayern!AN44 -> 42971.048 | ... AD8: =Bayern!AR30+Bayern!AR38+Bayern!AR44 -> 48045.744 | AF8: =Bayern!K30+Bayern!K38 -> 614939.2 | AG8: 55000 | AH8: =AF8/P8-1 -> 0.088779513 | AJ8: =SUM(S8:AD8)-SUM(AF8:AG8) -> 0 | AL8: =Bayern!AG30+Bayern!AG38 -> 43045.744 | AM8: =Bayern!AH30+Bayern!AH38 -> 49195.136 | AN8: =Bayern!AI30+Bayern!AI38 -> 61493.92 | AO8: =Bayern!AJ30+Bayern!AJ38 -> 52269.832 | AP8: =Bayern!AK30+Bayern!AK38 -> 55344.528 | AQ8: =Bayern!AL30+Bayern!AL38 -> 49195.136 | AR8: =Bayern!AM30+Bayern!AM38 -> 49195.136 | AS8: =Bayern!AN30+Bayern!AN38 -> 39971.048 | ... AW8: =Bayern!AR30+Bayern!AR38 -> 43045.744 | AZ8: =S8-AL8 -> 0 | BA8: =T8-AM8 -> 4000 | BB8: =U8-AN8 -> 4000 | BC8: =V8-AO8 -> 5000 | BD8: =W8-AP8 -> 5000 | BE8: =X8-AQ8 -> 6000 | BF8: =Y8-AR8 -> 5000 | BG8: =Z8-AS8 -> 3000 | ... BK8: =AD8-AW8 -> 5000
B9: Retail | C9: =Retail!Z6 -> 197085.25 | D9: =Retail!Y6 -> 200000 | E9: =IFERROR(C9/D9-1, "N/A") -> -0.01457375 | F9: =Retail!X6 -> 76005.05 | G9: =IFERROR(C9/F9-1, "N/A") -> 1.5930547 | I9: =Retail!P6 -> 197085.25 | J9: =Retail!Q6 -> 146000 | K9: =IFERROR(I9/J9-1, "N/A") -> 0.34989897 | L9: =Retail!O6 -> 135005.05 | M9: =IFERROR(I9/L9-1, "N/A") -> 0.45983613 | O9: =Retail!AA6 -> 200000 | P9: =C9 -> 197085.25 | Q9: =IFERROR(O9/P9-1, "N/A") -> 0.014789285 | S9: =Retail!AG6 -> 14000 | T9: =Retail!AH6 -> 16000 | U9: =Retail!AI6 -> 20000 | V9: =Retail!AJ6 -> 17000 | W9: =Retail!AK6 -> 18000 | X9: =Retail!AL6 -> 16000 | Y9: =Retail!AM6 -> 16000 | Z9: =Retail!AN6 -> 13000 | ... AD9: =Retail!AR6 -> 14000 | AF9: 200000 | AH9: =AF9/P9-1 -> 0.014789285 | AJ9: =SUM(S9:AD9)-SUM(AF9:AG9) -> 0 | AL9: =Retail!AG6 -> 14000 | AM9: =Retail!AH6 -> 16000 | AN9: =Retail!AI6 -> 20000 | AO9: =Retail!AJ6 -> 17000 | AP9: =Retail!AK6 -> 18000 | AQ9: =Retail!AL6 -> 16000 | AR9: =Retail!AM6 -> 16000 | AS9: =Retail!AN6 -> 13000 | ... AW9: =Retail!AR6 -> 14000 | AZ9: =S9-AL9 -> 0 | BA9: =T9-AM9 -> 0 | BB9: =U9-AN9 -> 0 | BC9: =V9-AO9 -> 0 | BD9: =W9-AP9 -> 0 | BE9: =X9-AQ9 -> 0 | BF9: =Y9-AR9 -> 0 | BG9: =Z9-AS9 -> 0 | ... BK9: =AD9-AW9 -> 0
B10: DE Other | C10: ='Golden Girls DE'!Z58 -> 116209.75 | D10: ='Golden Girls DE'!Y58 -> 86500 | E10: =IFERROR(C10/D10-1, "N/A") -> 0.34346532 | F10: ='Golden Girls DE'!X58 -> 124718.59 | G10: =IFERROR(C10/F10-1, "N/A") -> -0.068224312 | I10: ='Golden Girls DE'!P58 -> 116209.75 | J10: ='Golden Girls DE'!Q58 -> 63145 | K10: =IFERROR(I10/J10-1, "N/A") -> 0.84036345 | L10: ='Golden Girls DE'!O58 -> 124718.59 | M10: =IFERROR(I10/L10-1, "N/A") -> -0.068224312 | O10: ='Golden Girls DE'!AA58 -> 116600 | P10: =C10 -> 116209.75 | Q10: =IFERROR(O10/P10-1, "N/A") -> 0.003358152 | S10: ='Golden Girls DE'!AG58 -> 8162 | T10: ='Golden Girls DE'!AH58 -> 9328 | U10: ='Golden Girls DE'!AI58 -> 11660 | V10: ='Golden Girls DE'!AJ58 -> 9911 | W10: ='Golden Girls DE'!AK58 -> 10494 | X10: ='Golden Girls DE'!AL58 -> 9328 | Y10: ='Golden Girls DE'!AM58 -> 9328 | Z10: ='Golden Girls DE'!AN58 -> 7579 | ... AD10: ='Golden Girls DE'!AR58 -> 8162 | AF10: ='Golden Girls DE'!K58 -> 116600 | AH10: =AF10/P10-1 -> 0.003358152 | AJ10: =SUM(S10:AD10)-SUM(AF10:AG10) -> 0 | AL10: ='Golden Girls DE'!AG58 -> 8162 | AM10: ='Golden Girls DE'!AH58 -> 9328 | AN10: ='Golden Girls DE'!AI58 -> 11660 | AO10: ='Golden Girls DE'!AJ58 -> 9911 | AP10: ='Golden Girls DE'!AK58 -> 10494 | AQ10: ='Golden Girls DE'!AL58 -> 9328 | AR10: ='Golden Girls DE'!AM58 -> 9328 | AS10: ='Golden Girls DE'!AN58 -> 7579 | ... AW10: ='Golden Girls DE'!AR58 -> 8162 | AZ10: =S10-AL10 -> 0 | BA10: =T10-AM10 -> 0 | BB10: =U10-AN10 -> 0 | BC10: =V10-AO10 -> 0 | BD10: =W10-AP10 -> 0 | BE10: =X10-AQ10 -> 0 | BF10: =Y10-AR10 -> 0 | BG10: =Z10-AS10 -> 0 | ... BK10: =AD10-AW10 -> 0
AJ11: =SUM(S11:AD11)-SUM(AF11:AG11) -> 0
B12: Germany | C12: =SUM(C4:C10) -> 4283141.6 | D12: =SUM(D4:D10) -> 4599700 | E12: =IFERROR(C12/D12-1, "N/A") -> -0.068821523 | F12: =SUM(F4:F10) -> 4097447.1 | G12: =IFERROR(C12/F12-1, "N/A") -> 0.045319567 | I12: =SUM(I4:I10) -> 3244254.9 | J12: =SUM(J4:J10) -> 2567156.5 | K12: =IFERROR(I12/J12-1, "N/A") -> 0.26375423 | L12: =SUM(L4:L10) -> 3179067.8 | M12: =IFERROR(I12/L12-1, "N/A") -> 0.020505099 | O12: =SUM(O4:O10) -> 4911766.9 | P12: =SUM(P4:P10) -> 4283141.6 | Q12: =IFERROR(O12/P12-1, "N/A") -> 0.14676732 | S12: =SUM(S4:S10) -> 321773.68 | T12: =SUM(T4:T10) -> 390741.35 | U12: =SUM(U4:U10) -> 483676.69 | V12: =SUM(V4:V10) -> 415725.18 | W12: =SUM(W4:W10) -> 439709.02 | X12: =SUM(X4:X10) -> 395741.35 | Y12: =SUM(Y4:Y10) -> 393741.35 | Z12: =SUM(Z4:Z10) -> 312789.85 | ... AD12: =SUM(AD4:AD10) -> 351773.68 | AF12: =SUM(AF4:AF10) -> 4596766.9 | AG12: =SUM(AG4:AG10) -> 315000 | AH12: =AF12/P12-1 -> 0.073223171 | AJ12: =SUM(S12:AD12)-SUM(AF12:AG12) -> 0 | AL12: =SUM(AL4:AL10) -> 321773.68 | AM12: =SUM(AM4:AM10) -> 367741.35 | AN12: =SUM(AN4:AN10) -> 459676.69 | AO12: =SUM(AO4:AO10) -> 390725.18 | AP12: =SUM(AP4:AP10) -> 413709.02 | AQ12: =SUM(AQ4:AQ10) -> 367741.35 | AR12: =SUM(AR4:AR10) -> 367741.35 | AS12: =SUM(AS4:AS10) -> 298789.85 | ... AW12: =SUM(AW4:AW10) -> 321773.68 | AZ12: =SUM(AZ4:AZ10) -> 0 | BA12: =SUM(BA4:BA10) -> 23000 | BB12: =SUM(BB4:BB10) -> 24000 | BC12: =SUM(BC4:BC10) -> 25000 | BD12: =SUM(BD4:BD10) -> 26000 | BE12: =SUM(BE4:BE10) -> 28000 | BF12: =SUM(BF4:BF10) -> 26000 | BG12: =SUM(BG4:BG10) -> 14000 | ... BK12: =SUM(BK4:BK10) -> 30000
AJ13: =SUM(S13:AD13)-SUM(AF13:AG13) -> 0
B14: NL Central | C14: ='NL Central'!Z40+'NL Central'!Z47+'NL Central'!Z53 -> 883520.61 | D14: ='NL Central'!Y40+'NL Central'!Y47+'NL Central'!Y53 -> 977000 | E14: =IFERROR(C14/D14-1, "N/A") -> -0.095680031 | F14: ='NL Central'!X40+'NL Central'!X47+'NL Central'!X53 -> 901478.03 | G14: =IFERROR(C14/F14-1, "N/A") -> -0.019919975 | I14: ='NL Central'!P40+'NL Central'!P47+'NL Central'!P53 -> 883520.61 | J14: ='NL Central'!Q40+'NL Central'!Q47+'NL Central'!Q53 -> 695460 | K14: =IFERROR(I14/J14-1, "N/A") -> 0.27041183 | L14: ='NL Central'!O40+'NL Central'!O47+'NL Central'!O53 -> 901478.03 | M14: =IFERROR(I14/L14-1, "N/A") -> -0.019919975 | O14: ='NL Central'!AA40+'NL Central'!AA47+'NL Central'!AA53 -> 1003873.2 | P14: =C14 -> 883520.61 | Q14: =IFERROR(O14/P14-1, "N/A") -> 0.13621935 | S14: ='NL Central'!AG40+'NL Central'!AG47+'NL Central'!AG53 -> 66771.125 | T14: ='NL Central'!AH40+'NL Central'!AH47+'NL Central'!AH53 -> 80309.857 | U14: ='NL Central'!AI40+'NL Central'!AI47+'NL Central'!AI53 -> 99387.321 | V14: ='NL Central'!AJ40+'NL Central'!AJ47+'NL Central'!AJ53 -> 85079.223 | W14: ='NL Central'!AK40+'NL Central'!AK47+'NL Central'!AK53 -> 89848.589 | X14: ='NL Central'!AL40+'NL Central'!AL47+'NL Central'!AL53 -> 80309.857 | Y14: ='NL Central'!AM40+'NL Central'!AM47+'NL Central'!AM53 -> 80309.857 | Z14: ='NL Central'!AN40+'NL Central'!AN47+'NL Central'!AN53 -> 64001.759 | ... AD14: ='NL Central'!AR40+'NL Central'!AR47+'NL Central'!AR53 -> 71771.125 | AF14: ='NL Central'!K40+'NL Central'!K47 -> 953873.21 | AG14: 50000 | AH14: =AF14/P14-1 -> 0.07962757 | AJ14: =SUM(S14:AD14)-SUM(AF14:AG14) -> 0 | AL14: ='NL Central'!AG40+'NL Central'!AG47 -> 66771.125 | AM14: ='NL Central'!AH40+'NL Central'!AH47 -> 76309.857 | AN14: ='NL Central'!AI40+'NL Central'!AI47 -> 95387.321 | AO14: ='NL Central'!AJ40+'NL Central'!AJ47 -> 81079.223 | AP14: ='NL Central'!AK40+'NL Central'!AK47 -> 85848.589 | AQ14: ='NL Central'!AL40+'NL Central'!AL47 -> 76309.857 | AR14: ='NL Central'!AM40+'NL Central'!AM47 -> 76309.857 | AS14: ='NL Central'!AN40+'NL Central'!AN47 -> 62001.759 | ... AW14: ='NL Central'!AR40+'NL Central'!AR47 -> 66771.125 | AZ14: =S14-AL14 -> 0 | BA14: =T14-AM14 -> 4000 | BB14: =U14-AN14 -> 4000 | BC14: =V14-AO14 -> 4000 | BD14: =W14-AP14 -> 4000 | BE14: =X14-AQ14 -> 4000 | BF14: =Y14-AR14 -> 4000 | BG14: =Z14-AS14 -> 2000 | ... BK14: =AD14-AW14 -> 5000
B15: NL Other + BL | C15: ='NL Other_Belgium'!Z37+'NL Other_Belgium'!Z49+'NL Other_Belgium'!Z55 -> 958120.43 | D15: ='NL Other_Belgium'!Y37+'NL Other_Belgium'!Y49+'NL Other_Belgium'!Y55 -> 1036500 | E15: =IFERROR(C15/D15-1, "N/A") -> -0.07561946 | F15: ='NL Other_Belgium'!X37+'NL Other_Belgium'!X49+'NL Other_Belgium'!X55 -> 898194.38 | G15: =IFERROR(C15/F15-1, "N/A") -> 0.066718353 | I15: ='NL Other_Belgium'!P37+'NL Other_Belgium'!P49+'NL Other_Belgium'!P55 -> 958120.43 | J15: ='NL Other_Belgium'!Q37+'NL Other_Belgium'!Q49+'NL Other_Belgium'!Q55 -> 800020 | K15: =IFERROR(I15/J15-1, "N/A") -> 0.1976206 | L15: ='NL Other_Belgium'!O37+'NL Other_Belgium'!O49+'NL Other_Belgium'!O55 -> 898194.38 | M15: =IFERROR(I15/L15-1, "N/A") -> 0.066718353 | O15: ='NL Other_Belgium'!AA37+'NL Other_Belgium'!AA49+'NL Other_Belgium'!AA55 -> 1074723.8 | P15: =C15 -> 958120.43 | Q15: =IFERROR(O15/P15-1, "N/A") -> 0.12170014 | S15: ='NL Other_Belgium'!AG37+'NL Other_Belgium'!AG49+'NL Other_Belgium'!AG55 -> 71730.667 | T15: ='NL Other_Belgium'!AH37+'NL Other_Belgium'!AH49+'NL Other_Belgium'!AH55 -> 85977.905 | U15: ='NL Other_Belgium'!AI37+'NL Other_Belgium'!AI49+'NL Other_Belgium'!AI55 -> 106472.38 | V15: ='NL Other_Belgium'!AJ37+'NL Other_Belgium'!AJ49+'NL Other_Belgium'!AJ55 -> 91101.524 | W15: ='NL Other_Belgium'!AK37+'NL Other_Belgium'!AK49+'NL Other_Belgium'!AK55 -> 96225.143 | X15: ='NL Other_Belgium'!AL37+'NL Other_Belgium'!AL49+'NL Other_Belgium'!AL55 -> 85977.905 | Y15: ='NL Other_Belgium'!AM37+'NL Other_Belgium'!AM49+'NL Other_Belgium'!AM55 -> 85977.905 | Z15: ='NL Other_Belgium'!AN37+'NL Other_Belgium'!AN49+'NL Other_Belgium'!AN55 -> 68607.048 | ... AD15: ='NL Other_Belgium'!AR37+'NL Other_Belgium'!AR49+'NL Other_Belgium'!AR55 -> 76730.667 | AF15: ='NL Other_Belgium'!K37+'NL Other_Belgium'!K49 -> 1024723.8 | AG15: 50000 | AH15: =AF15/P15-1 -> 0.069514629 | AJ15: =SUM(S15:AD15)-SUM(AF15:AG15) -> 0 | AL15: ='NL Other_Belgium'!AG37+'NL Other_Belgium'!AG49 -> 71730.667 | AM15: ='NL Other_Belgium'!AH37+'NL Other_Belgium'!AH49 -> 81977.905 | AN15: ='NL Other_Belgium'!AI37+'NL Other_Belgium'!AI49 -> 102472.38 | AO15: ='NL Other_Belgium'!AJ37+'NL Other_Belgium'!AJ49 -> 87101.524 | AP15: ='NL Other_Belgium'!AK37+'NL Other_Belgium'!AK49 -> 92225.143 | AQ15: ='NL Other_Belgium'!AL37+'NL Other_Belgium'!AL49 -> 81977.905 | AR15: ='NL Other_Belgium'!AM37+'NL Other_Belgium'!AM49 -> 81977.905 | AS15: ='NL Other_Belgium'!AN37+'NL Other_Belgium'!AN49 -> 66607.048 | ... AW15: ='NL Other_Belgium'!AR37+'NL Other_Belgium'!AR49 -> 71730.667 | AZ15: =S15-AL15 -> 0 | BA15: =T15-AM15 -> 4000 | BB15: =U15-AN15 -> 4000 | BC15: =V15-AO15 -> 4000 | BD15: =W15-AP15 -> 4000 | BE15: =X15-AQ15 -> 4000 | BF15: =Y15-AR15 -> 4000 | BG15: =Z15-AS15 -> 2000 | ... BK15: =AD15-AW15 -> 5000
B16: NL Other | C16: ='Golden Girls NL'!Z13 -> 10399.47 | D16: ='Golden Girls NL'!Y13 -> 27000 | E16: =IFERROR(C16/D16-1, "N/A") -> -0.61483444 | F16: ='Golden Girls NL'!X13 -> 28533.06 | G16: =IFERROR(C16/F16-1, "N/A") -> -0.6355291 | I16: ='Golden Girls NL'!P13 -> 10399.47 | J16: ='Golden Girls NL'!Q13 -> 19710 | K16: =IFERROR(I16/J16-1, "N/A") -> -0.47237595 | L16: ='Golden Girls NL'!O13 -> 28533.06 | M16: =IFERROR(I16/L16-1, "N/A") -> -0.6355291 | O16: ='Golden Girls NL'!AA13 -> 11000 | P16: =C16 -> 10399.47 | Q16: =IFERROR(O16/P16-1, "N/A") -> 0.057746212 | S16: ='Golden Girls NL'!AG13 -> 770 | T16: ='Golden Girls NL'!AH13 -> 880 | U16: ='Golden Girls NL'!AI13 -> 1100 | V16: ='Golden Girls NL'!AJ13 -> 935 | W16: ='Golden Girls NL'!AK13 -> 990 | X16: ='Golden Girls NL'!AL13 -> 880 | Y16: ='Golden Girls NL'!AM13 -> 880 | Z16: ='Golden Girls NL'!AN13 -> 715 | ... AD16: ='Golden Girls NL'!AR13 -> 770 | AF16: 28000 | AH16: =AF16/P16-1 -> 1.6924449 | AJ16: =SUM(S16:AD16)-SUM(AF16:AG16) -> -17000 | AL16: ='Golden Girls NL'!AG13 -> 770 | AM16: ='Golden Girls NL'!AH13 -> 880 | AN16: ='Golden Girls NL'!AI13 -> 1100 | AO16: ='Golden Girls NL'!AJ13 -> 935 | AP16: ='Golden Girls NL'!AK13 -> 990 | AQ16: ='Golden Girls NL'!AL13 -> 880 | AR16: ='Golden Girls NL'!AM13 -> 880 | AS16: ='Golden Girls NL'!AN13 -> 715 | ... AW16: ='Golden Girls NL'!AR13 -> 770 | AZ16: =S16-AL16 -> 0 | BA16: =T16-AM16 -> 0 | BB16: =U16-AN16 -> 0 | BC16: =V16-AO16 -> 0 | BD16: =W16-AP16 -> 0 | BE16: =X16-AQ16 -> 0 | BF16: =Y16-AR16 -> 0 | BG16: =Z16-AS16 -> 0 | ... BK16: =AD16-AW16 -> 0
AJ17: =SUM(S17:AD17)-SUM(AF17:AG17) -> 0
B18: Benelux | C18: =SUM(C14:C16) -> 1852040.5 | D18: =SUM(D14:D16) -> 2040500 | E18: =IFERROR(C18/D18-1, "N/A") -> -0.092359466 | F18: =SUM(F14:F16) -> 1828205.5 | G18: =IFERROR(C18/F18-1, "N/A") -> 0.013037397 | I18: =SUM(I14:I16) -> 1852040.5 | J18: =SUM(J14:J16) -> 1515190 | K18: =IFERROR(I18/J18-1, "N/A") -> 0.22231569 | L18: =SUM(L14:L16) -> 1828205.5 | M18: =IFERROR(I18/L18-1, "N/A") -> 0.013037397 | O18: =SUM(O14:O16) -> 2089597 | P18: =SUM(P14:P16) -> 1852040.5 | Q18: =IFERROR(O18/P18-1, "N/A") -> 0.12826745 | S18: =SUM(S14:S16) -> 139271.79 | T18: =SUM(T14:T16) -> 167167.76 | U18: =SUM(U14:U16) -> 206959.7 | V18: =SUM(V14:V16) -> 177115.75 | W18: =SUM(W14:W16) -> 187063.73 | X18: =SUM(X14:X16) -> 167167.76 | Y18: =SUM(Y14:Y16) -> 167167.76 | Z18: =SUM(Z14:Z16) -> 133323.81 | ... AD18: =SUM(AD14:AD16) -> 149271.79 | AF18: =SUM(AF14:AF16) -> 2006597 | AG18: =SUM(AG14:AG16) -> 100000 | AH18: =AF18/P18-1 -> 0.083452017 | AJ18: =SUM(S18:AD18)-SUM(AF18:AG18) -> -17000 | AL18: =SUM(AL14:AL16) -> 139271.79 | AM18: =SUM(AM14:AM16) -> 159167.76 | AN18: =SUM(AN14:AN16) -> 198959.7 | AO18: =SUM(AO14:AO16) -> 169115.75 | AP18: =SUM(AP14:AP16) -> 179063.73 | AQ18: =SUM(AQ14:AQ16) -> 159167.76 | AR18: =SUM(AR14:AR16) -> 159167.76 | AS18: =SUM(AS14:AS16) -> 129323.81 | ... AW18: =SUM(AW14:AW16) -> 139271.79 | AZ18: =SUM(AZ14:AZ16) -> 0 | BA18: =SUM(BA14:BA16) -> 8000 | BB18: =SUM(BB14:BB16) -> 8000 | BC18: =SUM(BC14:BC16) -> 8000 | BD18: =SUM(BD14:BD16) -> 8000 | BE18: =SUM(BE14:BE16) -> 8000 | BF18: =SUM(BF14:BF16) -> 8000 | BG18: =SUM(BG14:BG16) -> 4000 | ... BK18: =SUM(BK14:BK16) -> 10000
AJ19: =SUM(S19:AD19)-SUM(AF19:AG19) -> 0
B20: German Switzerland | C20: =C49*1.05 -> 607829.03 | D20: =D49*1.05 -> 786555 | E20: =IFERROR(C20/D20-1, "N/A") -> -0.22722628 | F20: =F49*1.05 -> 698312.76 | G20: =IFERROR(C20/F20-1, "N/A") -> -0.12957479 | I20: =I49*1.05 -> 607829.03 | J20: =J49*1.05 -> 566730.15 | K20: =IFERROR(I20/J20-1, "N/A") -> 0.07251931 | L20: =L49*1.05 -> 698312.76 | M20: =IFERROR(I20/L20-1, "N/A") -> -0.12957479 | O20: =O49*1.05 -> 759528.83 | P20: =C20 -> 607829.03 | Q20: =IFERROR(O20/P20-1, "N/A") -> 0.24957644 | S20: =S49*1.05 -> 49308.268 | T20: =T49*1.05 -> 60552.307 | U20: =U49*1.05 -> 74640.383 | V20: =V49*1.05 -> 65124.326 | W20: =W49*1.05 -> 67596.345 | X20: =X49*1.05 -> 62127.307 | Y20: =Y49*1.05 -> 60552.307 | Z20: =Z49*1.05 -> 47886.249 | ... AD20: =AD49*1.05 -> 54558.268 | AF20: =('Switzerland DE'!K51+'Switzerland DE'!K59)*1.05 -> 704403.83 | AG20: =50000*1.05 -> 52500 | AH20: =AF20/P20-1 -> 0.15888482 | AJ20: =SUM(S20:AD20)-SUM(AF20:AG20) -> 2625 | AL20: =AL49*1.05 -> 49308.268 | AM20: =AM49*1.05 -> 56352.307 | AN20: =AN49*1.05 -> 70440.383 | AO20: =AO49*1.05 -> 59874.326 | AP20: =AP49*1.05 -> 63396.345 | AQ20: =AQ49*1.05 -> 56352.307 | AR20: =AR49*1.05 -> 56352.307 | AS20: =AS49*1.05 -> 45786.249 | ... AW20: =AW49*1.05 -> 49308.268 | AZ20: =S20-AL20 -> 0 | BA20: =T20-AM20 -> 4200 | BB20: =U20-AN20 -> 4200 | BC20: =V20-AO20 -> 5250 | BD20: =W20-AP20 -> 4200 | BE20: =X20-AQ20 -> 5775 | BF20: =Y20-AR20 -> 4200 | BG20: =Z20-AS20 -> 2100 | ... BK20: =AD20-AW20 -> 5250
B21: French Switzerland | C21: =C50*1.05 -> 15500.405 | D21: =D50*1.05 -> 39900 | E21: =IFERROR(C21/D21-1, "N/A") -> -0.61151868 | F21: =F50*1.05 -> 17700.291 | G21: =IFERROR(C21/F21-1, "N/A") -> -0.12428533 | I21: =I50*1.05 -> 15500.405 | J21: =J50*1.05 -> 21672 | K21: =IFERROR(I21/J21-1, "N/A") -> -0.28477277 | L21: =L50*1.05 -> 17700.291 | M21: =IFERROR(I21/L21-1, "N/A") -> -0.12428533 | O21: =O50*1.05 -> 91875 | P21: =C21 -> 15500.405 | Q21: =IFERROR(O21/P21-1, "N/A") -> 4.9272647 | S21: =S50*1.05 -> 2572.5 | T21: =T50*1.05 -> 7140 | U21: =U50*1.05 -> 8925 | V21: =V50*1.05 -> 7323.75 | W21: =W50*1.05 -> 9082.5 | X21: =X50*1.05 -> 7140 | Y21: =Y50*1.05 -> 7140 | Z21: =Z50*1.05 -> 4488.75 | ... AD21: =AD50*1.05 -> 7822.5 | AF21: =('Switzerland FR'!AA8+'Switzerland FR'!AA14)*1.05 -> 36750 | AG21: =50000*1.05 -> 52500 | AH21: =AF21/P21-1 -> 1.3709059 | AJ21: =SUM(S21:AD21)-SUM(AF21:AG21) -> 2625 | AL21: =AL50*1.05 -> 2572.5 | AM21: =AM50*1.05 -> 2940 | AN21: =AN50*1.05 -> 3675 | AO21: =AO50*1.05 -> 3123.75 | AP21: =AP50*1.05 -> 3307.5 | AQ21: =AQ50*1.05 -> 2940 | AR21: =AR50*1.05 -> 2940 | AS21: =AS50*1.05 -> 2388.75 | ... AW21: =AW50*1.05 -> 2572.5 | AZ21: =S21-AL21 -> 0 | BA21: =T21-AM21 -> 4200 | BB21: =U21-AN21 -> 5250 | BC21: =V21-AO21 -> 4200 | BD21: =W21-AP21 -> 5775 | BE21: =X21-AQ21 -> 4200 | BF21: =Y21-AR21 -> 4200 | BG21: =Z21-AS21 -> 2100 | ... BK21: =AD21-AW21 -> 5250
B22: Other Switzerland | C22: =C51*1.05 -> 0 | D22: =D51*1.05 -> 0 | E22: =IFERROR(C22/D22-1, "N/A") -> N/A | F22: =F51*1.05 -> 0 | G22: =IFERROR(C22/F22-1, "N/A") -> N/A | I22: =I51*1.05 -> 0 | J22: =J51*1.05 -> 0 | K22: =IFERROR(I22/J22-1, "N/A") -> N/A | L22: =L51*1.05 -> 0 | M22: =IFERROR(I22/L22-1, "N/A") -> N/A | O22: =O51*1.05 -> 0 | P22: =C22 -> 0 | Q22: =IFERROR(O22/P22-1, "N/A") -> N/A | S22: =S51*1.05 -> 0 | T22: =T51*1.05 -> 0 | U22: =U51*1.05 -> 0 | V22: =V51*1.05 -> 0 | W22: =W51*1.05 -> 0 | X22: =X51*1.05 -> 0 | Y22: =Y51*1.05 -> 0 | Z22: =Z51*1.05 -> 0 | ... AD22: =AD51*1.05 -> 0 | AJ22: =SUM(S22:AD22)-SUM(AF22:AG22) -> 0 | AL22: =AL51*1.05 -> 0 | AM22: =AM51*1.05 -> 0 | AN22: =AN51*1.05 -> 0 | AO22: =AO51*1.05 -> 0 | AP22: =AP51*1.05 -> 0 | AQ22: =AQ51*1.05 -> 0 | AR22: =AR51*1.05 -> 0 | AS22: =AS51*1.05 -> 0 | ... AW22: =AW51*1.05 -> 0 | AZ22: =S22-AL22 -> 0 | BA22: =T22-AM22 -> 0 | BB22: =U22-AN22 -> 0 | BC22: =V22-AO22 -> 0 | BD22: =W22-AP22 -> 0 | BE22: =X22-AQ22 -> 0 | BF22: =Y22-AR22 -> 0 | BG22: =Z22-AS22 -> 0 | ... BK22: =AD22-AW22 -> 0
AJ23: =SUM(S23:AD23)-SUM(AF23:AG23) -> 0
B24: Switzerland | C24: =SUM(C20:C22) -> 623329.43 | D24: =SUM(D20:D22) -> 826455 | E24: =IFERROR(C24/D24-1, "N/A") -> -0.24577934 | F24: =SUM(F20:F22) -> 716013.05 | G24: =IFERROR(C24/F24-1, "N/A") -> -0.12944403 | I24: =SUM(I20:I22) -> 623329.43 | J24: =SUM(J20:J22) -> 588402.15 | K24: =IFERROR(I24/J24-1, "N/A") -> 0.059359545 | L24: =SUM(L20:L22) -> 716013.05 | M24: =IFERROR(I24/L24-1, "N/A") -> -0.12944403 | O24: =SUM(O20:O22) -> 851403.83 | P24: =SUM(P20:P22) -> 623329.43 | Q24: =IFERROR(O24/P24-1, "N/A") -> 0.36589705 | S24: =SUM(S20:S22) -> 51880.768 | T24: =SUM(T20:T22) -> 67692.307 | U24: =SUM(U20:U22) -> 83565.383 | V24: =SUM(V20:V22) -> 72448.076 | W24: =SUM(W20:W22) -> 76678.845 | X24: =SUM(X20:X22) -> 69267.307 | Y24: =SUM(Y20:Y22) -> 67692.307 | Z24: =SUM(Z20:Z22) -> 52374.999 | ... AD24: =SUM(AD20:AD22) -> 62380.768 | AF24: =SUM(AF20:AF22) -> 741153.83 | AG24: =SUM(AG20:AG22) -> 105000 | AH24: =AF24/P24-1 -> 0.18902428 | AJ24: =SUM(S24:AD24)-SUM(AF24:AG24) -> 5250 | AL24: =SUM(AL20:AL22) -> 51880.768 | AM24: =SUM(AM20:AM22) -> 59292.307 | AN24: =SUM(AN20:AN22) -> 74115.383 | AO24: =SUM(AO20:AO22) -> 62998.076 | AP24: =SUM(AP20:AP22) -> 66703.845 | AQ24: =SUM(AQ20:AQ22) -> 59292.307 | AR24: =SUM(AR20:AR22) -> 59292.307 | AS24: =SUM(AS20:AS22) -> 48174.999 | ... AW24: =SUM(AW20:AW22) -> 51880.768 | AZ24: =SUM(AZ20:AZ22) -> 0 | BA24: =SUM(BA20:BA22) -> 8400 | BB24: =SUM(BB20:BB22) -> 9450 | BC24: =SUM(BC20:BC22) -> 9450 | BD24: =SUM(BD20:BD22) -> 9975 | BE24: =SUM(BE20:BE22) -> 9975 | BF24: =SUM(BF20:BF22) -> 8400 | BG24: =SUM(BG20:BG22) -> 4200 | ... BK24: =SUM(BK20:BK22) -> 10500
AJ25: =SUM(S25:AD25)-SUM(AF25:AG25) -> 0
B26: Spain | C26: =Spain!Z14+Spain!Z22+Spain!Z28 -> 132779.43 | D26: =Spain!Y14+Spain!Y22+Spain!Y28 -> 200000 | E26: =IFERROR(C26/D26-1, "N/A") -> -0.33610285 | F26: =Spain!X14+Spain!X22+Spain!X28 -> 87682.84 | G26: =IFERROR(C26/F26-1, "N/A") -> 0.51431489 | I26: =Spain!P14+Spain!P22+Spain!P28 -> 132779.43 | J26: =Spain!Q14+Spain!Q22+Spain!Q28 -> 121150 | K26: =IFERROR(I26/J26-1, "N/A") -> 0.095991993 | L26: =Spain!O14+Spain!O22+Spain!O28 -> 87682.84 | M26: =IFERROR(I26/L26-1, "N/A") -> 0.51431489 | O26: =Spain!AA14+Spain!AA22+Spain!AA28 -> 225000 | P26: =C26 -> 132779.43 | Q26: =IFERROR(O26/P26-1, "N/A") -> 0.69453958 | S26: =Spain!AG14+Spain!AG22+Spain!AG28 -> 12250 | T26: =Spain!AH14+Spain!AH22+Spain!AH28 -> 18000 | U26: =Spain!AI14+Spain!AI22+Spain!AI28 -> 21500 | V26: =Spain!AJ14+Spain!AJ22+Spain!AJ28 -> 18875 | W26: =Spain!AK14+Spain!AK22+Spain!AK28 -> 19750 | X26: =Spain!AL14+Spain!AL22+Spain!AL28 -> 18000 | Y26: =Spain!AM14+Spain!AM22+Spain!AM28 -> 18000 | Z26: =Spain!AN14+Spain!AN22+Spain!AN28 -> 13375 | ... AD26: =Spain!AR14+Spain!AR22+Spain!AR28 -> 17250 | AF26: 225000 | AH26: =AF26/P26-1 -> 0.69453958 | AJ26: =SUM(S26:AD26)-SUM(AF26:AG26) -> 0 | AL26: =Spain!AG14+Spain!AG22 -> 12250 | AM26: =Spain!AH14+Spain!AH22 -> 14000 | AN26: =Spain!AI14+Spain!AI22 -> 17500 | AO26: =Spain!AJ14+Spain!AJ22 -> 14875 | AP26: =Spain!AK14+Spain!AK22 -> 15750 | AQ26: =Spain!AL14+Spain!AL22 -> 14000 | AR26: =Spain!AM14+Spain!AM22 -> 14000 | AS26: =Spain!AN14+Spain!AN22 -> 11375 | ... AW26: =Spain!AR14+Spain!AR22 -> 12250 | AZ26: =S26-AL26 -> 0 | BA26: =T26-AM26 -> 4000 | BB26: =U26-AN26 -> 4000 | BC26: =V26-AO26 -> 4000 | BD26: =W26-AP26 -> 4000 | BE26: =X26-AQ26 -> 4000 | BF26: =Y26-AR26 -> 4000 | BG26: =Z26-AS26 -> 2000 | ... BK26: =AD26-AW26 -> 5000
B27: France North | C27: ='France North'!Z6+'France North'!Z12+'France North'!Z18 -> 15631.42 | D27: ='France North'!Y6+'France North'!Y12+'France North'!Y18 -> 118500 | E27: =IFERROR(C27/D27-1, "N/A") -> -0.86808928 | F27: ='France North'!X6+'France North'!X12+'France North'!X18 -> 7914.88 | G27: =IFERROR(C27/F27-1, "N/A") -> 0.97494087 | I27: ='France North'!P6+'France North'!P12+'France North'!P18 -> 15631.42 | J27: ='France North'!Q6+'France North'!Q12+'France North'!Q18 -> 58105 | K27: =IFERROR(I27/J27-1, "N/A") -> -0.73097978 | L27: ='France North'!O6+'France North'!O12+'France North'!O18 -> 7914.88 | M27: =IFERROR(I27/L27-1, "N/A") -> 0.97494087 | O27: ='France North'!AA6+'France North'!AA12+'France North'!AA18 -> 80000 | P27: =C27 -> 15631.42 | Q27: =IFERROR(O27/P27-1, "N/A") -> 4.1178972 | S27: ='France North'!AG6+'France North'!AG12+'France North'!AG18 -> 1750 | T27: ='France North'!AH6+'France North'!AH12+'France North'!AH18 -> 6000 | U27: ='France North'!AI6+'France North'!AI12+'France North'!AI18 -> 7500 | V27: ='France North'!AJ6+'France North'!AJ12+'France North'!AJ18 -> 7125 | W27: ='France North'!AK6+'France North'!AK12+'France North'!AK18 -> 7250 | X27: ='France North'!AL6+'France North'!AL12+'France North'!AL18 -> 7000 | Y27: ='France North'!AM6+'France North'!AM12+'France North'!AM18 -> 7000 | Z27: ='France North'!AN6+'France North'!AN12+'France North'!AN18 -> 3625 | ... AD27: ='France North'!AR6+'France North'!AR12+'France North'!AR18 -> 6750 | AF27: 80000 | AH27: =AF27/P27-1 -> 4.1178972 | AJ27: =SUM(S27:AD27)-SUM(AF27:AG27) -> 0 | AL27: ='France North'!AG6+'France North'!AG12 -> 1750 | AM27: ='France North'!AH6+'France North'!AH12 -> 2000 | AN27: ='France North'!AI6+'France North'!AI12 -> 2500 | AO27: ='France North'!AJ6+'France North'!AJ12 -> 2125 | AP27: ='France North'!AK6+'France North'!AK12 -> 2250 | AQ27: ='France North'!AL6+'France North'!AL12 -> 2000 | AR27: ='France North'!AM6+'France North'!AM12 -> 2000 | AS27: ='France North'!AN6+'France North'!AN12 -> 1625 | ... AW27: ='France North'!AR6+'France North'!AR12 -> 1750 | AZ27: =S27-AL27 -> 0 | BA27: =T27-AM27 -> 4000 | BB27: =U27-AN27 -> 5000 | BC27: =V27-AO27 -> 5000 | BD27: =W27-AP27 -> 5000 | BE27: =X27-AQ27 -> 5000 | BF27: =Y27-AR27 -> 5000 | BG27: =Z27-AS27 -> 2000 | ... BK27: =AD27-AW27 -> 5000
B28: France South | C28: ='France South'!Z6+'France South'!Z14+'France South'!Z20 -> 32154.93 | D28: ='France South'!Y6+'France South'!Y14+'France South'!Y20 -> 132500 | E28: =IFERROR(C28/D28-1, "N/A") -> -0.75732128 | F28: ='France South'!X6+'France South'!X14+'France South'!X20 -> 25118.66 | G28: =IFERROR(C28/F28-1, "N/A") -> 0.28012123 | I28: ='France South'!P6+'France South'!P14+'France South'!P20 -> 32154.93 | J28: ='France South'!Q6+'France South'!Q14+'France South'!Q20 -> 68325 | K28: =IFERROR(I28/J28-1, "N/A") -> -0.52938266 | L28: ='France South'!O6+'France South'!O14+'France South'!O20 -> 25118.66 | M28: =IFERROR(I28/L28-1, "N/A") -> 0.28012123 | O28: ='France South'!AA6+'France South'!AA14+'France South'!AA20 -> 110000 | P28: =C28 -> 32154.93 | Q28: =IFERROR(O28/P28-1, "N/A") -> 2.4209373 | S28: ='France South'!AG6+'France South'!AG14+'France South'!AG20 -> 3500 | T28: ='France South'!AH6+'France South'!AH14+'France South'!AH20 -> 8000 | U28: ='France South'!AI6+'France South'!AI14+'France South'!AI20 -> 9000 | V28: ='France South'!AJ6+'France South'!AJ14+'France South'!AJ20 -> 8250 | W28: ='France South'!AK6+'France South'!AK14+'France South'!AK20 -> 11500 | X28: ='France South'!AL6+'France South'!AL14+'France South'!AL20 -> 11000 | Y28: ='France South'!AM6+'France South'!AM14+'France South'!AM20 -> 8000 | Z28: ='France South'!AN6+'France South'!AN14+'France South'!AN20 -> 5250 | ... AD28: ='France South'!AR6+'France South'!AR14+'France South'!AR20 -> 8500 | AF28: 100000 | AH28: =AF28/P28-1 -> 2.109943 | AJ28: =SUM(S28:AD28)-SUM(AF28:AG28) -> 10000 | AL28: ='France South'!AG6+'France South'!AG14 -> 3500 | AM28: ='France South'!AH6+'France South'!AH14 -> 4000 | AN28: ='France South'!AI6+'France South'!AI14 -> 5000 | AO28: ='France South'!AJ6+'France South'!AJ14 -> 4250 | AP28: ='France South'!AK6+'France South'!AK14 -> 4500 | AQ28: ='France South'!AL6+'France South'!AL14 -> 4000 | AR28: ='France South'!AM6+'France South'!AM14 -> 4000 | AS28: ='France South'!AN6+'France South'!AN14 -> 3250 | ... AW28: ='France South'!AR6+'France South'!AR14 -> 3500 | AZ28: =S28-AL28 -> 0 | BA28: =T28-AM28 -> 4000 | BB28: =U28-AN28 -> 4000 | BC28: =V28-AO28 -> 4000 | BD28: =W28-AP28 -> 7000 | BE28: =X28-AQ28 -> 7000 | BF28: =Y28-AR28 -> 4000 | BG28: =Z28-AS28 -> 2000 | ... BK28: =AD28-AW28 -> 5000
B29: Italy | C29: =SUM(Italy!Z5+Italy!Z11+Italy!Z17) -> 8199.18 | D29: =SUM(Italy!Y5+Italy!Y11+Italy!Y17) -> 0 | E29: =IFERROR(C29/D29-1, "N/A") -> N/A | F29: =SUM(Italy!X5+Italy!X11+Italy!X17) -> 0 | G29: =IFERROR(C29/F29-1, "N/A") -> N/A | I29: =SUM(Italy!P5+Italy!P11+Italy!P17) -> 8199.18 | J29: =SUM(Italy!Q5+Italy!Q11+Italy!Q17) -> 0 | K29: =IFERROR(I29/J29-1, "N/A") -> N/A | L29: =SUM(Italy!O5+Italy!O11+Italy!O17) -> 0 | M29: =IFERROR(I29/L29-1, "N/A") -> N/A | O29: =SUM(Italy!AA5+Italy!AA11+Italy!AA17) -> 75000 | P29: =C29 -> 8199.18 | Q29: =IFERROR(O29/P29-1, "N/A") -> 8.1472562 | S29: =SUM(Italy!AG5+Italy!AG11+Italy!AG17) -> 1050 | T29: =SUM(Italy!AH5+Italy!AH11+Italy!AH17) -> 5200 | U29: =SUM(Italy!AI5+Italy!AI11+Italy!AI17) -> 5500 | V29: =SUM(Italy!AJ5+Italy!AJ11+Italy!AJ17) -> 5275 | W29: =SUM(Italy!AK5+Italy!AK11+Italy!AK17) -> 10350 | X29: =SUM(Italy!AL5+Italy!AL11+Italy!AL17) -> 8200 | Y29: =SUM(Italy!AM5+Italy!AM11+Italy!AM17) -> 5200 | Z29: =SUM(Italy!AN5+Italy!AN11+Italy!AN17) -> 2975 | ... AD29: =SUM(Italy!AR5+Italy!AR11+Italy!AR17) -> 6050 | AF29: 75000 | AH29: =AF29/P29-1 -> 8.1472562 | AJ29: =SUM(S29:AD29)-SUM(AF29:AG29) -> 0 | AL29: =SUM(Italy!AG5+Italy!AG11) -> 1050 | AM29: =SUM(Italy!AH5+Italy!AH11) -> 1200 | AN29: =SUM(Italy!AI5+Italy!AI11) -> 1500 | AO29: =SUM(Italy!AJ5+Italy!AJ11) -> 1275 | AP29: =SUM(Italy!AK5+Italy!AK11) -> 1350 | AQ29: =SUM(Italy!AL5+Italy!AL11) -> 1200 | AR29: =SUM(Italy!AM5+Italy!AM11) -> 1200 | AS29: =SUM(Italy!AN5+Italy!AN11) -> 975 | ... AW29: =SUM(Italy!AR5+Italy!AR11) -> 1050 | AZ29: =S29-AL29 -> 0 | BA29: =T29-AM29 -> 4000 | BB29: =U29-AN29 -> 4000 | BC29: =V29-AO29 -> 4000 | BD29: =W29-AP29 -> 9000 | BE29: =X29-AQ29 -> 7000 | BF29: =Y29-AR29 -> 4000 | BG29: =Z29-AS29 -> 2000 | ... BK29: =AD29-AW29 -> 5000
AJ30: =SUM(S30:AD30)-SUM(AF30:AG30) -> 0
B31: Other EU | C31: =SUM(C26:C29) -> 188764.96 | D31: =SUM(D26:D29) -> 451000 | E31: =IFERROR(C31/D31-1, "N/A") -> -0.58145242 | F31: =SUM(F26:F29) -> 120716.38 | G31: =IFERROR(C31/F31-1, "N/A") -> 0.56370627 | I31: =SUM(I26:I29) -> 188764.96 | J31: =SUM(J26:J29) -> 247580 | K31: =IFERROR(I31/J31-1, "N/A") -> -0.23755974 | L31: =SUM(L26:L29) -> 120716.38 | M31: =IFERROR(I31/L31-1, "N/A") -> 0.56370627 | O31: =SUM(O26:O29) -> 490000 | P31: =SUM(P26:P29) -> 188764.96 | Q31: =IFERROR(O31/P31-1, "N/A") -> 1.5958207 | S31: =SUM(S26:S29) -> 18550 | T31: =SUM(T26:T29) -> 37200 | U31: =SUM(U26:U29) -> 43500 | V31: =SUM(V26:V29) -> 39525 | W31: =SUM(W26:W29) -> 48850 | X31: =SUM(X26:X29) -> 44200 | Y31: =SUM(Y26:Y29) -> 38200 | Z31: =SUM(Z26:Z29) -> 25225 | ... AD31: =SUM(AD26:AD29) -> 38550 | AF31: =SUM(AF26:AF29) -> 480000 | AG31: =SUM(AG26:AG29) -> 0 | AH31: =AF31/P31-1 -> 1.5428448 | AJ31: =SUM(S31:AD31)-SUM(AF31:AG31) -> 10000 | AL31: =SUM(AL26:AL29) -> 18550 | AM31: =SUM(AM26:AM29) -> 21200 | AN31: =SUM(AN26:AN29) -> 26500 | AO31: =SUM(AO26:AO29) -> 22525 | AP31: =SUM(AP26:AP29) -> 23850 | AQ31: =SUM(AQ26:AQ29) -> 21200 | AR31: =SUM(AR26:AR29) -> 21200 | AS31: =SUM(AS26:AS29) -> 17225 | ... AW31: =SUM(AW26:AW29) -> 18550 | AZ31: =SUM(AZ26:AZ29) -> 0 | BA31: =SUM(BA26:BA29) -> 16000 | BB31: =SUM(BB26:BB29) -> 17000 | BC31: =SUM(BC26:BC29) -> 17000 | BD31: =SUM(BD26:BD29) -> 25000 | BE31: =SUM(BE26:BE29) -> 23000 | BF31: =SUM(BF26:BF29) -> 17000 | BG31: =SUM(BG26:BG29) -> 8000 | ... BK31: =SUM(BK26:BK29) -> 20000
AF33: =SUM(AF31,AF24,AF18,AF12) -> 7824517.7 | AG33: =SUM(AG31,AG24,AG18,AG12) -> 520000
AF35: =SUM(AF33+AG33) -> 8344517.7
B36: Elena Summary
B37: EUR | C37: Full Year | I37: YTD | O37: Full Year
C38: 25A | D38: 25B | E38: 25F vs 25B | F38: 24A | G38: 25F vs 24A | I38: 25A | J38: 25B | K38: 25A vs 25B | L38: 24A | M38: 25A vs 24A | O38: 26B | P38: 25A | Q38: 26B vs 25F | S38: 46023 | T38: 46054 | U38: 46082 | V38: 46113 | W38: 46143 | X38: 46174 | Y38: 46204 | Z38: 46235 | AA38: 46266 | AB38: 46296 | AC38: 46327 | AD38: 46357 | AL38: 46023 | AM38: 46054 | AN38: 46082 | AO38: 46113 | AP38: 46143 | AQ38: 46174 | AR38: 46204 | AS38: 46235 | AT38: 46266 | AU38: 46296 | AV38: 46327 | AW38: 46357 | AZ38: 46023 | BA38: 46054 | BB38: 46082 | BC38: 46113 | BD38: 46143 | BE38: 46174 | BF38: 46204 | BG38: 46235 | BH38: 46266 | BI38: 46296 | BJ38: 46327 | BK38: 46357
B39: French Switzerland | C39: =C21 -> 15500.405 | D39: =D21 -> 39900 | E39: -1 | F39: =F21 -> 17700.291 | G39: -1 | I39: =I21 -> 15500.405 | J39: =J21 -> 21672 | K39: -0.62502539 | L39: =L21 -> 17700.291 | M39: -0.44078643 | O39: =O21 -> 91875 | P39: =P21 -> 15500.405 | Q39: N/A | S39: =S21 -> 2572.5 | T39: =T21 -> 7140 | U39: =U21 -> 8925 | V39: =V21 -> 7323.75 | W39: =W21 -> 9082.5 | X39: =X21 -> 7140 | Y39: =Y21 -> 7140 | Z39: =Z21 -> 4488.75 | ... AD39: =AD21 -> 7822.5 | AL39: =AL21 -> 2572.5 | AM39: =AM21 -> 2940 | AN39: =AN21 -> 3675 | AO39: =AO21 -> 3123.75 | AP39: =AP21 -> 3307.5 | AQ39: =AQ21 -> 2940 | AR39: =AR21 -> 2940 | AS39: =AS21 -> 2388.75 | ... AW39: =AW21 -> 2572.5 | AZ39: =AZ21 -> 0 | BA39: =BA21 -> 4200 | BB39: =BB21 -> 5250 | BC39: =BC21 -> 4200 | BD39: =BD21 -> 5775 | BE39: =BE21 -> 4200 | BF39: =BF21 -> 4200 | BG39: =BG21 -> 2100 | ... BK39: =BK21 -> 5250
B40: France North | C40: =C27 -> 15631.42 | D40: =D27 -> 118500 | E40: -1 | F40: =F27 -> 7914.88 | G40: -1 | I40: =I27 -> 15631.42 | J40: =J27 -> 58105 | K40: -0.93630434 | L40: =L27 -> 7914.88 | M40: -0.32964246 | O40: =O27 -> 80000 | P40: =P27 -> 15631.42 | Q40: N/A | S40: =S27 -> 1750 | T40: =T27 -> 6000 | U40: =U27 -> 7500 | V40: =V27 -> 7125 | W40: =W27 -> 7250 | X40: =X27 -> 7000 | Y40: =Y27 -> 7000 | Z40: =Z27 -> 3625 | ... AD40: =AD27 -> 6750 | AL40: =AL27 -> 1750 | AM40: =AM27 -> 2000 | AN40: =AN27 -> 2500 | AO40: =AO27 -> 2125 | AP40: =AP27 -> 2250 | AQ40: =AQ27 -> 2000 | AR40: =AR27 -> 2000 | AS40: =AS27 -> 1625 | ... AW40: =AW27 -> 1750 | AZ40: =AZ27 -> 0 | BA40: =BA27 -> 4000 | BB40: =BB27 -> 5000 | BC40: =BC27 -> 5000 | BD40: =BD27 -> 5000 | BE40: =BE27 -> 5000 | BF40: =BF27 -> 5000 | BG40: =BG27 -> 2000 | ... BK40: =BK27 -> 5000
B41: Italy | C41: =C29 -> 8199.18 | D41: =D29 -> 0 | E41: -1 | F41: =F29 -> 0 | G41: -1 | I41: =I29 -> 8199.18 | J41: =J29 -> 0 | K41: -0.93630434 | L41: =L29 -> 0 | M41: -0.32964246 | O41: =O29 -> 75000 | P41: =P29 -> 8199.18 | Q41: N/A | S41: =S29 -> 1050 | T41: =T29 -> 5200 | U41: =U29 -> 5500 | V41: =V29 -> 5275 | W41: =W29 -> 10350 | X41: =X29 -> 8200 | Y41: =Y29 -> 5200 | Z41: =Z29 -> 2975 | ... AD41: =AD29 -> 6050 | AL41: =AL29 -> 1050 | AM41: =AM29 -> 1200 | AN41: =AN29 -> 1500 | AO41: =AO29 -> 1275 | AP41: =AP29 -> 1350 | AQ41: =AQ29 -> 1200 | AR41: =AR29 -> 1200 | AS41: =AS29 -> 975 | ... AW41: =AW29 -> 1050 | AZ41: =AZ29 -> 0 | BA41: =BA29 -> 4000 | BB41: =BB29 -> 4000 | BC41: =BC29 -> 4000 | BD41: =BD29 -> 9000 | BE41: =BE29 -> 7000 | BF41: =BF29 -> 4000 | BG41: =BG29 -> 2000 | ... BK41: =BK29 -> 5000
B42: Total Elena | C42: =SUM(C39:C41) -> 39331.005 | D42: =SUM(D39:D41) -> 158400 | E42: -1 | F42: =SUM(F39:F41) -> 25615.171 | G42: -1 | I42: =SUM(I39:I41) -> 39331.005 | J42: =SUM(J39:J41) -> 79777 | K42: -0.93630434 | L42: =SUM(L39:L41) -> 25615.171 | M42: -0.32964246 | O42: =SUM(O39:O41) -> 246875 | P42: =SUM(P39:P41) -> 39331.005 | Q42: N/A | S42: =SUM(S39:S41) -> 5372.5 | T42: =SUM(T39:T41) -> 18340 | U42: =SUM(U39:U41) -> 21925 | V42: =SUM(V39:V41) -> 19723.75 | W42: =SUM(W39:W41) -> 26682.5 | X42: =SUM(X39:X41) -> 22340 | Y42: =SUM(Y39:Y41) -> 19340 | Z42: =SUM(Z39:Z41) -> 11088.75 | ... AD42: =SUM(AD39:AD41) -> 20622.5 | AL42: =SUM(AL39:AL41) -> 5372.5 | AM42: =SUM(AM39:AM41) -> 6140 | AN42: =SUM(AN39:AN41) -> 7675 | AO42: =SUM(AO39:AO41) -> 6523.75 | AP42: =SUM(AP39:AP41) -> 6907.5 | AQ42: =SUM(AQ39:AQ41) -> 6140 | AR42: =SUM(AR39:AR41) -> 6140 | AS42: =SUM(AS39:AS41) -> 4988.75 | ... AW42: =SUM(AW39:AW41) -> 5372.5 | AZ42: =SUM(AZ39:AZ41) -> 0 | BA42: =SUM(BA39:BA41) -> 12200 | BB42: =SUM(BB39:BB41) -> 14250 | BC42: =SUM(BC39:BC41) -> 13200 | BD42: =SUM(BD39:BD41) -> 19775 | BE42: =SUM(BE39:BE41) -> 16200 | BF42: =SUM(BF39:BF41) -> 13200 | BG42: =SUM(BG39:BG41) -> 6100 | ... BK42: =SUM(BK39:BK41) -> 15250
B46: These numbers below are in Swiss Francs, to be used for actual commission calculations for the Team
...

Sheet Region review
C1: 2025
C2: Old region | D2: New region | F2: Commission earned | G2: Commission % | I2: "Lost" sales | J2: Commission % used | K2: Lost Commission | L2: Monthly uplift | N2: Commission under old scheme | O2: Commission under new scheme | P2: Benefit of new scheme on 2025 sales
B3: Kerstin | C3: 721212.06 | D3: =Summary!C4 -> 602834.42 | F3: 19711.32 | G3: =F3/C3 -> 0.027330824 | I3: =C3-D3 -> 118377.64 | J3: 0.03 | K3: =I3*J3 -> 3551.3292 | L3: =MROUND(K3/12, 100) -> 300 | N3: =F3 -> 19711.32 | O3: =SUM(D23:O23,D31:O31,Q31) -> 27498.357 | P3: =O3-N3 -> 7787.0367
B4: Ara | C4: 719983.41 | D4: =Summary!C5 -> 375419.11 | F4: 28357.29 | G4: =F4/C4 -> 0.039386033 | I4: =C4-D4 -> 344564.3 | J4: 0.04 | K4: =I4*J4 -> 13782.572 | L4: =MROUND(K4/12, 100) -> 1100 | N4: =F4 -> 28357.29 | O4: =SUM(D46:O46,D54:O54,Q54) -> 38024.733 | P4: =O4-N4 -> 9667.443
B17: Kerstin:
B18: 2025 | D18: 45658 | E18: 45689 | F18: 45717 | G18: 45748 | H18: 45778 | I18: 45809 | J18: 45839 | K18: 45870 | L18: 45901 | M18: 45931 | N18: 45962 | O18: 45992
B19: Existing sales | D19: =D33-D27 -> 47163.19 | E19: =E33-E27 -> 38296.67 | F19: =F33-F27 -> 52596.8 | G19: =G33-G27 -> 61308.56 | H19: =H33-H27 -> 61413.83 | I19: =I33-I27 -> 39368.89 | J19: =J33-J27 -> 66298.71 | K19: =K33-K27 -> 59196.87 | ... O19: =O33-O27 -> 49560.6
B20: Existing budget | D20: =D34-D28 -> 51005.5 | E20: =E34-E28 -> 62776 | F20: =F34-F28 -> 82393.5 | G20: =G34-G28 -> 70623 | H20: =H34-H28 -> 70623 | I20: =I34-I28 -> 62776 | J20: =J34-J28 -> 62776 | K20: =K34-K28 -> 39235 | ... O20: =O34-O28 -> 54929
B21: % achieved | D21: =D19/D20 -> 0.92466871 | E21: =E19/E20 -> 0.61005273 | F21: =F19/F20 -> 0.63836104 | G21: =G19/G20 -> 0.86811039 | H21: =H19/H20 -> 0.86960098 | I21: =I19/I20 -> 0.62713282 | J21: =J19/J20 -> 1.0561156 | K21: =K19/K20 -> 1.5087771 | ... O21: =O19/O20 -> 0.90226656
B22: Commission % applied | D22: =IF(D21<0.9, 0, IF(D21<1, 0.03, IF(D21>1, "Multiple"))) -> 0.03 | E22: =IF(E21<0.9, 0, IF(E21<1, 0.03, IF(E21>1, "Multiple"))) -> 0 | F22: =IF(F21<0.9, 0, IF(F21<1, 0.03, IF(F21>1, "Multiple"))) -> 0 | G22: =IF(G21<0.9, 0, IF(G21<1, 0.03, IF(G21>1, "Multiple"))) -> 0 | H22: =IF(H21<0.9, 0, IF(H21<1, 0.03, IF(H21>1, "Multiple"))) -> 0 | I22: =IF(I21<0.9, 0, IF(I21<1, 0.03, IF(I21>1, "Multiple"))) -> 0 | J22: =IF(J21<0.9, 0, IF(J21<1, 0.03, IF(J21>1, "Multiple"))) -> Multiple | K22: =IF(K21<0.9, 0, IF(K21<1, 0.03, IF(K21>1, "Multiple"))) -> Multiple | ... O22: =IF(O21<0.9, 0, IF(O21<1, 0.03, IF(O21>1, "Multiple"))) -> 0.03
B23: Commission | D23: =IF(D22="Multiple", D20*6%+(D19-D20)*10%, D19*D22) -> 1414.8957 | E23: =IF(E22="Multiple", E20*6%+(E19-E20)*10%, E19*E22) -> 0 | F23: =IF(F22="Multiple", F20*6%+(F19-F20)*10%, F19*F22) -> 0 | G23: =IF(G22="Multiple", G20*6%+(G19-G20)*10%, G19*G22) -> 0 | H23: =IF(H22="Multiple", H20*6%+(H19-H20)*10%, H19*H22) -> 0 | I23: =IF(I22="Multiple", I20*6%+(I19-I20)*10%, I19*I22) -> 0 | J23: =IF(J22="Multiple", J20*6%+(J19-J20)*10%, J19*J22) -> 4118.831 | K23: =IF(K22="Multiple", K20*6%+(K19-K20)*10%, K19*K22) -> 4350.287 | ... O23: =IF(O22="Multiple", O20*6%+(O19-O20)*10%, O19*O22) -> 1486.818
B25: New door sales (first 3 months) | D25: 0 | E25: 0 | F25: 0 | G25: 0 | H25: 11459.17 | I25: 0 | J25: 13774.14 | K25: 0 | L25: 0 | M25: 0 | N25: 0 | O25: 0 | Q25: Full year check
B26: New door sales (reorder) | D26: 0 | E26: 0 | F26: 0 | G26: 0 | H26: 0 | I26: 0 | J26: 0 | K26: 0 | L26: 13576.99 | M26: 10724.19 | N26: -27.73 | O26: 0
B27: Total new door sales | D27: 0 | E27: 0 | F27: 0 | G27: 0 | H27: 11459.17 | I27: 0 | J27: 13774.14 | K27: 0 | L27: 13576.99 | M27: 10724.19 | N27: -27.73 | O27: 0 | Q27: =SUM(D27:O27) -> 49506.76
B28: New door budget | D28: 0 | E28: 750 | F28: 1500 | G28: 1500 | H28: 2250 | I28: 2250 | J28: 3000 | K28: 2250 | L28: 4500 | M28: 4500 | N28: 4500 | O28: 3000 | Q28: =SUM(D28:O28) -> 30000
B29: % achieved | D29: =IFERROR(D27/D28, 0) -> 0 | E29: =IFERROR(E27/E28, 0) -> 0 | F29: =IFERROR(F27/F28, 0) -> 0 | G29: =IFERROR(G27/G28, 0) -> 0 | H29: =IFERROR(H27/H28, 0) -> 5.0929644 | I29: =IFERROR(I27/I28, 0) -> 0 | J29: =IFERROR(J27/J28, 0) -> 4.59138 | K29: =IFERROR(K27/K28, 0) -> 0 | ... O29: =IFERROR(O27/O28, 0) -> 0 | Q29: =IFERROR(Q27/Q28, 0) -> 1.6502253
B30: Commission % applied | D30: =IF(D29<0.8, 0, IF(D29<0.9, 5%, 10%)) -> 0 | E30: =IF(E29<0.8, 0, IF(E29<0.9, 5%, 10%)) -> 0 | F30: =IF(F29<0.8, 0, IF(F29<0.9, 5%, 10%)) -> 0 | G30: =IF(G29<0.8, 0, IF(G29<0.9, 5%, 10%)) -> 0 | H30: =IF(H29<0.8, 0, IF(H29<0.9, 5%, 10%)) -> 0.1 | I30: =IF(I29<0.8, 0, IF(I29<0.9, 5%, 10%)) -> 0 | J30: =IF(J29<0.8, 0, IF(J29<0.9, 5%, 10%)) -> 0.1 | K30: =IF(K29<0.8, 0, IF(K29<0.9, 5%, 10%)) -> 0 | ... O30: =IF(O29<0.8, 0, IF(O29<0.9, 5%, 10%)) -> 0 | Q30: N/A
B31: Commission | D31: =D25*10%+D30*D26 -> 0 | E31: =E25*10%+E30*E26 -> 0 | F31: =F25*10%+F30*F26 -> 0 | G31: =G25*10%+G30*G26 -> 0 | H31: =H25*10%+H30*H26 -> 1145.917 | I31: =I25*10%+I30*I26 -> 0 | J31: =J25*10%+J30*J26 -> 1377.414 | K31: =K25*10%+K30*K26 -> 0 | ... O31: =O25*10%+O30*O26 -> 0 | Q31: =IF(Q29>1, 5000, 0) -> 5000
B33: Total Sales | D33: 47163.19 | E33: 38296.67 | F33: 52596.8 | G33: 61308.56 | H33: 72873 | I33: 39368.89 | J33: 80072.85 | K33: 59196.87 | L33: 66780.44 | M33: 64031.96 | N33: 89962.23 | O33: 49560.6
B34: Total Budget | D34: 51005.5 | E34: 63526 | F34: 83893.5 | G34: 72123 | H34: 72873 | I34: 65026 | J34: 65776 | K34: 41485 | L34: 75123 | M34: 90817 | N34: 75123 | O34: 57929
B40: Ara:
B41: 2025 | D41: 45658 | E41: 45689 | F41: 45717 | G41: 45748 | H41: 45778 | I41: 45809 | J41: 45839 | K41: 45870 | L41: 45901 | M41: 45931 | N41: 45962 | O41: 45992
B42: Existing sales | D42: =D56-D48 -> 40604.13 | E42: =E56-E48 -> 45367.29 | F42: =F56-F48 -> 52810.52 | G42: =G56-G48 -> 81802.45 | H42: =H56-H48 -> 67677.67 | I42: =I56-I48 -> 20634.6 | J42: =J56-J48 -> 64676.87 | K42: =K56-K48 -> 40795.76 | ... O42: =O56-O48 -> 64703.47
B43: Existing budget | D43: =D57-D51 -> 47710 | E43: =E57-E51 -> 58720 | F43: =F57-F51 -> 77070 | G43: =G57-G51 -> 66060 | H43: =H57-H51 -> 66060 | I43: =I57-I51 -> 58720 | J43: =J57-J51 -> 58720 | K43: =K57-K51 -> 36700 | ... O43: =O57-O51 -> 51380
B44: % achieved | D44: =D42/D43 -> 0.8510612 | E44: =E42/E43 -> 0.77260371 | F44: =F42/F43 -> 0.68522797 | G44: =G42/G43 -> 1.2383053 | H44: =H42/H43 -> 1.0244879 | I44: =I42/I43 -> 0.35140668 | J44: =J42/J43 -> 1.1014453 | K44: =K42/K43 -> 1.1116011 | ... O44: =O42/O43 -> 1.2593124
B45: Commission % applied | D45: =IF(D44<0.9, 0, IF(D44<1, 0.03, IF(D44>1, "Multiple"))) -> 0 | E45: =IF(E44<0.9, 0, IF(E44<1, 0.03, IF(E44>1, "Multiple"))) -> 0 | F45: =IF(F44<0.9, 0, IF(F44<1, 0.03, IF(F44>1, "Multiple"))) -> 0 | G45: =IF(G44<0.9, 0, IF(G44<1, 0.03, IF(G44>1, "Multiple"))) -> Multiple | H45: =IF(H44<0.9, 0, IF(H44<1, 0.03, IF(H44>1, "Multiple"))) -> Multiple | I45: =IF(I44<0.9, 0, IF(I44<1, 0.03, IF(I44>1, "Multiple"))) -> 0 | J45: =IF(J44<0.9, 0, IF(J44<1, 0.03, IF(J44>1, "Multiple"))) -> Multiple | K45: =IF(K44<0.9, 0, IF(K44<1, 0.03, IF(K44>1, "Multiple"))) -> Multiple | ... O45: =IF(O44<0.9, 0, IF(O44<1, 0.03, IF(O44>1, "Multiple"))) -> Multiple
B46: Commission | D46: =IF(D45="Multiple", D43*6%+(D42-D43)*10%, D42*D45) -> 0 | E46: =IF(E45="Multiple", E43*6%+(E42-E43)*10%, E42*E45) -> 0 | F46: =IF(F45="Multiple", F43*6%+(F42-F43)*10%, F42*F45) -> 0 | G46: =IF(G45="Multiple", G43*6%+(G42-G43)*10%, G42*G45) -> 5537.845 | H46: =IF(H45="Multiple", H43*6%+(H42-H43)*10%, H42*H45) -> 4125.367 | I46: =IF(I45="Multiple", I43*6%+(I42-I43)*10%, I42*I45) -> 0 | J46: =IF(J45="Multiple", J43*6%+(J42-J43)*10%, J42*J45) -> 4118.887 | K46: =IF(K45="Multiple", K43*6%+(K42-K43)*10%, K42*K45) -> 2611.576 | ... O46: =IF(O45="Multiple", O43*6%+(O42-O43)*10%, O42*O45) -> 4415.147
B48: New door sales (first 3 months) | D48: 11352.24 | E48: 690.25 | F48: 561.63 | G48: 0 | H48: 0 | I48: 5372.19 | J48: 4407.18 | K48: 0 | L48: 985.15 | M48: 1453.72 | N48: 0 | O48: 0 | Q48: Full year check
B49: New door sales (reorder) | D49: =D50-D48 -> 0 | E49: =E50-E48 -> 0 | F49: =F50-F48 -> 0 | G49: =G50-G48 -> 0 | H49: =H50-H48 -> 0 | I49: =I50-I48 -> 0 | J49: =J50-J48 -> 0 | K49: =K50-K48 -> 1770.87 | ... O49: =O50-O48 -> 2444.34
B50: Total new door sales | D50: 11352.24 | E50: 690.25 | F50: 561.63 | G50: 0 | H50: 0 | I50: 5372.19 | J50: 4407.18 | K50: 1770.87 | L50: 2083.3 | M50: 1865.24 | N50: 5835.91 | O50: 2444.34 | Q50: =SUM(D50:O50) -> 36383.15
B51: New door budget | D51: 0 | E51: 750 | F51: 1500 | G51: 1500 | H51: 2250 | I51: 2250 | J51: 3000 | K51: 2250 | L51: 4500 | M51: 4500 | N51: 4500 | O51: 3000 | Q51: =SUM(D51:O51) -> 30000
B52: % achieved | D52: =IFERROR(D50/D51, 0) -> 0 | E52: =IFERROR(E50/E51, 0) -> 0.92033333 | F52: =IFERROR(F50/F51, 0) -> 0.37442 | G52: =IFERROR(G50/G51, 0) -> 0 | H52: =IFERROR(H50/H51, 0) -> 0 | I52: =IFERROR(I50/I51, 0) -> 2.38764 | J52: =IFERROR(J50/J51, 0) -> 1.46906 | K52: =IFERROR(K50/K51, 0) -> 0.78705333 | ... O52: =IFERROR(O50/O51, 0) -> 0.81478 | Q52: =IFERROR(Q50/Q51, 0) -> 1.2127717
B53: Commission % applied | D53: =IF(D52<0.8, 0, IF(D52<0.9, 5%, 10%)) -> 0 | E53: =IF(E52<0.8, 0, IF(E52<0.9, 5%, 10%)) -> 0.1 | F53: =IF(F52<0.8, 0, IF(F52<0.9, 5%, 10%)) -> 0 | G53: =IF(G52<0.8, 0, IF(G52<0.9, 5%, 10%)) -> 0 | H53: =IF(H52<0.8, 0, IF(H52<0.9, 5%, 10%)) -> 0 | I53: =IF(I52<0.8, 0, IF(I52<0.9, 5%, 10%)) -> 0.1 | J53: =IF(J52<0.8, 0, IF(J52<0.9, 5%, 10%)) -> 0.1 | K53: =IF(K52<0.8, 0, IF(K52<0.9, 5%, 10%)) -> 0 | ... O53: =IF(O52<0.8, 0, IF(O52<0.9, 5%, 10%)) -> 0.05 | Q53: N/A
B54: Commission | D54: =D48*10%+D53*D49 -> 1135.224 | E54: =E48*10%+E53*E49 -> 69.025 | F54: =F48*10%+F53*F49 -> 56.163 | G54: =G48*10%+G53*G49 -> 0 | H54: =H48*10%+H53*H49 -> 0 | I54: =I48*10%+I53*I49 -> 537.219 | J54: =J48*10%+J53*J49 -> 440.718 | K54: =K48*10%+K53*K49 -> 0 | ... O54: =O48*10%+O53*O49 -> 122.217 | Q54: =IF(Q52>1, 5000, 0) -> 5000
B56: Total Sales | D56: 51956.37 | E56: 46057.54 | F56: 53372.15 | G56: 81802.45 | H56: 67677.67 | I56: 26006.79 | J56: 69084.05 | K56: 40795.76 | L56: 48596.55 | M56: 83213.45 | N56: 67238.94 | O56: 64703.47
B57: Total Budget | D57: 47710 | E57: 59470 | F57: 78570 | G57: 67560 | H57: 68310 | I57: 60970 | J57: 61720 | K57: 38950 | L57: 70560 | M57: 85240 | N57: 70560 | O57: 54380

Sheet NRW Marina
O1: Year to date | P1: Year to date | Q1: Year to date | S1: Year to date | T1: Year to date | V1: Full year | W1: Full year | X1: Full year | Y1: Full year | Z1: Full year | AA1: Full year | AC1: Full year | AD1: Full year | AE1: Full year | AG1: 0.07 | AH1: 0.08 | AI1: 0.1 | AJ1: 0.085 | AK1: 0.09 | AL1: 0.08 | AM1: 0.08 | AN1: 0.065 | AO1: 0.095 | AP1: 0.1 | AQ1: 0.085 | AR1: 0.07
B2: Customer Code | C2: Customer Name | D2: Country | E2: Region | F2: Customer Map | G2: New door year | H2: Active? | I2: 2025 Cluster | J2: 2025A | K2: 2026B | L2: Size indicator | M2: Customer Growth Class | O2: 2024 YTD | P2: 2025 YTD | Q2: 2025B YTD | S2: 25 vs 24 % | T2: 25 vs 25B % | V2: 2022 | W2: 2023 | X2: 2024 | Y2: 2025B | Z2: 2025A | AA2: 2026B | AC2: 25 vs 24 % | AD2: 25 vs 25B % | AE2: 26B vs 25F % | AG2: 46023 | AH2: 46054 | AI2: 46082 | AJ2: 46113 | AK2: 46143 | AL2: 46174 | AM2: 46204 | AN2: 46235 | AO2: 46266 | AP2: 46296 | AQ2: 46327 | AR2: 46357
A3: Marina | B3: 20018 | C3: Susanne Gollmer | D3: =VLOOKUP($B3, 'Performance Data'!$B:$K, 3, 0) -> Germany | E3: =VLOOKUP($B3, 'Performance Data'!$B:$K, 4, 0) -> NRW | F3: =VLOOKUP($B3, 'Performance Data'!$B:$K, 6, 0) -> Institutes / Clinic | G3: =VLOOKUP($B3, 'Performance Data'!$B:$K, 10, 0) -> Pre-2022 | H3: Yes | I3: =VLOOKUP($B3, 'Performance Data'!$B:$K, 7, 0) -> AA | J3: =P3 -> 45228.2 | K3: =J3*1.07-500 -> 47894.174 | M3: Grow | O3: =SUMIF('Performance Data'!$B:$B, $B3,'Performance Data'!N:N) -> 33166.95 | P3: =SUMIF('Performance Data'!$B:$B, $B3,'Performance Data'!O:O) -> 45228.2 | Q3: =SUMIF('Performance Data'!$B:$B, $B3,'Performance Data'!P:P) -> 25550 | S3: =$P3/O3-1 -> 0.36365267 | T3: =P3/Q3-1 -> 0.77018395 | V3: =SUMIF('Performance Data'!$B:$B, $B3,'Performance Data'!AC:AC) -> 34150.32 | W3: =SUMIF('Performance Data'!$B:$B, $B3,'Performance Data'!AD:AD) -> 37681.89 | X3: =SUMIF('Performance Data'!$B:$B, $B3,'Performance Data'!AE:AE) -> 33166.95 | Y3: =SUMIF('Performance Data'!$B:$B, $B3,'Performance Data'!AG:AG) -> 35000 | Z3: =P3 -> 45228.2 | AA3: =K3 -> 47894.174 | AC3: =Z3/X3-1 -> 0.36365267 | AD3: =Z3/Y3-1 -> 0.29223429 | AE3: =AA3/Z3-1 -> 0.05894495 | AG3: =$AA3*AG$1 -> 3352.5922 | AH3: =$AA3*AH$1 -> 3831.5339 | AI3: =$AA3*AI$1 -> 4789.4174 | AJ3: =$AA3*AJ$1 -> 4071.0048 | AK3: =$AA3*AK$1 -> 4310.4757 | AL3: =$AA3*AL$1 -> 3831.5339 | AM3: =$AA3*AM$1 -> 3831.5339 | AN3: =$AA3*AN$1 -> 3113.1213 | ... AR3: =$AA3*AR$1 -> 3352.5922
B4: 20395 | C4: Top Parfümerie Manegold | D4: =VLOOKUP($B4, 'Performance Data'!$B:$K, 3, 0) -> Germany | E4: =VLOOKUP($B4, 'Performance Data'!$B:$K, 4, 0) -> NRW | F4: =VLOOKUP($B4, 'Performance Data'!$B:$K, 6, 0) -> Institutes / Clinic | G4: =VLOOKUP($B4, 'Performance Data'!$B:$K, 10, 0) -> Pre-2022 | H4: Yes | I4: =VLOOKUP($B4, 'Performance Data'!$B:$K, 7, 0) -> AA | J4: =P4 -> 38545.42 | K4: =J4*1.07-500 -> 40743.599 | M4: Grow | O4: =SUMIF('Performance Data'!$B:$B, $B4,'Performance Data'!N:N) -> 24902.71 | P4: =SUMIF('Performance Data'!$B:$B, $B4,'Performance Data'!O:O) -> 38545.42 | Q4: =SUMIF('Performance Data'!$B:$B, $B4,'Performance Data'!P:P) -> 19345 | S4: =$P4/O4-1 -> 0.54784038 | T4: =P4/Q4-1 -> 0.99252623 | V4: =SUMIF('Performance Data'!$B:$B, $B4,'Performance Data'!AC:AC) -> 20225.52 | W4: =SUMIF('Performance Data'!$B:$B, $B4,'Performance Data'!AD:AD) -> 22701.68 | X4: =SUMIF('Performance Data'!$B:$B, $B4,'Performance Data'!AE:AE) -> 24902.71 | Y4: =SUMIF('Performance Data'!$B:$B, $B4,'Performance Data'!AG:AG) -> 26500 | Z4: =P4 -> 38545.42 | AA4: =K4 -> 40743.599 | AC4: =Z4/X4-1 -> 0.54784038 | AD4: =Z4/Y4-1 -> 0.45454415 | AE4: =AA4/Z4-1 -> 0.05702829 | AG4: =$AA4*AG$1 -> 2852.052 | AH4: =$AA4*AH$1 -> 3259.488 | AI4: =$AA4*AI$1 -> 4074.3599 | AJ4: =$AA4*AJ$1 -> 3463.2059 | AK4: =$AA4*AK$1 -> 3666.9239 | AL4: =$AA4*AL$1 -> 3259.488 | AM4: =$AA4*AM$1 -> 3259.488 | AN4: =$AA4*AN$1 -> 2648.334 | ... AR4: =$AA4*AR$1 -> 2852.052
B5: 20519 | C5: Besime Celik | D5: =VLOOKUP($B5, 'Performance Data'!$B:$K, 3, 0) -> Germany | E5: =VLOOKUP($B5, 'Performance Data'!$B:$K, 4, 0) -> NRW | F5: =VLOOKUP($B5, 'Performance Data'!$B:$K, 6, 0) -> 0 | G5: =VLOOKUP($B5, 'Performance Data'!$B:$K, 10, 0) -> Pre-2022 | H5: Yes | I5: =VLOOKUP($B5, 'Performance Data'!$B:$K, 7, 0) -> AA | J5: =P5 -> 19654.56 | K5: =J5*1.07-500 -> 20530.379 | M5: Maintain | O5: =SUMIF('Performance Data'!$B:$B, $B5,'Performance Data'!N:N) -> 20150.65 | P5: =SUMIF('Performance Data'!$B:$B, $B5,'Performance Data'!O:O) -> 19654.56 | Q5: =SUMIF('Performance Data'!$B:$B, $B5,'Performance Data'!P:P) -> 17520 | S5: =$P5/O5-1 -> -0.024619057 | T5: =P5/Q5-1 -> 0.12183562 | V5: =SUMIF('Performance Data'!$B:$B, $B5,'Performance Data'!AC:AC) -> 10659.14 | W5: =SUMIF('Performance Data'!$B:$B, $B5,'Performance Data'!AD:AD) -> 14136.59 | X5: =SUMIF('Performance Data'!$B:$B, $B5,'Performance Data'!AE:AE) -> 20150.65 | Y5: =SUMIF('Performance Data'!$B:$B, $B5,'Performance Data'!AG:AG) -> 24000 | Z5: =P5 -> 19654.56 | AA5: =K5 -> 20530.379 | AC5: =Z5/X5-1 -> -0.024619057 | AD5: =Z5/Y5-1 -> -0.18106 | AE5: =AA5/Z5-1 -> 0.044560611 | AG5: =$AA5*AG$1 -> 1437.1265 | AH5: =$AA5*AH$1 -> 1642.4303 | AI5: =$AA5*AI$1 -> 2053.0379 | AJ5: =$AA5*AJ$1 -> 1745.0822 | AK5: =$AA5*AK$1 -> 1847.7341 | AL5: =$AA5*AL$1 -> 1642.4303 | AM5: =$AA5*AM$1 -> 1642.4303 | AN5: =$AA5*AN$1 -> 1334.4746 | ... AR5: =$AA5*AR$1 -> 1437.1265
