Workbook

Sheet Trackers >>

Sheet Initiative Log - Detailed
B1: Date: | C1: =TODAY() -> 46044 | D1: =MONTH(C1)&RIGHT(YEAR(C1), 2) -> 126
B3: Initiative | C3: Description | D3: Segment | E3: Responsible Director | F3: Responsible Consultant | G3: 2026B Sales Incremental (kEUR) | H3: 2028B Sales Incremental (kEUR) | I3: 2028 Potential Sales (kEUR) | J3: 2026B EBITDA (kEUR) | K3: 2028B EBITDA (kEUR) | L3: 2028 Potential EBITDA (kEUR) | M3: Upfront Cost (Cost prior to revenue) | N3: Size of the prize | O3: Impact on Business Valuation | P3: Level of QMS Control / Influence | Q3: Mgmt Action | R3: Start Date | S3: Review Date | T3: Current status | U3: Updates since last reporting | V3: Key activities until next reporting | W3: Expected long-term developments | X3: Notes | Y3: Sales Planned to date (kEUR) | Z3: Sales achieved to date (kEUR) | AA3: Costs planned to date (kEUR) | AB3: Costs incurred to date (kEUR) | AC3: Costs committed to date (kEUR)
B4: 1.1 Core Market Visibility | C4: Attend more Trade Shows | D4: Core Markets | E4: Giovanni Russo | F4: N/A | G4: ='Initiatives Summary'!$C45*2/3 -> 179.72605 | H4: ='Initiatives Summary'!$AQ45*50% -> 560.63216 | I4: ='1.1 Core Markets Visibility'!$E7*40% -> 640.72247 | J4: =G4*'1.1 Core Markets Visibility'!$K$17+'1.1 Core Markets Visibility'!K20+'1.1 Core Markets Visibility'!K26+'1.1 Core Markets Visibility'!K25 -> -0.9890255 | K4: =H4*'1.1 Core Markets Visibility'!$M$17+'1.1 Core Markets Visibility'!M20+'1.1 Core Markets Visibility'!M26+'1.1 Core Markets Visibility'!M25 -> 194.58878 | L4: =I4*'1.1 Core Markets Visibility'!$E$17+'1.1 Core Markets Visibility'!E20+'1.1 Core Markets Visibility'!E26+'1.1 Core Markets Visibility'!E25 -> 211.8082 | M4: ='1.1 Core Markets Visibility'!K20 -> -120 | N4: =IF(OR(I4>1000,L4>500),"High",IF(OR(I4>500,L4>250),"Medium","Low")) -> Medium | O4: Low | P4: High | Q4: Proceed | R4: 46023 | S4: =R4+6*30 -> 46203 | T4: Not yet started | Y4: =INDEX('1.1 Core Markets Visibility'!$AG$6:$AT$15, 1, MATCH( $D$1, '1.1 Core Markets Visibility'!$AG$4:$AT$4, 0)) -> 0 | AA4: =INDEX('1.1 Core Markets Visibility'!$AG$6:$AT$15, 9, MATCH( $D$1, '1.1 Core Markets Visibility'!$AG$4:$AT$4, 0)) -> 0
C5: Specific PR and Merchandising Support | D5: Core Markets | E5: Giovanni Russo | F5: N/A | G5: ='Initiatives Summary'!$C45*1/3 -> 89.863025 | H5: ='Initiatives Summary'!$AQ45*50% -> 560.63216 | I5: ='1.1 Core Markets Visibility'!$E7*60% -> 961.08371 | J5: ='Initiatives Summary'!$C68-J4 -> -467.41506 | K5: ='Initiatives Summary'!$AQ68-K4 -> -199.99379 | L5: ='1.1 Core Markets Visibility'!E28-L4 -> 126.37422 | M5: ='Initiatives Summary'!$C77-M4 -> -325.74 | N5: =IF(OR(I5>1000,L5>500),"High",IF(OR(I5>500,L5>250),"Medium","Low")) -> Medium | O5: Low | P5: Medium | Q5: Proceed | R5: 46023 | S5: =R5+6*30 -> 46203 | T5: Not yet started | U5: Committed to Platinum Sponsorship at SpaInside (€6k) | W5: SpaInside event planned for Jun-26 | Y5: =INDEX('1.1 Core Markets Visibility'!$AG$6:$AT$15, 2, MATCH( $D$1, '1.1 Core Markets Visibility'!$AG$4:$AT$4, 0)) -> 0 | AA5: =INDEX('1.1 Core Markets Visibility'!$AG$6:$AT$15, 10, MATCH( $D$1, '1.1 Core Markets Visibility'!$AG$4:$AT$4, 0)) -> 0 | AC5: 6
B6: 1.2 Core Markets Team | C6: Additional Team Members (+2 FTE) | D6: Core Markets | E6: Giovanni Russo | F6: N/A | G6: ='Initiatives Summary'!$D45 -> 84 | H6: ='Initiatives Summary'!$AR45 -> 644 | I6: ='1.2 Core Markets Team expansion'!$E7 -> 920 | J6: ='Initiatives Summary'!$D68 -> -72.84 | K6: ='Initiatives Summary'!$AR68 -> 293.26 | L6: ='1.2 Core Markets Team expansion'!$E28 -> 490.6 | M6: ='Initiatives Summary'!$D77 -> -71.7 | N6: =IF(OR(I6>1000,L6>500),"High",IF(OR(I6>500,L6>250),"Medium","Low")) -> Medium | O6: Medium | P6: High | Q6: Proceed | R6: 46113 | S6: =R6+6*30 -> 46293 | T6: Not yet started | Y6: =INDEX('1.2 Core Markets Team expansion'!$AH$7:$AU$11, 1, MATCH($D$1, '1.2 Core Markets Team expansion'!$AH$4:$AU$4, 0)) -> 0 | AA6: =INDEX('1.2 Core Markets Team expansion'!$AH$7:$AU$11, 5, MATCH($D$1, '1.2 Core Markets Team expansion'!$AH$4:$AU$4, 0)) -> 0
B7: 2.1 Mark Wuttke | C7: Spa Chains - Tosca | D7: USA B2B | E7: Melissa Blamey | F7: Mark Wuttke | G7: ='2.1 Mark Wuttke Contact Book'!C46*20% -> 200 | H7: ='2.1 Mark Wuttke Contact Book'!E46*20% -> 400 | I7: ='2.1 Mark Wuttke Contact Book'!E46 -> 2000 | J7: =G7*'2.1 Mark Wuttke Contact Book'!K$29 -> 101.28397 | K7: =H7*'2.1 Mark Wuttke Contact Book'!M$29 -> 217.09177 | L7: =I7*'2.1 Mark Wuttke Contact Book'!E$29 -> 1181.1174 | M7: ='Initiatives Summary'!$E77 -> -95.121506 | N7: =IF(OR(I7>1000,L7>500),"High",IF(OR(I7>500,L7>250),"Medium","Low")) -> High | O7: High | P7: Low | Q7: Performance Review | R7: 45839 | S7: 46174 | T7: Under Review | Y7: =INDEX('2.1 Mark Wuttke Contact Book'!$AH$6:$AU$21,1,MATCH($D$1,'2.1 Mark Wuttke Contact Book'!$AH$4:$AU$4,0)) -> 0 | AA7: =INDEX('2.1 Mark Wuttke Contact Book'!$AH$6:$AU$21,16,MATCH($D$1,'2.1 Mark Wuttke Contact Book'!$AH$4:$AU$4,0)) -> 43
C8: Spa Chains - Woodhouse | D8: USA B2B | E8: Melissa Blamey | F8: Mark Wuttke | G8: ='2.1 Mark Wuttke Contact Book'!C47*40% -> 600 | H8: ='2.1 Mark Wuttke Contact Book'!E47*36%+30 -> 2370 | I8: ='2.1 Mark Wuttke Contact Book'!E47 -> 6500 | J8: =G8*'2.1 Mark Wuttke Contact Book'!K$29 -> 303.85191 | K8: =H8*'2.1 Mark Wuttke Contact Book'!M$29 -> 1286.2687 | L8: =I8*'2.1 Mark Wuttke Contact Book'!E$29 -> 3838.6315 | N8: =IF(OR(I8>1000,L8>500),"High",IF(OR(I8>500,L8>250),"Medium","Low")) -> High | O8: High | P8: Low | Q8: Monitor | R8: 45839 | S8: 46082 | T8: Ongoing | Y8: =INDEX('2.1 Mark Wuttke Contact Book'!$AH$6:$AU$21,2,MATCH($D$1,'2.1 Mark Wuttke Contact Book'!$AH$4:$AU$4,0)) -> 0
C9: Spa Chains - Trilogy | D9: USA B2B | E9: Melissa Blamey | F9: Mark Wuttke | G9: ='2.1 Mark Wuttke Contact Book'!C48*40% -> 400 | H9: ='2.1 Mark Wuttke Contact Book'!E48*40% -> 800 | I9: ='2.1 Mark Wuttke Contact Book'!E48 -> 2000 | J9: =G9*'2.1 Mark Wuttke Contact Book'!K$29 -> 202.56794 | K9: =H9*'2.1 Mark Wuttke Contact Book'!M$29 -> 434.18353 | L9: =I9*'2.1 Mark Wuttke Contact Book'!E$29 -> 1181.1174 | N9: =IF(OR(I9>1000,L9>500),"High",IF(OR(I9>500,L9>250),"Medium","Low")) -> High | O9: High | P9: Low | Q9: Monitor | R9: 45839 | S9: 46082 | T9: Ongoing | Y9: =INDEX('2.1 Mark Wuttke Contact Book'!$AH$6:$AU$21,3,MATCH($D$1,'2.1 Mark Wuttke Contact Book'!$AH$4:$AU$4,0)) -> 0
C10: Spa Chains - Other | D10: USA B2B | E10: Melissa Blamey | F10: Mark Wuttke | G10: ='2.1 Mark Wuttke Contact Book'!C49*20% -> 100 | H10: ='2.1 Mark Wuttke Contact Book'!E49*20% -> 200 | I10: ='2.1 Mark Wuttke Contact Book'!E49 -> 1000 | J10: =G10*'2.1 Mark Wuttke Contact Book'!K$29 -> 50.641985 | K10: =H10*'2.1 Mark Wuttke Contact Book'!M$29 -> 108.54588 | L10: =I10*'2.1 Mark Wuttke Contact Book'!E$29 -> 590.5587 | N10: =IF(OR(I10>1000,L10>500),"High",IF(OR(I10>500,L10>250),"Medium","Low")) -> High | O10: Medium | P10: Low | Q10: Monitor | R10: 45839 | S10: 46082 | T10: Initiated | Y10: =INDEX('2.1 Mark Wuttke Contact Book'!$AH$6:$AU$21,4,MATCH($D$1,'2.1 Mark Wuttke Contact Book'!$AH$4:$AU$4,0)) -> 0
C11: Key Account Openings | D11: USA B2B | E11: Melissa Blamey | F11: Mark Wuttke | G11: ='2.1 Mark Wuttke Contact Book'!C51*30*(1+'2.1 Mark Wuttke Contact Book'!$H$7) -> 19.8 | H11: =('2.1 Mark Wuttke Contact Book'!E51*30+'2.1 Mark Wuttke Contact Book'!D51*50+'2.1 Mark Wuttke Contact Book'!C51*55)*(1+'2.1 Mark Wuttke Contact Book'!$H$7) -> 89.1 | I11: =('2.1 Mark Wuttke Contact Book'!E51*30+'2.1 Mark Wuttke Contact Book'!D51*50+'2.1 Mark Wuttke Contact Book'!C51*55) -> 270 | J11: =G11*'2.1 Mark Wuttke Contact Book'!K$29 -> 10.027113 | K11: =H11*'2.1 Mark Wuttke Contact Book'!M$29 -> 48.357191 | L11: =I11*'2.1 Mark Wuttke Contact Book'!E$29 -> 159.45085 | N11: =IF(OR(I11>1000,L11>500),"High",IF(OR(I11>500,L11>250),"Medium","Low")) -> Low | O11: Medium | P11: Medium | Q11: Monitor | R11: 45839 | S11: 46082 | T11: Initiated | Y11: =INDEX('2.1 Mark Wuttke Contact Book'!$AH$6:$AU$21,5,MATCH($D$1,'2.1 Mark Wuttke Contact Book'!$AH$4:$AU$4,0)) -> 0
C12: Team Improvements / Coaching | D12: USA B2B | E12: Melissa Blamey | F12: Mark Wuttke | G12: ='2.1 Mark Wuttke Contact Book'!K7-SUM('Initiative Log - Detailed'!G7:G11) -> 29.734096 | H12: ='2.1 Mark Wuttke Contact Book'!M7-SUM('Initiative Log - Detailed'!H7:H11) -> 40.185189 | I12: ='2.1 Mark Wuttke Contact Book'!E7-SUM(I7:I11) -> 46.015726 | J12: =G12*'2.1 Mark Wuttke Contact Book'!K$29 -> 15.057936 | K12: =H12*'2.1 Mark Wuttke Contact Book'!M$29 -> 21.809684 | L12: =I12*'2.1 Mark Wuttke Contact Book'!E$29 -> 27.174987 | N12: =IF(OR(I12>1000,L12>500),"High",IF(OR(I12>500,L12>250),"Medium","Low")) -> Low | O12: Low | P12: High | Q12: Monitor | R12: 45839 | S12: 46082 | T12: Ongoing | Y12: =INDEX('2.1 Mark Wuttke Contact Book'!$AH$6:$AU$21,6,MATCH($D$1,'2.1 Mark Wuttke Contact Book'!$AH$4:$AU$4,0)) -> 0
B13: 2.2 Jaime Castle | C13: Med Spas | D13: USA B2B | E13: Melissa Blamey | F13: Jaime Castle | G13: ='2.2 Jaime Contact Book'!C46*(1+'2.2 Jaime Contact Book'!$H$7) -> 510 | H13: ='2.2 Jaime Contact Book'!E46*(1+'2.2 Jaime Contact Book'!$H$7) -> 900 | I13: ='2.2 Jaime Contact Book'!E46 -> 1500 | J13: =G13*'2.2 Jaime Contact Book'!K$29 -> 244.78748 | K13: =H13*'2.2 Jaime Contact Book'!M$29 -> 467.91785 | L13: =I13*'2.2 Jaime Contact Book'!E$29 -> 814.36442 | M13: ='Initiatives Summary'!$F77 -> -166.79623 | N13: =IF(OR(I13>1000,L13>500),"High",IF(OR(I13>500,L13>250),"Medium","Low")) -> High | O13: High | P13: Medium | Q13: Monitor | R13: 45839 | S13: 46082 | T13: Ongoing | Y13: =INDEX('2.2 Jaime Contact Book'!$AH$6:$AU$20, 1, MATCH($D$1, '2.2 Jaime Contact Book'!$AH$4:$AU$4, 0)) -> 0 | AA13: =INDEX('2.2 Jaime Contact Book'!$AH$6:$AU$20, 15, MATCH($D$1, '2.2 Jaime Contact Book'!$AH$4:$AU$4, 0)) -> 24
C14: Extended Salesforce (1099er / MeyerSpa) | D14: USA B2B | E14: Melissa Blamey | F14: Jaime Castle | G14: ='2.2 Jaime Contact Book'!C47*(1+'2.2 Jaime Contact Book'!$H$7) -> 300 | H14: ='2.2 Jaime Contact Book'!E47*(1+'2.2 Jaime Contact Book'!$H$7) -> 1200 | I14: ='2.2 Jaime Contact Book'!E47 -> 2000 | J14: =G14*'2.2 Jaime Contact Book'!K$29 -> 143.99263 | K14: =H14*'2.2 Jaime Contact Book'!M$29 -> 623.89046 | L14: =I14*'2.2 Jaime Contact Book'!E$29 -> 1085.8192 | N14: =IF(OR(I14>1000,L14>500),"High",IF(OR(I14>500,L14>250),"Medium","Low")) -> High | O14: High | P14: Medium | Q14: Monitor | R14: 45839 | S14: 46082 | T14: Ongoing | Y14: =INDEX('2.2 Jaime Contact Book'!$AH$6:$AU$20, 2, MATCH($D$1, '2.2 Jaime Contact Book'!$AH$4:$AU$4, 0)) -> 0
C15: Cruise Ships | D15: USA B2B | E15: Melissa Blamey | F15: Jaime Castle | G15: ='2.2 Jaime Contact Book'!C48*(1+'2.2 Jaime Contact Book'!$H$7) -> 3 | H15: ='2.2 Jaime Contact Book'!E48*(1+'2.2 Jaime Contact Book'!$H$7) -> 450 | I15: ='2.2 Jaime Contact Book'!E48 -> 750 | J15: =G15*'2.2 Jaime Contact Book'!K$29 -> 1.4399263 | K15: =H15*'2.2 Jaime Contact Book'!M$29 -> 233.95892 | L15: =I15*'2.2 Jaime Contact Book'!E$29 -> 407.18221 | N15: =IF(OR(I15>1000,L15>500),"High",IF(OR(I15>500,L15>250),"Medium","Low")) -> Medium | O15: Medium | P15: Low | Q15: Monitor | R15: 45839 | S15: 46266 | T15: Initiated | Y15: =INDEX('2.2 Jaime Contact Book'!$AH$6:$AU$20, 3, MATCH($D$1, '2.2 Jaime Contact Book'!$AH$4:$AU$4, 0)) -> 0
C16: Retail | D16: USA B2B | E16: Melissa Blamey | F16: Jaime Castle | G16: ='2.2 Jaime Contact Book'!C49*(1+'2.2 Jaime Contact Book'!$H$7) -> 30 | H16: ='2.2 Jaime Contact Book'!E49*(1+'2.2 Jaime Contact Book'!$H$7) -> 210 | I16: ='2.2 Jaime Contact Book'!E49 -> 350 | J16: =G16*'2.2 Jaime Contact Book'!K$29 -> 14.399263 | K16: =H16*'2.2 Jaime Contact Book'!M$29 -> 109.18083 | L16: =I16*'2.2 Jaime Contact Book'!E$29 -> 190.01837 | N16: =IF(OR(I16>1000,L16>500),"High",IF(OR(I16>500,L16>250),"Medium","Low")) -> Low | O16: Medium | P16: Low | Q16: Monitor | R16: 45839 | S16: 46266 | T16: Initiated | Y16: =INDEX('2.2 Jaime Contact Book'!$AH$6:$AU$20, 4, MATCH($D$1, '2.2 Jaime Contact Book'!$AH$4:$AU$4, 0)) -> 0
C17: Medical Claims / Storytelling | D17: USA B2B | E17: Melissa Blamey | F17: Jaime Castle | G17: ='2.2 Jaime Contact Book'!K7-SUM(G13:G16) -> 8.849178 | H17: ='2.2 Jaime Contact Book'!M7-SUM(H13:H16) -> 13.804718 | I17: ='2.2 Jaime Contact Book'!E7-SUM(I13:I16) -> 23.007863 | J17: =G17*'2.2 Jaime Contact Book'!K$29 -> 4.2473881 | K17: =H17*'2.2 Jaime Contact Book'!M$29 -> 7.1771931 | L17: =I17*'2.2 Jaime Contact Book'!E$29 -> 12.49119 | N17: =IF(OR(I17>1000,L17>500),"High",IF(OR(I17>500,L17>250),"Medium","Low")) -> Low | O17: Medium | P17: High | Q17: Monitor | R17: 45839 | S17: 46082 | T17: Ongoing | Y17: =INDEX('2.2 Jaime Contact Book'!$AH$6:$AU$20, 5, MATCH($D$1, '2.2 Jaime Contact Book'!$AH$4:$AU$4, 0)) -> 0
B18: 2.3 US visibility | C18: Trade Show Sponsorship | D18: USA B2B | E18: Melissa Blamey | F18: N/A | G18: ='Initiatives Summary'!$G45*2/3 -> 60.432055 | H18: ='Initiatives Summary'!$AU45*50% -> 313.6055 | I18: ='2.3 US Visibility'!$E7*40% -> 358.40629 | J18: =G18*'2.3 US Visibility'!K$17+'2.3 US Visibility'!K20 -> -32.862997 | K18: =H18*'2.3 US Visibility'!M$17+'2.3 US Visibility'!M20 -> 149.38032 | L18: =I18*'2.3 US Visibility'!E$17+'2.3 US Visibility'!E20 -> 184.54894 | M18: ='2.3 US Visibility'!K20 -> -80 | N18: =IF(OR(I18>1000,L18>500),"High",IF(OR(I18>500,L18>250),"Medium","Low")) -> Low | O18: Medium | P18: High | Q18: Proceed | R18: 46023 | S18: =R18+6*30 -> 46203 | T18: Not yet started
C19: Specific PR and Merchandising Support | D19: USA B2B | E19: Melissa Blamey | F19: N/A | G19: ='Initiatives Summary'!$G45*1/3 -> 30.216027 | H19: ='Initiatives Summary'!$AU45*50% -> 313.6055 | I19: ='2.3 US Visibility'!$E7*60% -> 537.60944 | J19: ='2.3 US Visibility'!K28-J18 -> -117.99631 | K19: ='2.3 US Visibility'!M28-K18 -> 24.18422 | L19: ='2.3 US Visibility'!E28-L18 -> 173.14683 | M19: ='2.3 US Visibility'!K37-M18 -> -76.5 | N19: =IF(OR(I19>1000,L19>500),"High",IF(OR(I19>500,L19>250),"Medium","Low")) -> Medium | O19: Medium | P19: Medium | Q19: Proceed | R19: 46023 | S19: 46203 | T19: Not yet started
B20: 2.4 US Team | C20: Additional Team Members (+2 FTE) | D20: USA B2B | E20: Melissa Blamey | F20: N/A | G20: ='Initiatives Summary'!$H45 -> 84 | H20: ='Initiatives Summary'!$AV45 -> 644 | I20: ='2.4 US Team Expansion'!$E7 -> 920 | J20: ='Initiatives Summary'!$H68 -> -157.88 | K20: ='Initiatives Summary'!$AV68 -> 177.14 | L20: ='2.4 US Team Expansion'!$E28 -> 366.2 | M20: ='Initiatives Summary'!$H77 -> -111.7 | N20: =IF(OR(I20>1000,L20>500),"High",IF(OR(I20>500,L20>250),"Medium","Low")) -> Medium | O20: Medium | P20: High | Q20: Proceed | R20: 46113 | S20: =R20+6*30 -> 46293 | T20: Not yet started
B21: 3.1 China | C21: Investment opportunity e.g. KOL EU event | D21: China | E21: Suzanna Uden | F21: N/A | G21: ='Initiatives Summary'!$I45 -> 125 | H21: ='Initiatives Summary'!$AW45 -> 250 | I21: ='3.1 China'!$E7 -> 500 | J21: ='Initiatives Summary'!$I68 -> -33.75 | K21: ='Initiatives Summary'!$AW68 -> 33.75 | L21: ='3.1 China'!$E28 -> 192.5 | M21: ='Initiatives Summary'!$I77 -> -100 | N21: =IF(OR(I21>1000,L21>500),"High",IF(OR(I21>500,L21>250),"Medium","Low")) -> Low | O21: Medium | P21: Low | Q21: Proceed | R21: TBC | S21: TBC | T21: Not yet started
B22: 3.2 Lane Crawford | C22: Lane Crawford dept store HK opening | D22: China | E22: Clare Morgan | F22: N/A | G22: ='Initiatives Summary'!$J45 -> 50 | H22: ='Initiatives Summary'!$AX45 -> 150 | I22: ='3.2 Lane Crawford'!$E7 -> 300 | J22: ='Initiatives Summary'!$J68 -> -23.5 | K22: ='Initiatives Summary'!$AX68 -> 10.25 | L22: ='3.2 Lane Crawford'!$E28 -> 105.5 | M22: ='Initiatives Summary'!$J77 -> -30 | N22: =IF(OR(I22>1000,L22>500),"High",IF(OR(I22>500,L22>250),"Medium","Low")) -> Low | O22: Medium | P22: Medium | Q22: Monitor | R22: 45931 | S22: 46082 | T22: Initiated
B23: 4.1 Nadim Hammoud | C23: Middle East MedSpa / Clinic support | D23: Middle East | E23: Rainer Anskinewitsch | F23: Nadim Hammoud | G23: ='Initiatives Summary'!$K45 -> 35 | H23: ='Initiatives Summary'!$AY45 -> 166.25 | I23: ='4.1 Nadim ME'!$E7 -> 237.5 | J23: ='Initiatives Summary'!$K68 -> 22.4 | K23: ='Initiatives Summary'!$AY68 -> 107.23125 | L23: ='4.1 Nadim ME'!$E28 -> 153.1875 | M23: ='Initiatives Summary'!$K77 -> -15 | N23: =IF(OR(I23>1000,L23>500),"High",IF(OR(I23>500,L23>250),"Medium","Low")) -> Low | O23: Medium | P23: Low | Q23: Monitor | R23: 45839 | S23: 46082 | T23: Cancelled
B24: 4.2 ME Retail | C24: Investment opportunity e.g. Retail Lounge budget | D24: Middle East | E24: Rainer Anskinewitsch | F24: N/A | G24: ='Initiatives Summary'!$L45 -> 50 | H24: ='Initiatives Summary'!$AZ45 -> 125 | I24: ='4.2 ME Retail'!$E7 -> 250 | J24: ='Initiatives Summary'!$L68 -> -18 | K24: ='Initiatives Summary'!$AZ68 -> 30.625 | L24: ='4.2 ME Retail'!$E28 -> 111.25 | M24: ='Initiatives Summary'!$L77 -> 0 | N24: =IF(OR(I24>1000,L24>500),"High",IF(OR(I24>500,L24>250),"Medium","Low")) -> Low | O24: Medium | P24: Low | Q24: Proceed | R24: TBC | S24: TBC | T24: Not yet started
B25: 5.1 Mingo Ku | C25: New APAC distributors | D25: APAC | E25: Suzanna Uden | F25: Mingo Ku | G25: ='Initiatives Summary'!$M45 -> 37.5 | H25: ='Initiatives Summary'!$BA45 -> 75 | I25: ='5.1 Mingo'!$E7 -> 300 | J25: ='Initiatives Summary'!$M68 -> 25.125 | K25: ='Initiatives Summary'!$BA68 -> 50.625 | L25: ='5.1 Mingo'!$E28 -> 202.5 | M25: ='Initiatives Summary'!$M77 -> 0 | N25: =IF(OR(I25>1000,L25>500),"High",IF(OR(I25>500,L25>250),"Medium","Low")) -> Low | O25: Medium | P25: Low | Q25: Monitor | R25: 45839 | S25: 46174 | T25: Ongoing
B26: 5.2 Juan Albanell | C26: New APAC distributors (Malaysia, Singapore, Taiwan) | D26: APAC | E26: Suzanna Uden | F26: Juan Albanell | G26: ='5.2 Juan'!C46*(1+'5.2 Juan'!$H$7) -> 100 | H26: ='5.2 Juan'!E46*(1+'5.2 Juan'!$H$7) -> 200 | I26: ='5.2 Juan'!E46 -> 2000 | J26: =G26*'5.2 Juan'!K$29 -> 57.916667 | K26: =H26*'5.2 Juan'!M$29 -> 119.25153 | L26: =I26*'5.2 Juan'!E$29 -> 1302.9448 | M26: ='Initiatives Summary'!$N77 -> -33 | N26: =IF(OR(I26>1000,L26>500),"High",IF(OR(I26>500,L26>250),"Medium","Low")) -> High | O26: Medium | P26: Low | Q26: Complete | R26: 46023 | S26: 46082 | T26: Cancelled
C27: China sub-distributor support | D27: China | E27: Suzanna Uden | F27: Juan Albanell | G27: =('5.2 Juan'!K7-G26)*50% -> 10 | H27: =('5.2 Juan'!M7-H26)*50% -> 63 | I27: =('5.2 Juan'!E7-I26)*50% -> 630 | J27: =G27*'5.2 Juan'!K$29 -> 5.7916667 | K27: =H27*'5.2 Juan'!M$29 -> 37.564233 | L27: =I27*'5.2 Juan'!E$29 -> 410.42761 | N27: =IF(OR(I27>1000,L27>500),"High",IF(OR(I27>500,L27>250),"Medium","Low")) -> Medium | O27: Medium | P27: Low | Q27: Complete | R27: 46023 | S27: 46082 | T27: Cancelled
C28: Middle East sub-distributor support | D28: Middle East | E28: Rainer Anskinewitsch | F28: Juan Albanell | G28: =('5.2 Juan'!K7-G26)*50% -> 10 | H28: =('5.2 Juan'!M7-H26)*50% -> 63 | I28: =('5.2 Juan'!E7-I26)*50% -> 630 | J28: =G28*'5.2 Juan'!K$29 -> 5.7916667 | K28: =H28*'5.2 Juan'!M$29 -> 37.564233 | L28: =I28*'5.2 Juan'!E$29 -> 410.42761 | N28: =IF(OR(I28>1000,L28>500),"High",IF(OR(I28>500,L28>250),"Medium","Low")) -> Medium | O28: Medium | P28: Low | Q28: Complete | R28: 46023 | S28: 46082 | T28: Cancelled
B29: 5.3 Vishal Mishra | C29: Support opening of India | D29: APAC | E29: Suzanna Uden | F29: Vishal Mishra | G29: ='Initiatives Summary'!$O45 -> 25 | H29: ='Initiatives Summary'!$BC45 -> 50 | I29: ='5.3 Vishal_India'!$E7 -> 100 | J29: ='Initiatives Summary'!$O68 -> -19.25 | K29: ='Initiatives Summary'!$BC68 -> -9.81 | L29: ='5.3 Vishal_India'!$E28 -> 23.94 | M29: ='Initiatives Summary'!$O77 -> -18 | N29: =IF(OR(I29>1000,L29>500),"High",IF(OR(I29>500,L29>250),"Medium","Low")) -> Low | O29: Low | P29: Low | Q29: Monitor | R29: 45839 | S29: 46174 | T29: Ongoing
B30: 5.4 International Event | C30: International and US event (biannual) | D30: Export | E30: Viola Kleist | F30: N/A | G30: ='Initiatives Summary'!$P45 -> 36.459375 | H30: ='Initiatives Summary'!$BD45 -> 44.25 | I30: ='5.4 Export Event'!$E7 -> 59 | J30: ='Initiatives Summary'!$P68 -> -101.30141 | K30: ='Initiatives Summary'!$BD68 -> -108.01625 | L30: ='5.4 Export Event'!$E28 -> -98.355 | M30: ='Initiatives Summary'!$P77 -> -125 | N30: =IF(OR(I30>1000,L30>500),"High",IF(OR(I30>500,L30>250),"Medium","Low")) -> Low | O30: Medium | P30: High | Q30: Proceed | R30: 45992 | S30: 46113 | T30: Cancelled
B31: 5.5 ABC Brokers | C31: New global distributors from network of Eduardo Emilio | D31: Export | E31: Rainer Anskinewitsch | F31: Eduardo Emilio | G31: ='Initiatives Log'!G17 -> 250 | H31: ='Initiatives Log'!H17 -> 1000 | I31: ='Initiatives Log'!I17 -> 2000 | J31: ='Initiatives Log'!J17 -> 157.5 | K31: ='Initiatives Log'!K17 -> 655 | L31: ='Initiatives Log'!L17 -> 1330 | M31: ='Initiatives Log'!M17 -> -8 | N31: =IF(OR(I31>1000,L31>500),"High",IF(OR(I31>500,L31>250),"Medium","Low")) -> High | O31: Medium | P31: Low | Q31: Proceed | R31: 45992 | S31: 46174 | T31: Not yet started
B32: 6.1 eComm EU | C32: Additional EU eComm paid media | D32: eCommerce | E32: Viola Kleist | F32: N/A | G32: ='Initiatives Summary'!$R45 -> 252.7 | H32: ='Initiatives Summary'!$BF45 -> 484.69575 | I32: ='6.1 eComm Growth EU'!$E7 -> 692.4225 | J32: ='Initiatives Summary'!$R68 -> -46.293 | K32: ='Initiatives Summary'!$BF68 -> 134.80911 | L32: ='6.1 eComm Growth EU'!$E28 -> 320.72455 | M32: ='Initiatives Summary'!$R77 -> -22.599667 | N32: =IF(OR(I32>1000,L32>500),"High",IF(OR(I32>500,L32>250),"Medium","Low")) -> Medium | O32: Medium | P32: High | Q32: Proceed | R32: 46023 | S32: 46082 | T32: Not yet started
B33: 6.2 eComm US | C33: Additional US eComm paid media | D33: eCommerce | E33: Viola Kleist | F33: N/A | G33: ='Initiatives Summary'!$S45 -> 119.7 | H33: ='Initiatives Summary'!$BG45 -> 308.80325 | I33: ='6.2 eComm Growth US'!$E7 -> 441.1475 | J33: ='Initiatives Summary'!$S68 -> -7.944 | K33: ='Initiatives Summary'!$BG68 -> 148.39968 | L33: ='6.2 eComm Growth US'!$E28 -> 265.52434 | M33: ='Initiatives Summary'!$S77 -> -9.44 | N33: =IF(OR(I33>1000,L33>500),"High",IF(OR(I33>500,L33>250),"Medium","Low")) -> Medium | O33: Medium | P33: High | Q33: Proceed | R33: 46023 | S33: 46082 | T33: Not yet started
B34: 7.1 NPD | C34: Cambrium Longevity and 4th Gen Collagen projects | D34: All | E34: Stefanie Wriedt | F34: Cambrium | G34: ='Initiatives Summary'!$T45 -> 154.41748 | H34: ='Initiatives Summary'!$BH45 -> 810.13109 | I34: ='7.1 Cambrium NPD'!$E7 -> 1080.1748 | J34: ='Initiatives Summary'!$T68 -> 22.474211 | K34: ='Initiatives Summary'!$BH68 -> 573.25818 | L34: ='7.1 Cambrium NPD'!$E28 -> 769.34424 | M34: ='Initiatives Summary'!$T77 -> -300 | N34: =IF(OR(I34>1000,L34>500),"High",IF(OR(I34>500,L34>250),"Medium","Low")) -> High | O34: High | P34: High | Q34: Proceed | R34: 46023 | S34: 46296 | T34: Not yet started
B35: 7.2 Social Media | C35: Social Media and Awareness Campaign | D35: All | E35: Viola Kleist | F35: N/A | G35: ='Initiatives Summary'!$U45 -> 205.88997 | H35: ='Initiatives Summary'!$BI45 -> 405.06555 | I35: ='7.2 Social Media_Mkting'!$E7 -> 540.08739 | J35: ='Initiatives Summary'!$U68 -> -161.03438 | K35: ='Initiatives Summary'!$BI68 -> 60.879092 | L35: ='7.2 Social Media_Mkting'!$E7 -> 540.08739 | M35: ='Initiatives Summary'!$U77 -> -311 | N35: =IF(OR(I35>1000,L35>500),"High",IF(OR(I35>500,L35>250),"Medium","Low")) -> High | O35: High | P35: High | Q35: Proceed | R35: 46023 | S35: 46174 | T35: Not yet started
B37: Total | G37: =SUM(G4:G36) -> 4191.2873 | H37: =SUM(H4:H36) -> 13904.761 | I37: =SUM(I4:I36) -> 30537.178 | J37: =SUM(J4:J36) -> 128.24057 | K37: =SUM(K4:K36) -> 6078.3226 | L37: =SUM(L4:L36) -> 17080.607 | M37: =SUM(M4:M36) -> -2019.5974

Sheet BAU Log - Detailed
B1: Date: | C1: =TODAY() -> 46044 | D1: =MONTH(C1)&RIGHT(YEAR(C1), 2) -> 126 | F1: Update
B3: Segment | C3: Responsible Director | D3: 2026B Sales (kEUR) | E3: 2028B Sales (kEUR) | F3: Size of the prize | G3: Impact on Business Valuation | H3: Level of QMS Control / Influence | I3: Current status | J3: Roadblocks | K3: Enablers | L3: Accelerators | M3: Updates since last reporting | N3: Key activities until next reporting | O3: Expected long-term developments | P3: Notes | Q3: Sales Planned to date (kEUR) | R3: Sales achieved to date (kEUR)
B4: Core Markets | C4: Giovanni Russo | D4: ='3YP'!E11 -> 7837.575 | E4: ='3YP'!G11 -> 9226.8725 | F4: =IF(E4>3000,"High",IF(E4>1500,"Medium","Low")) -> High | G4: High | H4: High | I4: On Track | J4: 1. Lack of visibility / brand awareness 2. Team capability / flexibility 3. Saturated marketplace | L4: Initiatives 1.1 and 1.2
B5: UK B2B | C5: Clare Morgan | D5: ='3YP'!E15 -> 496.7 | E5: ='3YP'!G15 -> 850.57 | F5: =IF(E5>3000,"High",IF(E5>1500,"Medium","Low")) -> Low | G5: Low | H5: High | I5: On Track | J5: 1. Lack of visibility / brand awareness 2. Use of consultants to minimise team spend 3. Saturated marketplace
B6: USA B2B | C6: Melissa Blamey | D6: ='3YP'!E19 -> 1003.242 | E6: ='3YP'!G19 -> 1553.8575 | F6: =IF(E6>3000,"High",IF(E6>1500,"Medium","Low")) -> Medium | G6: High | H6: Medium | I6: Behind | J6: 1. Lack of visibility / brand awareness 2. Team rotation / capability 3. Saturated marketplace
B7: Export | C7: Rainer Anskinewitsch | D7: ='3YP'!E28 -> 1944.5 | E7: ='3YP'!G28 -> 2360 | F7: =IF(E7>3000,"High",IF(E7>1500,"Medium","Low")) -> Medium | G7: Medium | H7: Low | I7: On Track | J7: 1. Lack of visibility / brand awareness 2. No dedicated team for growth 3. Complicated regulatory environments 4. Limited high value markets left untouched
B8: Company 1 | D8: =SUM(D4:D7) -> 11282.017 | E8: =SUM(E4:E7) -> 13991.3 | F8: High | G8: High | H8: Medium | I8: On Track
B10: China | C10: Suzanna Uden | D10: ='3YP'!E32 -> 800 | E10: ='3YP'!G32 -> 1600 | F10: =IF(E10>3000,"High",IF(E10>1500,"Medium","Low")) -> Medium | G10: High | H10: Low | I10: Behind
B11: Middle East | C11: Rainer Anskinewitsch | D11: ='3YP'!E33 -> 200 | E11: ='3YP'!G33 -> 500 | F11: =IF(E11>3000,"High",IF(E11>1500,"Medium","Low")) -> Low | G11: Medium | H11: Low | I11: Behind
B12: APAC | C12: Suzanna Uden | D12: ='3YP'!E34 -> 145 | E12: ='3YP'!G34 -> 375 | F12: =IF(E12>3000,"High",IF(E12>1500,"Medium","Low")) -> Low | G12: Medium | H12: Low | I12: Behind
B13: Company 2 | D13: =SUM(D10:D12) -> 1145 | E13: =SUM(E10:E12) -> 2475 | F13: Medium | G13: Medium | H13: Low | I13: Behind
B15: eCommerce EU | C15: Viola Kleist | D15: ='3YP'!E38 -> 748 | E15: ='3YP'!G38 -> 888.624 | F15: =IF(E15>3000,"High",IF(E15>1500,"Medium","Low")) -> Low | G15: Medium | H15: High | I15: On Track
B16: eCommerce US | C16: Viola Kleist | D16: ='3YP'!E39 -> 406 | E16: ='3YP'!G39 -> 482.328 | F16: =IF(E16>3000,"High",IF(E16>1500,"Medium","Low")) -> Low | G16: Medium | H16: High | I16: Ahead
B17: Amazon | C17: Viola Kleist | D17: ='3YP'!E40 -> 110 | E17: ='3YP'!G40 -> 130.68 | F17: =IF(E17>3000,"High",IF(E17>1500,"Medium","Low")) -> Low | G17: Medium | H17: High | I17: Ahead
B18: Other Online | C18: Clare Morgan | D18: ='3YP'!E41 -> 34.981105 | E18: ='3YP'!G41 -> 34.981105 | F18: =IF(E18>3000,"High",IF(E18>1500,"Medium","Low")) -> Low | G18: Low | H18: Low | I18: On Track
B19: Company 3 | D19: =SUM(D15:D18) -> 1298.9811 | E19: =SUM(E15:E18) -> 1536.6131 | F19: Medium | G19: Medium | H19: High | I19: Ahead
B21: Total QMS | D21: =SUM(D19,D13,D8) -> 13725.998 | E21: =SUM(E19,E13,E8) -> 18002.913

Sheet Definition
C1: Definition | D1: Examples
B2: Roadblocks | C2: Factual issues that are both controllable and uncontrollable, that negatively impact our plans for success. | D2: 1. Lack of Brand Awareness 2. Internal Capabilities / existing team performance 3. Economic sanctions or macro-economic factors
B3: Enablers | C3: Controllable actions or factors that can be taken within our Base budget | D3: Actions: 1. Refocus PR / Marketing budget 2. Attendance of trade shows 3. Team changes - replace A with B (within budget) Factors: 1. Clear professional strategy 2. Capable, motivated, knowledgable team 3. Strong back-office to deliver excellent customer experience
B4: Accelerators | C4: Further controllable actions that could be taken with spend or actions outside of our Base Budget. These would be above and beyond the normal | D4: 1. Significant PR / Awareness campaigns 2. Attendance of 10+ trade shows 3. Additional Team members 4. Team restructuring

Sheet Initiatives >>

Sheet 1.1 Core Markets Visibility
Z1: 0.05 | AA1: 0.1 | AB1: 0.1 | AC1: 0.2 | AD1: 0.25 | AE1: 0.3
B2: More Trade Shows
B3: Significant PR and Media spend | R3: Monthly | S3: Monthly | T3: Monthly | U3: Monthly | V3: Monthly | W3: Monthly | X3: Monthly | Y3: Monthly | Z3: Monthly | AA3: Monthly | AB3: Monthly | AC3: Monthly | AD3: Monthly | AE3: Monthly | AG3: To date | AH3: To date | AI3: To date | AJ3: To date | AK3: To date | AL3: To date | AM3: To date | AN3: To date | AO3: To date | AP3: To date | AQ3: To date | AR3: To date | AS3: To date | AT3: To date
R4: =MONTH(R5)&RIGHT(YEAR(R5), 2) -> 1125 | S4: =MONTH(S5)&RIGHT(YEAR(S5), 2) -> 1225 | T4: =MONTH(T5)&RIGHT(YEAR(T5), 2) -> 126 | U4: =MONTH(U5)&RIGHT(YEAR(U5), 2) -> 226 | V4: =MONTH(V5)&RIGHT(YEAR(V5), 2) -> 326 | W4: =MONTH(W5)&RIGHT(YEAR(W5), 2) -> 426 | X4: =MONTH(X5)&RIGHT(YEAR(X5), 2) -> 526 | Y4: =MONTH(Y5)&RIGHT(YEAR(Y5), 2) -> 626 | ... AE4: =MONTH(AE5)&RIGHT(YEAR(AE5), 2) -> 1226 | AG4: =MONTH(AG5)&RIGHT(YEAR(AG5), 2) -> 1125 | AH4: =MONTH(AH5)&RIGHT(YEAR(AH5), 2) -> 1225 | AI4: =MONTH(AI5)&RIGHT(YEAR(AI5), 2) -> 126 | AJ4: =MONTH(AJ5)&RIGHT(YEAR(AJ5), 2) -> 226 | AK4: =MONTH(AK5)&RIGHT(YEAR(AK5), 2) -> 326 | AL4: =MONTH(AL5)&RIGHT(YEAR(AL5), 2) -> 426 | AM4: =MONTH(AM5)&RIGHT(YEAR(AM5), 2) -> 526 | AN4: =MONTH(AN5)&RIGHT(YEAR(AN5), 2) -> 626 | ... AT4: =MONTH(AT5)&RIGHT(YEAR(AT5), 2) -> 1226
C5: 2026 | D5: 2027 | E5: 2028 | H5: Risk Factor | K5: 2026 | L5: 2027 | M5: 2028 | R5: 45962 | S5: 45992 | T5: 46023 | U5: 46054 | V5: 46082 | W5: 46113 | X5: 46143 | Y5: 46174 | Z5: 46204 | AA5: 46235 | AB5: 46266 | AC5: 46296 | AD5: 46327 | AE5: 46357 | AG5: 45962 | AH5: 45992 | AI5: 46023 | AJ5: 46054 | AK5: 46082 | AL5: 46113 | AM5: 46143 | AN5: 46174 | AO5: 46204 | AP5: 46235 | AQ5: 46266 | AR5: 46296 | AS5: 46327 | AT5: 46357
Q6: Trade show - Sales | Z6: =$K7*50%*Z$1 -> 6.7397269 | AA6: =$K7*50%*AA$1 -> 13.479454 | AB6: =$K7*50%*AB$1 -> 13.479454 | AC6: =$K7*50%*AC$1 -> 26.958907 | AD6: =$K7*50%*AD$1 -> 33.698634 | AE6: =$K7*50%*AE$1 -> 40.438361 | AG6: =R6 -> 0 | AH6: =AG6+S6 -> 0 | AI6: =AH6+T6 -> 0 | AJ6: =AI6+U6 -> 0 | AK6: =AJ6+V6 -> 0 | AL6: =AK6+W6 -> 0 | AM6: =AL6+X6 -> 0 | AN6: =AM6+Y6 -> 0 | AO6: =AN6+Z6 -> 6.7397269 | ... AT6: =AS6+AE6 -> 134.79454
B7: Revenue | C7: =C46*10+'3YP'!E11*C47 -> 385.12725 | D7: =C46*20+D46*15+'3YP'!F11*D47 -> 930.46762 | E7: =C46*25+D46*20+E46*15+'3YP'!G11*E47 -> 1601.8062 | H7: -0.3 | J7: Revenue | K7: =C7*(1+$H$7) -> 269.58907 | L7: =D7*(1+$H$7) -> 651.32734 | M7: =E7*(1+$H$7) -> 1121.2643 | Q7: PR & Media - Sales | Z7: =$K7*50%*Z$1 -> 6.7397269 | AA7: =$K7*50%*AA$1 -> 13.479454 | AB7: =$K7*50%*AB$1 -> 13.479454 | AC7: =$K7*50%*AC$1 -> 26.958907 | AD7: =$K7*50%*AD$1 -> 33.698634 | AE7: =$K7*50%*AE$1 -> 40.438361 | AG7: =R7 -> 0 | AH7: =AG7+S7 -> 0 | AI7: =AH7+T7 -> 0 | AJ7: =AI7+U7 -> 0 | AK7: =AJ7+V7 -> 0 | AL7: =AK7+W7 -> 0 | AM7: =AL7+X7 -> 0 | AN7: =AM7+Y7 -> 0 | AO7: =AN7+Z7 -> 6.7397269 | ... AT7: =AS7+AE7 -> 134.79454
B8: Cost of Sales | C8: =-C7*(1-COGS!C3) -> -57.769088 | D8: =-D7*(1-COGS!D3) -> -137.24397 | E8: =-E7*(1-COGS!E3) -> -232.2619 | J8: Cost of Sales | K8: =C8*(1+$H$7) -> -40.438361 | L8: =D8*(1+$H$7) -> -96.070782 | M8: =E8*(1+$H$7) -> -162.58333
B10: Gross Profit I | C10: =SUM(C7:C8) -> 327.35816 | D10: =SUM(D7:D8) -> 793.22365 | E10: =SUM(E7:E8) -> 1369.5443 | J10: Gross Profit I | K10: =SUM(K7:K8) -> 229.15071 | L10: =SUM(L7:L8) -> 555.25656 | M10: =SUM(M7:M8) -> 958.681 | Q10: Trade show - adj. EBITDA | V10: =V6*$K$17+V14+SUM($K$25:$K$26)*(V6/SUM($T6:$AE6))/2 -> -12 | W10: =W6*$K$17+W14+SUM($K$25:$K$26)*(W6/SUM($T6:$AE6))/2 -> -12 | X10: =X6*$K$17+X14+SUM($K$25:$K$26)*(X6/SUM($T6:$AE6))/2 -> -12 | Y10: =Y6*$K$17+Y14+SUM($K$25:$K$26)*(Y6/SUM($T6:$AE6))/2 -> -12 | Z10: =Z6*$K$17+Z14+SUM($K$25:$K$26)*(Z6/SUM($T6:$AE6))/2 -> -7.1376021 | AA10: =AA6*$K$17+AA14+SUM($K$25:$K$26)*(AA6/SUM($T6:$AE6))/2 -> -2.2752042 | AB10: =AB6*$K$17+AB14+SUM($K$25:$K$26)*(AB6/SUM($T6:$AE6))/2 -> -2.2752042 | AC10: =AC6*$K$17+AC14+SUM($K$25:$K$26)*(AC6/SUM($T6:$AE6))/2 -> 7.4495915 | ... AE10: =AE6*$K$17+AE14+SUM($K$25:$K$26)*(AE6/SUM($T6:$AE6))/2 -> 17.174387 | AG10: =R10 -> 0 | AH10: =AG10+S10 -> 0 | AI10: =AH10+T10 -> 0 | AJ10: =AI10+U10 -> 0 | AK10: =AJ10+V10 -> -12 | AL10: =AK10+W10 -> -24 | AM10: =AL10+X10 -> -36 | AN10: =AM10+Y10 -> -48 | AO10: =AN10+Z10 -> -55.137602 | ... AT10: =AS10+AE10 -> -22.752042
B11: GP I % | C11: =C10/C$7 -> 0.85 | D11: =D10/D$7 -> 0.8525 | E11: =E10/E$7 -> 0.855 | J11: GP I % | K11: =K10/K$7 -> 0.85 | L11: =L10/L$7 -> 0.8525 | M11: =M10/M$7 -> 0.855 | Q11: PR & Media - adj. EBITDA | V11: =V7*$K$17+V15+SUM($K$25:$K$26)*(V7/SUM($T7:$AE7))/2 -> -54.29 | W11: =W7*$K$17+W15+SUM($K$25:$K$26)*(W7/SUM($T7:$AE7))/2 -> -54.29 | X11: =X7*$K$17+X15+SUM($K$25:$K$26)*(X7/SUM($T7:$AE7))/2 -> -54.29 | Y11: =Y7*$K$17+Y15+SUM($K$25:$K$26)*(Y7/SUM($T7:$AE7))/2 -> -54.29 | Z11: =Z7*$K$17+Z15+SUM($K$25:$K$26)*(Z7/SUM($T7:$AE7))/2 -> -49.427602 | AA11: =AA7*$K$17+AA15+SUM($K$25:$K$26)*(AA7/SUM($T7:$AE7))/2 -> -44.565204 | AB11: =AB7*$K$17+AB15+SUM($K$25:$K$26)*(AB7/SUM($T7:$AE7))/2 -> -44.565204 | AC11: =AC7*$K$17+AC15+SUM($K$25:$K$26)*(AC7/SUM($T7:$AE7))/2 -> -34.840408 | ... AE11: =AE7*$K$17+AE15+SUM($K$25:$K$26)*(AE7/SUM($T7:$AE7))/2 -> -25.115613 | AG11: =R11 -> 0 | AH11: =AG11+S11 -> 0 | AI11: =AH11+T11 -> 0 | AJ11: =AI11+U11 -> 0 | AK11: =AJ11+V11 -> -54.29 | AL11: =AK11+W11 -> -108.58 | AM11: =AL11+X11 -> -162.87 | AN11: =AM11+Y11 -> -217.16 | AO11: =AN11+Z11 -> -266.5876 | ... AT11: =AS11+AE11 -> -445.65204
B13: Shipping and distribution costs | C13: =-C7*'Other COS'!$C$4 -> -3.8512725 | D13: =-D7*'Other COS'!$C$4 -> -9.3046762 | E13: =-E7*'Other COS'!$C$4 -> -16.018062 | J13: Shipping and distribution costs | K13: =-K7*'Other COS'!$C$4 -> -2.6958907 | L13: =-L7*'Other COS'!$C$4 -> -6.5132734 | M13: =-M7*'Other COS'!$C$4 -> -11.212643
B14: Rebates | C14: 0 | D14: =-D7*3% -> -27.914029 | E14: =-E7*3% -> -48.054185 | J14: Rebates | K14: 0 | L14: =-L7*3% -> -19.53982 | M14: =-M7*3% -> -33.63793 | Q14: Trade show - Spend | V14: =$K20*10% -> -12 | W14: =$K20*10% -> -12 | X14: =$K20*10% -> -12 | Y14: =$K20*10% -> -12 | Z14: =$K20*10% -> -12 | AA14: =$K20*10% -> -12 | AB14: =$K20*10% -> -12 | AC14: =$K20*10% -> -12 | ... AE14: =$K20*10% -> -12
Q15: PR & Media - Spend | V15: =$K19*10% -> -54.29 | W15: =$K19*10% -> -54.29 | X15: =$K19*10% -> -54.29 | Y15: =$K19*10% -> -54.29 | Z15: =$K19*10% -> -54.29 | AA15: =$K19*10% -> -54.29 | AB15: =$K19*10% -> -54.29 | AC15: =$K19*10% -> -54.29 | ... AE15: =$K19*10% -> -54.29
B16: Gross profit II | C16: =SUM(C10,C13:C14) -> 323.50689 | D16: =SUM(D10,D13:D14) -> 756.00495 | E16: =SUM(E10,E13:E14) -> 1305.472 | J16: Gross profit II | K16: =SUM(K10,K13:K14) -> 226.45482 | L16: =SUM(L10,L13:L14) -> 529.20346 | M16: =SUM(M10,M13:M14) -> 913.83042
B17: GP II % | C17: =C16/C$7 -> 0.84 | D17: =D16/D$7 -> 0.8125 | E17: =E16/E$7 -> 0.815 | J17: GP II % | K17: =K16/K$7 -> 0.84 | L17: =L16/L$7 -> 0.8125 | M17: =M16/M$7 -> 0.815
B19: Advertising and Marketing | C19: =-Extra!F5/1000 -> -542.9 | D19: =C19*1.1 -> -597.19 | E19: =D19*1.1 -> -656.909 | J19: Advertising and Marketing | K19: =C19 -> -542.9 | L19: =D19 -> -597.19 | M19: =E19 -> -656.909
B20: Sales and Training Expenses | C20: =-Extra!F42/1000 -> -120 | D20: =C20*1.1 -> -132 | E20: =D20*1.1 -> -145.2 | J20: Sales and Training Expenses | K20: =C20 -> -120 | L20: =D20 -> -132 | M20: =E20 -> -145.2
B22: Gross profit III | C22: =SUM(C16,C19:C20) -> -339.39311 | D22: =SUM(D16,D19:D20) -> 26.814945 | E22: =SUM(E16,E19:E20) -> 503.36303 | J22: Gross profit III | K22: =SUM(K16,K19:K20) -> -436.44518 | L22: =SUM(L16,L19:L20) -> -199.98654 | M22: =SUM(M16,M19:M20) -> 111.72142
B23: GP III % | C23: =C22/C$7 -> -0.88124928 | D23: =D22/D$7 -> 0.028818784 | E23: =E22/E$7 -> 0.31424715 | J23: GP III % | K23: =K22/K$7 -> -1.6189275 | L23: =L22/L$7 -> -0.30704459 | M23: =M22/M$7 -> 0.099638792
B25: Personnel Expenses | C25: =-C7*10% -> -38.512725 | D25: =-D7*10% -> -93.046762 | E25: =-E7*10% -> -160.18062 | J25: Personnel Expenses | K25: =-K7*10% -> -26.958907 | L25: =-L7*10% -> -65.132734 | M25: =-M7*10% -> -112.12643
B26: Other Admin Expenses | C26: -5 | D26: -5 | E26: -5 | J26: Other Admin Expenses | K26: -5 | L26: -5 | M26: -5
B28: Adjusted EBITDA | C28: =SUM(C22,C25:C26) -> -382.90583 | D28: =SUM(D22,D25:D26) -> -71.231817 | E28: =SUM(E22,E25:E26) -> 338.18242 | J28: Adjusted EBITDA | K28: =SUM(K22,K25:K26) -> -468.40408 | L28: =SUM(L22,L25:L26) -> -270.11927 | M28: =SUM(M22,M25:M26) -> -5.4050094
B29: Adj EBITDA % | C29: =C28/C$7 -> -0.994232 | D29: =D28/D$7 -> -0.076554858 | E29: =E28/E$7 -> 0.21112568 | J29: Adj EBITDA % | K29: =K28/K$7 -> -1.7374743 | L29: =L28/L$7 -> -0.41472123 | M29: =M28/M$7 -> -0.0048204596
B31: Exceptionals | C31: 0 | D31: 0 | E31: 0 | J31: Exceptionals | K31: 0 | L31: 0 | M31: 0
B33: EBITDA | C33: =SUM(C28,C31) -> -382.90583 | D33: =SUM(D28,D31) -> -71.231817 | E33: =SUM(E28,E31) -> 338.18242 | J33: EBITDA | K33: =SUM(K28,K31) -> -468.40408 | L33: =SUM(L28,L31) -> -270.11927 | M33: =SUM(M28,M31) -> -5.4050094
B34: EBITDA % | C34: =C33/C$7 -> -0.994232 | D34: =D33/D$7 -> -0.076554858 | E34: =E33/E$7 -> 0.21112568 | J34: EBITDA % | K34: =K33/K$7 -> -1.7374743 | L34: =L33/L$7 -> -0.41472123 | M34: =M33/M$7 -> -0.0048204596
B37: Risk Amount | C37: =C20+C19*60% -> -445.74 | F37: 60% marketing spend plus full trade show budget | J37: Risk Amount | K37: =K20+K19*60% -> -445.74 | N37: 60% marketing spend plus full trade show budget
B44: Workings
B46: New doors | C46: 15 | D46: 25 | E46: 30
B47: Existing growth | C47: 0.03 | D47: 0.03 | E47: 0.03

Sheet 1.2 Core Markets Team expansion
U1: 0 | V1: 0 | W1: 0 | X1: 0 | Y1: 0 | Z1: 0 | AA1: 0.1 | AB1: 0.1 | AC1: 0.15 | AD1: 0.2 | AE1: 0.2 | AF1: 0.25
B2: +1 FTE CH
B3: +1 FTE DE | S3: Monthly | T3: Monthly | U3: Monthly | V3: Monthly | W3: Monthly | X3: Monthly | Y3: Monthly | Z3: Monthly | AA3: Monthly | AB3: Monthly | AC3: Monthly | AD3: Monthly | AE3: Monthly | AF3: Monthly | AH3: To date | AI3: To date | AJ3: To date | AK3: To date | AL3: To date | AM3: To date | AN3: To date | AO3: To date | AP3: To date | AQ3: To date | AR3: To date | AS3: To date | AT3: To date | AU3: To date
S4: =MONTH(S5)&RIGHT(YEAR(S5), 2) -> 1125 | T4: =MONTH(T5)&RIGHT(YEAR(T5), 2) -> 1225 | U4: =MONTH(U5)&RIGHT(YEAR(U5), 2) -> 126 | V4: =MONTH(V5)&RIGHT(YEAR(V5), 2) -> 226 | W4: =MONTH(W5)&RIGHT(YEAR(W5), 2) -> 326 | X4: =MONTH(X5)&RIGHT(YEAR(X5), 2) -> 426 | Y4: =MONTH(Y5)&RIGHT(YEAR(Y5), 2) -> 526 | Z4: =MONTH(Z5)&RIGHT(YEAR(Z5), 2) -> 626 | ... AF4: =MONTH(AF5)&RIGHT(YEAR(AF5), 2) -> 1226 | AH4: =MONTH(AH5)&RIGHT(YEAR(AH5), 2) -> 1125 | AI4: =MONTH(AI5)&RIGHT(YEAR(AI5), 2) -> 1225 | AJ4: =MONTH(AJ5)&RIGHT(YEAR(AJ5), 2) -> 126 | AK4: =MONTH(AK5)&RIGHT(YEAR(AK5), 2) -> 226 | AL4: =MONTH(AL5)&RIGHT(YEAR(AL5), 2) -> 326 | AM4: =MONTH(AM5)&RIGHT(YEAR(AM5), 2) -> 426 | AN4: =MONTH(AN5)&RIGHT(YEAR(AN5), 2) -> 526 | AO4: =MONTH(AO5)&RIGHT(YEAR(AO5), 2) -> 626 | ... AU4: =MONTH(AU5)&RIGHT(YEAR(AU5), 2) -> 1226
C5: 2026 | D5: 2027 | E5: 2028 | H5: Risk Factor | K5: 2026 | L5: 2027 | M5: 2028 | S5: 45962 | T5: 45992 | U5: 46023 | V5: 46054 | W5: 46082 | X5: 46113 | Y5: 46143 | Z5: 46174 | AA5: 46204 | AB5: 46235 | AC5: 46266 | AD5: 46296 | AE5: 46327 | AF5: 46357 | AH5: 45962 | AI5: 45992 | AJ5: 46023 | AK5: 46054 | AL5: 46082 | AM5: 46113 | AN5: 46143 | AO5: 46174 | AP5: 46204 | AQ5: 46235 | AR5: 46266 | AS5: 46296 | AT5: 46327 | AU5: 46357
B7: Revenue | C7: =C46*10 -> 120 | D7: =C46*20+D46*15 -> 480 | E7: =C46*25+D46*20+E46*15 -> 920 | H7: -0.3 | J7: Revenue | K7: =C7*(1+$H$7) -> 84 | L7: =D7*(1+$H$7) -> 336 | M7: =E7*(1+$H$7) -> 644 | R7: Sales | U7: =$K7*U1 -> 0 | V7: =$K7*V1 -> 0 | W7: =$K7*W1 -> 0 | X7: =$K7*X1 -> 0 | Y7: =$K7*Y1 -> 0 | Z7: =$K7*Z1 -> 0 | AA7: =$K7*AA1 -> 8.4 | AB7: =$K7*AB1 -> 8.4 | ... AF7: =$K7*AF1 -> 21 | AH7: =S7 -> 0 | AI7: =AH7+T7 -> 0 | AJ7: =AI7+U7 -> 0 | AK7: =AJ7+V7 -> 0 | AL7: =AK7+W7 -> 0 | AM7: =AL7+X7 -> 0 | AN7: =AM7+Y7 -> 0 | AO7: =AN7+Z7 -> 0 | AP7: =AO7+AA7 -> 8.4 | ... AU7: =AT7+AF7 -> 84
B8: Cost of Sales | C8: =-C7*(1-COGS!C3) -> -18 | D8: =-D7*(1-COGS!D3) -> -70.8 | E8: =-E7*(1-COGS!E3) -> -133.4 | J8: Cost of Sales | K8: =C8*(1+$H$7) -> -12.6 | L8: =D8*(1+$H$7) -> -49.56 | M8: =E8*(1+$H$7) -> -93.38
R9: EBITDA | U9: =U7*$K17-U11 -> 0 | V9: =V7*$K17-V11 -> 0 | W9: =W7*$K17-W11 -> 0 | X9: =X7*$K17-X11 -> -15 | Y9: =Y7*$K17-Y11 -> -15 | Z9: =Z7*$K17-Z11 -> -15 | AA9: =AA7*$K17-AA11 -> -8.784 | AB9: =AB7*$K17-AB11 -> -8.784 | ... AF9: =AF7*$K17-AF11 -> 0.54 | AH9: =S9 -> 0 | AI9: =AH9+T9 -> 0 | AJ9: =AI9+U9 -> 0 | AK9: =AJ9+V9 -> 0 | AL9: =AK9+W9 -> 0 | AM9: =AL9+X9 -> -15 | AN9: =AM9+Y9 -> -30 | AO9: =AN9+Z9 -> -45 | AP9: =AO9+AA9 -> -53.784 | ... AU9: =AT9+AF9 -> -72.84
B10: Gross Profit I | C10: =SUM(C7:C8) -> 102 | D10: =SUM(D7:D8) -> 409.2 | E10: =SUM(E7:E8) -> 786.6 | J10: Gross Profit I | K10: =SUM(K7:K8) -> 71.4 | L10: =SUM(L7:L8) -> 286.44 | M10: =SUM(M7:M8) -> 550.62
B11: GP I % | C11: =C10/C$7 -> 0.85 | D11: =D10/D$7 -> 0.8525 | E11: =E10/E$7 -> 0.855 | J11: GP I % | K11: =K10/K$7 -> 0.85 | L11: =L10/L$7 -> 0.8525 | M11: =M10/M$7 -> 0.855 | R11: Cost | X11: =-($K25+$K7*10%)/9+X7*10%-$K26/9 -> 15 | Y11: =-($K25+$K7*10%)/9+Y7*10%-$K26/9 -> 15 | Z11: =-($K25+$K7*10%)/9+Z7*10%-$K26/9 -> 15 | AA11: =-($K25+$K7*10%)/9+AA7*10%-$K26/9 -> 15.84 | AB11: =-($K25+$K7*10%)/9+AB7*10%-$K26/9 -> 15.84 | AC11: =-($K25+$K7*10%)/9+AC7*10%-$K26/9 -> 16.26 | AD11: =-($K25+$K7*10%)/9+AD7*10%-$K26/9 -> 16.68 | AE11: =-($K25+$K7*10%)/9+AE7*10%-$K26/9 -> 16.68 | AF11: =-($K25+$K7*10%)/9+AF7*10%-$K26/9 -> 17.1 | AH11: =S11 -> 0 | AI11: =AH11+T11 -> 0 | AJ11: =AI11+U11 -> 0 | AK11: =AJ11+V11 -> 0 | AL11: =AK11+W11 -> 0 | AM11: =AL11+X11 -> 15 | AN11: =AM11+Y11 -> 30 | AO11: =AN11+Z11 -> 45 | AP11: =AO11+AA11 -> 60.84 | ... AU11: =AT11+AF11 -> 143.4
B13: Shipping and distribution costs | C13: =-C7*'Other COS'!$C$4 -> -1.2 | D13: =-D7*'Other COS'!$C$4 -> -4.8 | E13: =-E7*'Other COS'!$C$4 -> -9.2 | J13: Shipping and distribution costs | K13: =C13*(1+$H$7) -> -0.84 | L13: =D13*(1+$H$7) -> -3.36 | M13: =E13*(1+$H$7) -> -6.44
B14: Rebates | C14: 0 | D14: =-D7*3% -> -14.4 | E14: =-E7*3% -> -27.6 | J14: Rebates | K14: =C14*(1+$H$7) -> 0 | L14: =D14*(1+$H$7) -> -10.08 | M14: =E14*(1+$H$7) -> -19.32
B16: Gross profit II | C16: =SUM(C10,C13:C14) -> 100.8 | D16: =SUM(D10,D13:D14) -> 390 | E16: =SUM(E10,E13:E14) -> 749.8 | J16: Gross profit II | K16: =SUM(K10,K13:K14) -> 70.56 | L16: =SUM(L10,L13:L14) -> 273 | M16: =SUM(M10,M13:M14) -> 524.86
B17: GP II % | C17: =C16/C$7 -> 0.84 | D17: =D16/D$7 -> 0.8125 | E17: =E16/E$7 -> 0.815 | J17: GP II % | K17: =K16/K$7 -> 0.84 | L17: =L16/L$7 -> 0.8125 | M17: =M16/M$7 -> 0.815
B19: Advertising and Marketing | C19: 0 | D19: 0 | E19: 0 | J19: Advertising and Marketing | K19: =C19 -> 0 | L19: =D19 -> 0 | M19: =E19 -> 0
B20: Sales and Training Expenses | C20: 0 | D20: 0 | E20: 0 | J20: Sales and Training Expenses | K20: =C20 -> 0 | L20: =D20 -> 0 | M20: =E20 -> 0
B22: Gross profit III | C22: =SUM(C16,C19:C20) -> 100.8 | D22: =SUM(D16,D19:D20) -> 390 | E22: =SUM(E16,E19:E20) -> 749.8 | J22: Gross profit III | K22: =SUM(K16,K19:K20) -> 70.56 | L22: =SUM(L16,L19:L20) -> 273 | M22: =SUM(M16,M19:M20) -> 524.86
B23: GP III % | C23: =C22/C$7 -> 0.84 | D23: =D22/D$7 -> 0.8125 | E23: =E22/E$7 -> 0.815 | J23: GP III % | K23: =K22/K$7 -> 0.84 | L23: =L22/L$7 -> 0.8125 | M23: =M22/M$7 -> 0.815
B25: Personnel Expenses | C25: =-C7*10%-60*2 -> -132 | D25: =-D7*10%-60*2*1.1 -> -180 | E25: =-E7*10%-60*2*1.1^2 -> -237.2 | J25: Personnel Expenses | K25: =-K7*10%-60*2 -> -128.4 | L25: =-L7*10%-60*2*1.1 -> -165.6 | M25: =-M7*10%-60*2*1.1^2 -> -209.6
B26: Other Admin Expenses | C26: -15 | D26: -20 | E26: -22 | J26: Other Admin Expenses | K26: =C26 -> -15 | L26: =D26 -> -20 | M26: =E26 -> -22
B28: Adjusted EBITDA | C28: =SUM(C22,C25:C26) -> -46.2 | D28: =SUM(D22,D25:D26) -> 190 | E28: =SUM(E22,E25:E26) -> 490.6 | J28: Adjusted EBITDA | K28: =SUM(K22,K25:K26) -> -72.84 | L28: =SUM(L22,L25:L26) -> 87.4 | M28: =SUM(M22,M25:M26) -> 293.26
B29: Adj EBITDA % | C29: =C28/C$7 -> -0.385 | D29: =D28/D$7 -> 0.39583333 | E29: =E28/E$7 -> 0.53326087 | J29: Adj EBITDA % | K29: =K28/K$7 -> -0.86714286 | L29: =L28/L$7 -> 0.26011905 | M29: =M28/M$7 -> 0.45537267
B31: Exceptionals | C31: 0 | D31: 0 | E31: 0 | J31: Exceptionals | K31: =C31 -> 0 | L31: =D31 -> 0 | M31: =E31 -> 0
B33: EBITDA | C33: =SUM(C28,C31) -> -46.2 | D33: =SUM(D28,D31) -> 190 | E33: =SUM(E28,E31) -> 490.6 | J33: EBITDA | K33: =SUM(K28,K31) -> -72.84 | L33: =SUM(L28,L31) -> 87.4 | M33: =SUM(M28,M31) -> 293.26
B34: EBITDA % | C34: =C33/C$7 -> -0.385 | D34: =D33/D$7 -> 0.39583333 | E34: =E33/E$7 -> 0.53326087 | J34: EBITDA % | K34: =K33/K$7 -> -0.86714286 | L34: =L33/L$7 -> 0.26011905 | M34: =M33/M$7 -> 0.45537267
B37: Risk Amount | C37: =(C25+C26)*6/12 -> -73.5 | F37: 6 months of employee costs | J37: Risk Amount | K37: =(K25+K26)*6/12 -> -71.7 | N37: 6 months of employee costs
B44: Workings
B46: New doors | C46: 12 | D46: 16 | E46: 20

Sheet 2.1 Mark Wuttke Contact Book
B2: Day Spas
B3: Coaching | S3: Monthly | T3: Monthly | U3: Monthly | V3: Monthly | W3: Monthly | X3: Monthly | Y3: Monthly | Z3: Monthly | AA3: Monthly | AB3: Monthly | AC3: Monthly | AD3: Monthly | AE3: Monthly | AF3: Monthly | AH3: To date | AI3: To date | AJ3: To date | AK3: To date | AL3: To date | AM3: To date | AN3: To date | AO3: To date | AP3: To date | AQ3: To date | AR3: To date | AS3: To date | AT3: To date | AU3: To date
S4: =MONTH(S5)&RIGHT(YEAR(S5), 2) -> 1125 | T4: =MONTH(T5)&RIGHT(YEAR(T5), 2) -> 1225 | U4: =MONTH(U5)&RIGHT(YEAR(U5), 2) -> 126 | V4: =MONTH(V5)&RIGHT(YEAR(V5), 2) -> 226 | W4: =MONTH(W5)&RIGHT(YEAR(W5), 2) -> 326 | X4: =MONTH(X5)&RIGHT(YEAR(X5), 2) -> 426 | Y4: =MONTH(Y5)&RIGHT(YEAR(Y5), 2) -> 526 | Z4: =MONTH(Z5)&RIGHT(YEAR(Z5), 2) -> 626 | ... AF4: =MONTH(AF5)&RIGHT(YEAR(AF5), 2) -> 1226 | AH4: =MONTH(AH5)&RIGHT(YEAR(AH5), 2) -> 1125 | AI4: =MONTH(AI5)&RIGHT(YEAR(AI5), 2) -> 1225 | AJ4: =MONTH(AJ5)&RIGHT(YEAR(AJ5), 2) -> 126 | AK4: =MONTH(AK5)&RIGHT(YEAR(AK5), 2) -> 226 | AL4: =MONTH(AL5)&RIGHT(YEAR(AL5), 2) -> 326 | AM4: =MONTH(AM5)&RIGHT(YEAR(AM5), 2) -> 426 | AN4: =MONTH(AN5)&RIGHT(YEAR(AN5), 2) -> 526 | AO4: =MONTH(AO5)&RIGHT(YEAR(AO5), 2) -> 626 | ... AU4: =MONTH(AU5)&RIGHT(YEAR(AU5), 2) -> 1226
C5: 2026 | D5: 2027 | E5: 2028 | H5: Risk Factor | K5: 2026 | L5: 2027 | M5: 2028 | S5: 45962 | T5: 45992 | U5: 46023 | V5: 46054 | W5: 46082 | X5: 46113 | Y5: 46143 | Z5: 46174 | AA5: 46204 | AB5: 46235 | AC5: 46266 | AD5: 46296 | AE5: 46327 | AF5: 46357 | AH5: 45962 | AI5: 45992 | AJ5: 46023 | AK5: 46054 | AL5: 46082 | AM5: 46113 | AN5: 46143 | AO5: 46174 | AP5: 46204 | AQ5: 46235 | AR5: 46266 | AS5: 46296 | AT5: 46327 | AU5: 46357
Q6: Spa Chains - Tosca | R6: Sales | U6: ='Initiative Log - Detailed'!$G7*U27 -> 0 | V6: ='Initiative Log - Detailed'!$G7*V27 -> 0 | W6: ='Initiative Log - Detailed'!$G7*W27 -> 0 | X6: ='Initiative Log - Detailed'!$G7*X27 -> 0 | Y6: ='Initiative Log - Detailed'!$G7*Y27 -> 0 | Z6: ='Initiative Log - Detailed'!$G7*Z27 -> 0 | AA6: ='Initiative Log - Detailed'!$G7*AA27 -> 0 | AB6: ='Initiative Log - Detailed'!$G7*AB27 -> 60 | ... AF6: ='Initiative Log - Detailed'!$G7*AF27 -> 40 | AH6: =S6 -> 0 | AI6: =AH6+T6 -> 0 | AJ6: =AI6+U6 -> 0 | AK6: =AJ6+V6 -> 0 | AL6: =AK6+W6 -> 0 | AM6: =AL6+X6 -> 0 | AN6: =AM6+Y6 -> 0 | AO6: =AN6+Z6 -> 0 | AP6: =AO6+AA6 -> 0 | ... AU6: =AT6+AF6 -> 200
B7: Revenue | C7: =SUM(C46:C49)+C51*30+'3YP'!E17*C52 -> 4089.4973 | D7: =SUM(D46:D49)+D51*30+C51*50+'3YP'!F17*D52 -> 8948.3464 | E7: =SUM(E46:E49)+E51*30+D51*50+C51*55+'3YP'!G17*E52 -> 11816.016 | H7: -0.67 | J7: Revenue | K7: =C7*(1+$H$7) -> 1349.5341 | L7: =D7*(1+$H$7) -> 2952.9543 | M7: =E7*(1+$H$7) -> 3899.2852 | Q7: Spa Chains - Woodhouse | R7: Sales | U7: ='Initiative Log - Detailed'!$G8*U28 -> 0 | V7: ='Initiative Log - Detailed'!$G8*V28 -> 0 | W7: ='Initiative Log - Detailed'!$G8*W28 -> 60 | X7: ='Initiative Log - Detailed'!$G8*X28 -> 18 | Y7: ='Initiative Log - Detailed'!$G8*Y28 -> 24 | Z7: ='Initiative Log - Detailed'!$G8*Z28 -> 24 | AA7: ='Initiative Log - Detailed'!$G8*AA28 -> 90 | AB7: ='Initiative Log - Detailed'!$G8*AB28 -> 42 | ... AF7: ='Initiative Log - Detailed'!$G8*AF28 -> 78 | AH7: =S7 -> 0 | AI7: =AH7+T7 -> 0 | AJ7: =AI7+U7 -> 0 | AK7: =AJ7+V7 -> 0 | AL7: =AK7+W7 -> 60 | AM7: =AL7+X7 -> 78 | AN7: =AM7+Y7 -> 102 | AO7: =AN7+Z7 -> 126 | AP7: =AO7+AA7 -> 216 | ... AU7: =AT7+AF7 -> 600
B8: Cost of Sales | C8: =-C7*(1-COGS!C15+5%) -> -817.89945 | D8: =-D7*(1-COGS!D15+5%) -> -1767.2984 | E8: =-E7*(1-COGS!E15+5%) -> -2304.1231 | J8: Cost of Sales | K8: =C8*(1+$H$7) -> -269.90682 | L8: =D8*(1+$H$7) -> -583.20848 | M8: =E8*(1+$H$7) -> -760.36061 | Q8: Spa Chains - Trilogy | R8: Sales | U8: ='Initiative Log - Detailed'!$G9*U29 -> 0 | V8: ='Initiative Log - Detailed'!$G9*V29 -> 0 | W8: ='Initiative Log - Detailed'!$G9*W29 -> 0 | X8: ='Initiative Log - Detailed'!$G9*X29 -> 40 | Y8: ='Initiative Log - Detailed'!$G9*Y29 -> 16 | Z8: ='Initiative Log - Detailed'!$G9*Z29 -> 24 | AA8: ='Initiative Log - Detailed'!$G9*AA29 -> 60 | AB8: ='Initiative Log - Detailed'!$G9*AB29 -> 28 | ... AF8: ='Initiative Log - Detailed'!$G9*AF29 -> 52 | AH8: =S8 -> 0 | AI8: =AH8+T8 -> 0 | AJ8: =AI8+U8 -> 0 | AK8: =AJ8+V8 -> 0 | AL8: =AK8+W8 -> 0 | AM8: =AL8+X8 -> 40 | AN8: =AM8+Y8 -> 56 | AO8: =AN8+Z8 -> 80 | AP8: =AO8+AA8 -> 140 | ... AU8: =AT8+AF8 -> 400
Q9: Spa Chains - Other | R9: Sales | U9: ='Initiative Log - Detailed'!$G10*U30 -> 0 | V9: ='Initiative Log - Detailed'!$G10*V30 -> 0 | W9: ='Initiative Log - Detailed'!$G10*W30 -> 0 | X9: ='Initiative Log - Detailed'!$G10*X30 -> 0 | Y9: ='Initiative Log - Detailed'!$G10*Y30 -> 0 | Z9: ='Initiative Log - Detailed'!$G10*Z30 -> 0 | AA9: ='Initiative Log - Detailed'!$G10*AA30 -> 0 | AB9: ='Initiative Log - Detailed'!$G10*AB30 -> 0 | ... AF9: ='Initiative Log - Detailed'!$G10*AF30 -> 25 | AH9: =S9 -> 0 | AI9: =AH9+T9 -> 0 | AJ9: =AI9+U9 -> 0 | AK9: =AJ9+V9 -> 0 | AL9: =AK9+W9 -> 0 | AM9: =AL9+X9 -> 0 | AN9: =AM9+Y9 -> 0 | AO9: =AN9+Z9 -> 0 | AP9: =AO9+AA9 -> 0 | ... AU9: =AT9+AF9 -> 100
B10: Gross Profit I | C10: =SUM(C7:C8) -> 3271.5978 | D10: =SUM(D7:D8) -> 7181.048 | E10: =SUM(E7:E8) -> 9511.8927 | J10: Gross Profit I | K10: =SUM(K7:K8) -> 1079.6273 | L10: =SUM(L7:L8) -> 2369.7458 | M10: =SUM(M7:M8) -> 3138.9246 | Q10: Key Account Openings | R10: Sales | U10: ='Initiative Log - Detailed'!$G11*U31 -> 0 | V10: ='Initiative Log - Detailed'!$G11*V31 -> 0 | W10: ='Initiative Log - Detailed'!$G11*W31 -> 0 | X10: ='Initiative Log - Detailed'!$G11*X31 -> 0 | Y10: ='Initiative Log - Detailed'!$G11*Y31 -> 0 | Z10: ='Initiative Log - Detailed'!$G11*Z31 -> 0 | AA10: ='Initiative Log - Detailed'!$G11*AA31 -> 1.98 | AB10: ='Initiative Log - Detailed'!$G11*AB31 -> 1.98 | ... AF10: ='Initiative Log - Detailed'!$G11*AF31 -> 4.95 | AH10: =S10 -> 0 | AI10: =AH10+T10 -> 0 | AJ10: =AI10+U10 -> 0 | AK10: =AJ10+V10 -> 0 | AL10: =AK10+W10 -> 0 | AM10: =AL10+X10 -> 0 | AN10: =AM10+Y10 -> 0 | AO10: =AN10+Z10 -> 0 | AP10: =AO10+AA10 -> 1.98 | ... AU10: =AT10+AF10 -> 19.8
B11: GP I % | C11: =C10/C$7 -> 0.8 | D11: =D10/D$7 -> 0.8025 | E11: =E10/E$7 -> 0.805 | J11: GP I % | K11: =K10/K$7 -> 0.8 | L11: =L10/L$7 -> 0.8025 | M11: =M10/M$7 -> 0.805 | Q11: Team Improvements / Coaching | R11: Sales | U11: ='Initiative Log - Detailed'!$G12*U32 -> 0 | V11: ='Initiative Log - Detailed'!$G12*V32 -> 0 | W11: ='Initiative Log - Detailed'!$G12*W32 -> 2.9734096 | X11: ='Initiative Log - Detailed'!$G12*X32 -> 2.9734096 | Y11: ='Initiative Log - Detailed'!$G12*Y32 -> 2.9734096 | Z11: ='Initiative Log - Detailed'!$G12*Z32 -> 2.9734096 | AA11: ='Initiative Log - Detailed'!$G12*AA32 -> 2.9734096 | AB11: ='Initiative Log - Detailed'!$G12*AB32 -> 2.9734096 | ... AF11: ='Initiative Log - Detailed'!$G12*AF32 -> 2.9734096 | AH11: =S11 -> 0 | AI11: =AH11+T11 -> 0 | AJ11: =AI11+U11 -> 0 | AK11: =AJ11+V11 -> 0 | AL11: =AK11+W11 -> 2.9734096 | AM11: =AL11+X11 -> 5.9468192 | AN11: =AM11+Y11 -> 8.9202287 | AO11: =AN11+Z11 -> 11.893638 | AP11: =AO11+AA11 -> 14.867048 | ... AU11: =AT11+AF11 -> 29.734096
B13: Shipping and distribution costs | C13: =-C7*'Other COS'!$C$16 -> -286.26481 | D13: =-D7*'Other COS'!$C$16 -> -626.38425 | E13: =-E7*'Other COS'!$C$16 -> -827.1211 | J13: Shipping and distribution costs | K13: =-K7*'Other COS'!$C$16 -> -94.467387 | L13: =-L7*'Other COS'!$C$16 -> -206.7068 | M13: =-M7*'Other COS'!$C$16 -> -272.94996
B14: Rebates | C14: =-SUM(C46:C49)*5% -> -200 | D14: =-SUM(D46:D49)*5% -> -437.5 | E14: =-SUM(E46:E49)*5% -> -575 | J14: Rebates | K14: =C14*(1+$H$7) -> -66 | L14: =D14*(1+$H$7) -> -144.375 | M14: =E14*(1+$H$7) -> -189.75 | Q14: Spa Chains - Tosca | R14: EBITDA | U14: ='Initiative Log - Detailed'!$J7*U27 -> 0 | V14: ='Initiative Log - Detailed'!$J7*V27 -> 0 | W14: ='Initiative Log - Detailed'!$J7*W27 -> 0 | X14: ='Initiative Log - Detailed'!$J7*X27 -> 0 | Y14: ='Initiative Log - Detailed'!$J7*Y27 -> 0 | Z14: ='Initiative Log - Detailed'!$J7*Z27 -> 0 | AA14: ='Initiative Log - Detailed'!$J7*AA27 -> 0 | AB14: ='Initiative Log - Detailed'!$J7*AB27 -> 30.385191 | ... AF14: ='Initiative Log - Detailed'!$J7*AF27 -> 20.256794 | AH14: =S14 -> 0 | AI14: =AH14+T14 -> 0 | AJ14: =AI14+U14 -> 0 | AK14: =AJ14+V14 -> 0 | AL14: =AK14+W14 -> 0 | AM14: =AL14+X14 -> 0 | AN14: =AM14+Y14 -> 0 | AO14: =AN14+Z14 -> 0 | AP14: =AO14+AA14 -> 0 | ... AU14: =AT14+AF14 -> 101.28397
Q15: Spa Chains - Woodhouse | R15: EBITDA | U15: ='Initiative Log - Detailed'!$J8*U28 -> 0 | V15: ='Initiative Log - Detailed'!$J8*V28 -> 0 | W15: ='Initiative Log - Detailed'!$J8*W28 -> 30.385191 | X15: ='Initiative Log - Detailed'!$J8*X28 -> 9.1155573 | Y15: ='Initiative Log - Detailed'!$J8*Y28 -> 12.154076 | Z15: ='Initiative Log - Detailed'!$J8*Z28 -> 12.154076 | AA15: ='Initiative Log - Detailed'!$J8*AA28 -> 45.577787 | AB15: ='Initiative Log - Detailed'!$J8*AB28 -> 21.269634 | ... AF15: ='Initiative Log - Detailed'!$J8*AF28 -> 39.500748 | AH15: =S15 -> 0 | AI15: =AH15+T15 -> 0 | AJ15: =AI15+U15 -> 0 | AK15: =AJ15+V15 -> 0 | AL15: =AK15+W15 -> 30.385191 | AM15: =AL15+X15 -> 39.500748 | AN15: =AM15+Y15 -> 51.654825 | AO15: =AN15+Z15 -> 63.808901 | AP15: =AO15+AA15 -> 109.38669 | ... AU15: =AT15+AF15 -> 303.85191
B16: Gross profit II | C16: =SUM(C10,C13:C14) -> 2785.333 | D16: =SUM(D10,D13:D14) -> 6117.1638 | E16: =SUM(E10,E13:E14) -> 8109.7716 | J16: Gross profit II | K16: =SUM(K10,K13:K14) -> 919.15989 | L16: =SUM(L10,L13:L14) -> 2018.664 | M16: =SUM(M10,M13:M14) -> 2676.2246 | Q16: Spa Chains - Trilogy | R16: EBITDA | U16: ='Initiative Log - Detailed'!$J9*U29 -> 0 | V16: ='Initiative Log - Detailed'!$J9*V29 -> 0 | W16: ='Initiative Log - Detailed'!$J9*W29 -> 0 | X16: ='Initiative Log - Detailed'!$J9*X29 -> 20.256794 | Y16: ='Initiative Log - Detailed'!$J9*Y29 -> 8.1027176 | Z16: ='Initiative Log - Detailed'!$J9*Z29 -> 12.154076 | AA16: ='Initiative Log - Detailed'!$J9*AA29 -> 30.385191 | AB16: ='Initiative Log - Detailed'!$J9*AB29 -> 14.179756 | ... AF16: ='Initiative Log - Detailed'!$J9*AF29 -> 26.333832 | AH16: =S16 -> 0 | AI16: =AH16+T16 -> 0 | AJ16: =AI16+U16 -> 0 | AK16: =AJ16+V16 -> 0 | AL16: =AK16+W16 -> 0 | AM16: =AL16+X16 -> 20.256794 | AN16: =AM16+Y16 -> 28.359512 | AO16: =AN16+Z16 -> 40.513588 | AP16: =AO16+AA16 -> 70.898779 | ... AU16: =AT16+AF16 -> 202.56794
B17: GP II % | C17: =C16/C$7 -> 0.68109423 | D17: =D16/D$7 -> 0.68360829 | E17: =E16/E$7 -> 0.68633723 | J17: GP II % | K17: =K16/K$7 -> 0.68109423 | L17: =L16/L$7 -> 0.68360829 | M17: =M16/M$7 -> 0.68633723 | Q17: Spa Chains - Other | R17: EBITDA | U17: ='Initiative Log - Detailed'!$J10*U30 -> 0 | V17: ='Initiative Log - Detailed'!$J10*V30 -> 0 | W17: ='Initiative Log - Detailed'!$J10*W30 -> 0 | X17: ='Initiative Log - Detailed'!$J10*X30 -> 0 | Y17: ='Initiative Log - Detailed'!$J10*Y30 -> 0 | Z17: ='Initiative Log - Detailed'!$J10*Z30 -> 0 | AA17: ='Initiative Log - Detailed'!$J10*AA30 -> 0 | AB17: ='Initiative Log - Detailed'!$J10*AB30 -> 0 | ... AF17: ='Initiative Log - Detailed'!$J10*AF30 -> 12.660496 | AH17: =S17 -> 0 | AI17: =AH17+T17 -> 0 | AJ17: =AI17+U17 -> 0 | AK17: =AJ17+V17 -> 0 | AL17: =AK17+W17 -> 0 | AM17: =AL17+X17 -> 0 | AN17: =AM17+Y17 -> 0 | AO17: =AN17+Z17 -> 0 | AP17: =AO17+AA17 -> 0 | ... AU17: =AT17+AF17 -> 50.641985
Q18: Key Account Openings | R18: EBITDA | U18: ='Initiative Log - Detailed'!$J11*U31 -> 0 | V18: ='Initiative Log - Detailed'!$J11*V31 -> 0 | W18: ='Initiative Log - Detailed'!$J11*W31 -> 0 | X18: ='Initiative Log - Detailed'!$J11*X31 -> 0 | Y18: ='Initiative Log - Detailed'!$J11*Y31 -> 0 | Z18: ='Initiative Log - Detailed'!$J11*Z31 -> 0 | AA18: ='Initiative Log - Detailed'!$J11*AA31 -> 1.0027113 | AB18: ='Initiative Log - Detailed'!$J11*AB31 -> 1.0027113 | ... AF18: ='Initiative Log - Detailed'!$J11*AF31 -> 2.5067783 | AH18: =S18 -> 0 | AI18: =AH18+T18 -> 0 | AJ18: =AI18+U18 -> 0 | AK18: =AJ18+V18 -> 0 | AL18: =AK18+W18 -> 0 | AM18: =AL18+X18 -> 0 | AN18: =AM18+Y18 -> 0 | AO18: =AN18+Z18 -> 0 | AP18: =AO18+AA18 -> 1.0027113 | ... AU18: =AT18+AF18 -> 10.027113
B19: Advertising and Marketing | C19: =-C7*3% -> -122.68492 | D19: =-D7*3% -> -268.45039 | E19: =-E7*3% -> -354.48047 | J19: Advertising and Marketing | K19: =-K7*3% -> -40.486023 | L19: =-L7*3% -> -88.58863 | M19: =-M7*3% -> -116.97856 | Q19: Team Improvements / Coaching | R19: EBITDA | U19: ='Initiative Log - Detailed'!$J12*U32 -> 0 | V19: ='Initiative Log - Detailed'!$J12*V32 -> 0 | W19: ='Initiative Log - Detailed'!$J12*W32 -> 1.5057936 | X19: ='Initiative Log - Detailed'!$J12*X32 -> 1.5057936 | Y19: ='Initiative Log - Detailed'!$J12*Y32 -> 1.5057936 | Z19: ='Initiative Log - Detailed'!$J12*Z32 -> 1.5057936 | AA19: ='Initiative Log - Detailed'!$J12*AA32 -> 1.5057936 | AB19: ='Initiative Log - Detailed'!$J12*AB32 -> 1.5057936 | ... AF19: ='Initiative Log - Detailed'!$J12*AF32 -> 1.5057936 | AH19: =S19 -> 0 | AI19: =AH19+T19 -> 0 | AJ19: =AI19+U19 -> 0 | AK19: =AJ19+V19 -> 0 | AL19: =AK19+W19 -> 1.5057936 | AM19: =AL19+X19 -> 3.0115873 | AN19: =AM19+Y19 -> 4.5173809 | AO19: =AN19+Z19 -> 6.0231745 | AP19: =AO19+AA19 -> 7.5289682 | ... AU19: =AT19+AF19 -> 15.057936
B20: Sales and Training Expenses | C20: =C19/2 -> -61.342459 | D20: =D19/2 -> -134.2252 | E20: =E19/2 -> -177.24024 | J20: Sales and Training Expenses | K20: =K19/2 -> -20.243011 | L20: =L19/2 -> -44.294315 | M20: =M19/2 -> -58.489278
R21: Costs | S21: 14 | T21: 14 | U21: =15+SUM(U6:U11)*0.05 -> 15 | V21: 15 | W21: =ROUND(15+SUM(W6:W11)*0.05, 0) -> 18 | X21: =ROUND(17+SUM(X6:X11)*0.05, 0) -> 20 | Y21: =ROUND(17+SUM(Y6:Y11)*0.05, 0) -> 19 | Z21: =ROUND(17+SUM(Z6:Z11)*0.05, 0) -> 20 | AA21: =ROUND(17+SUM(AA6:AA11)*0.05, 0) -> 25 | AB21: =ROUND(17+SUM(AB6:AB11)*0.05, 0) -> 24 | AC21: =ROUND(17+SUM(AC6:AC11)*0.05, 0) -> 24 | AD21: =ROUND(17+SUM(AD6:AD11)*0.05, 0) -> 32 | AE21: =ROUND(17+SUM(AE6:AE11)*0.05, 0) -> 27 | AF21: =ROUND(17+SUM(AF6:AF11)*0.05, 0)+4 -> 31 | AH21: =S21 -> 14 | AI21: =AH21+T21 -> 28 | AJ21: =AI21+U21 -> 43 | AK21: =AJ21+V21 -> 58 | AL21: =AK21+W21 -> 76 | AM21: =AL21+X21 -> 96 | AN21: =AM21+Y21 -> 115 | AO21: =AN21+Z21 -> 135 | AP21: =AO21+AA21 -> 160 | ... AU21: =AT21+AF21 -> 298
B22: Gross profit III | C22: =SUM(C16,C19:C20) -> 2601.3056 | D22: =SUM(D16,D19:D20) -> 5714.4882 | E22: =SUM(E16,E19:E20) -> 7578.0509 | J22: Gross profit III | K22: =SUM(K16,K19:K20) -> 858.43086 | L22: =SUM(L16,L19:L20) -> 1885.7811 | M22: =SUM(M16,M19:M20) -> 2500.7568
B23: GP III % | C23: =C22/C$7 -> 0.63609423 | D23: =D22/D$7 -> 0.63860829 | E23: =E22/E$7 -> 0.64133723 | J23: GP III % | K23: =K22/K$7 -> 0.63609423 | L23: =L22/L$7 -> 0.63860829 | M23: =M22/M$7 -> 0.64133723
